Workbook
Name Asservissement: PARAM!$A$44:$A$46
Name CODE_SANDRE_3: PARAM!$I$4:$I$19
Name CODE_SANDRE_SCL: PARAM!$F$4:$F$7
Name CODE_SANDRE_STEU: PARAM!$E$4:$E$19
Name conditions_meteo: PARAM!$F$44:$F$46
Name Conformité: PARAM!$B$44:$B$48
Name Conformité: PARAM!$B$44:$B$48
Name Conformité: PARAM!$B$44:$B$48
Name Eq_h_controle: PARAM!$C$30:$C$32
Name Eq_h_controle: PARAM!$C$30:$C$32
Name Eq_h_controle: PARAM!$C$30:$C$32
Name Eq_h_controle: PARAM!$C$30:$C$32
Name EQUIPEMENT_PREL: PARAM!$B$4:$B$6
Name EQUIPEMENT_PREL: PARAM!$B$4:$B$6
Name EQUIPEMENT_PREL: PARAM!$B$4:$B$6
Name EQUIPEMENT_Q: PARAM!$A$4:$A$15
Name Frequence: PARAM!$E$44:$E$51
Name Frequence: PARAM!$E$44:$E$51
Name Frequence: PARAM!$E$44:$E$51
Name Frequence: PARAM!$E$44:$E$51
Name Frequence: PARAM!$E$44:$E$51
Name Frequence: PARAM!$E$44:$E$51
Name LISTE_1: PARAM!$A$21:$A$22
Name LISTE_1: PARAM!$A$21:$A$22
Name LISTE_1: PARAM!$A$21:$A$22
Name LISTE_1: PARAM!$A$21:$A$22
Name LISTE_1: PARAM!$A$21:$A$22
Name LISTE_1: PARAM!$A$21:$A$22
Name LISTE_1: PARAM!$A$21:$A$22
Name LISTE_1: PARAM!$A$21:$A$22
Name LISTE_1: PARAM!$A$21:$A$22
Name LISTE_1: PARAM!$A$21:$A$22
Name LISTE_1: PARAM!$A$21:$A$22
Name LISTE_1: PARAM!$A$21:$A$22
Name LISTE_1: PARAM!$A$21:$A$22
Name LISTE_1_a: '[1]#REF'!#REF!
Name LISTE_1_a: '[1]#REF'!#REF!
Name LISTE_1_a: '[1]#REF'!#REF!
Name LISTE_1_a: '[1]#REF'!#REF!
Name LISTE_1_a: '[1]#REF'!#REF!
Name LISTE_1_a: '[1]#REF'!#REF!
Name LISTE_1_a: '[1]#REF'!#REF!
Name LISTE_1_a: '[1]#REF'!#REF!
Name LISTE_2: PARAM!$B$21:$B$23
Name LISTE_2: PARAM!$B$21:$B$23
Name LISTE_2: PARAM!$B$21:$B$23
Name LISTE_2: PARAM!$B$21:$B$23
Name LISTE_2: PARAM!$B$21:$B$23
Name LISTE_2: PARAM!$B$21:$B$23
Name LISTE_2: PARAM!$B$21:$B$23
Name LISTE_2: PARAM!$B$21:$B$23
Name LISTE_2: PARAM!$B$21:$B$23
Name LISTE_2: PARAM!$B$21:$B$23
Name LISTE_2: PARAM!$B$21:$B$23
Name LISTE_2: PARAM!$B$21:$B$23
Name LISTE_2: PARAM!$B$21:$B$23
Name LISTE_3: PARAM!$C$21:$C$24
Name LISTE_3: PARAM!$C$21:$C$24
Name LISTE_3: PARAM!$C$21:$C$24
Name LISTE_3: PARAM!$C$21:$C$24

Sheet Descriptif
AC1: Ne rien mettre dans cette colonne | AD1: Ne rien mettre dans cette colonne | AE1: Ne rien mettre dans cette colonne | AF1: Ne rien mettre dans cette colonne | AG1: Ne rien mettre dans cette colonne | AH1: Ne rien mettre dans cette colonne | AI1: Ne rien mettre dans cette colonne | AJ1: Ne rien mettre dans cette colonne
C2: CONTRÔLE ANNUEL DES DISPOSITIFS D'AUTOSURVEILLANCE DES SYSTÈMES D'ASSAINISSEMENT COLLECTIF | AC2: début données sys collect | AD2: =ROW(E12)+1 -> 13 | AE2: fin données sys collect | AF2: =ROW(D15)-1 -> 14 | AG2: pluvio SCL | AH2: =ROW(E20)+1 -> 21 | AI2: =ROW(D23)-1 -> 22
C3: NOM DU SYSTÈME D'ASSAINISSEMENT : | G3: BARJAC (30) | K3: NOM SYSTÈME DE TRAITEMENT : | N3: BARJAC (30) | Q3: NOM SYSTÈME DE COLLECTE : | AC3: début données station | AD3: =ROW(E32)+1 -> 33 | AE3: fin données station | AF3: =ROW(D41)-1 -> 40 | AG3: pluvio STEU | AH3: =ROW(E46)+1 -> 47 | AI3: =ROW(D49)-1 -> 48
C4: CODE SANDRE DE L'AGGLOMERATION : | K4: CODE SANDRE DE LA STATION : | N4: 060930290002 | Q4: CODE SANDRE DU RESEAU :
C5: NOM DU MAITRE D'OUVRAGE : | G5: Commune de Barjac | K5: CAPACITE DE LA STATION : | N5: 5 000 EH | Q5: EXPLOITANT DU RESEAU :
C6: ORGANISME DE CONTRÔLE : | G6: CEREG Ingénierie | K6: EXPLOITANT DE LA STATION : | N6: Régie | Q6: ok
C8: SYSTÈME DE COLLECTE
D10: Liste des équipements du système de collecte par point
E12: Actif | F12: Lien vers l'onglet de l'équipement | H12: Point réglementaire | I12: Localisation (cf. MAS) | J12: Code du point (cf MAS) | K12: Libellé du point | M12: Type d'équipement | O12: Type de matériel | Q12: Pluviométre de référence | AC12: Liste préleveurs | AE12: Liste débimètres | AG12: Liste thermo | AI12: Liste pluvio
E13: Oui | F13: A1_DO1_Q_Grav | H13: A1 | I13: =IF(ISBLANK(A1_DO1_Q_Grav!J5), "", A1_DO1_Q_Grav!J5) -> A1 | J13: =IF(ISBLANK(A1_DO1_Q_Grav!J4), "", A1_DO1_Q_Grav!J4) -> DO1 | K13: =IF(ISBLANK(A1_DO1_Q_Grav!J3), "", A1_DO1_Q_Grav!J3) -> DO1 | M13: Débitmètre gravitaire | O13: =IF(ISBLANK(A1_DO1_Q_Grav!D40), "", A1_DO1_Q_Grav!D40) -> Seuil | S13: Gérer l'équipement | AB13: =ROW(A13)- $AD$2 +1 -> 1 | AC13: =IF(AND($E13="Oui",$M13="Préleveur"),$F13,"") | AD13: {=IFERROR(INDEX($AC$13:$AC$94,SMALL(IF($AC$13:$AC$94<>"",ROW($AC$13:$AC$94)-ROW(INDIRECT("$AC$13"))+1),ROW(INDIRECT("A" & AB13 ) ))),"")} -> A3_P102_PREL | AE13: =IF(AND($E13="Oui",LEFT($M13,10) ="Débitmètre"),$F13,"") -> A1_DO1_Q_Grav | AF13: {=IFERROR(INDEX($AE$13:$AE$94,SMALL(IF($AE$13:$AE$94<>"",ROW($AE$13:$AE$94)-ROW(INDIRECT("$AE$13"))+1),ROW(INDIRECT("A" & AB13 ) ))),"")} -> A1_DO1_Q_Grav | AG13: =IF(AND($E13="Oui",LEFT($M13,5) ="Sonde"),$F13,"") | AH13: {=IFERROR(INDEX($AG$13:$AG$94,SMALL(IF($AG$13:$AG$94<>"",ROW($AG$13:$AG$94)-ROW(INDIRECT("$AG$13"))+1),ROW(INDIRECT("A" & AB13 ) ))),"")} -> A4_P103_TEMP | AI13: =IF(AND($E13="Oui", $M13 <> "", $M13 = ""),$F13,"") | AJ13: {=IFERROR(INDEX($AI$13:$AI$94,SMALL(IF($AI$13:$AI$94<>"",ROW($AI$13:$AI$94)-ROW(INDIRECT("$AI$13"))+1),ROW(INDIRECT("A" & AB13 ) ))),"")} -> PLUVIO_SCL_ooo
AB14: =ROW(A14)- $AD$2 +1 -> 2 | AC14: =IF(AND($E14="Oui",$M14="Préleveur"),$F14,"") | AD14: {=IFERROR(INDEX($AC$13:$AC$94,SMALL(IF($AC$13:$AC$94<>"",ROW($AC$13:$AC$94)-ROW(INDIRECT("$AC$13"))+1),ROW(INDIRECT("A" & AB14 ) ))),"")} -> A4_P103_PREL | AE14: =IF(AND($E14="Oui",LEFT($M14,10) ="Débitmètre"),$F14,"") | AF14: {=IFERROR(INDEX($AE$13:$AE$94,SMALL(IF($AE$13:$AE$94<>"",ROW($AE$13:$AE$94)-ROW(INDIRECT("$AE$13"))+1),ROW(INDIRECT("A" & AB14 ) ))),"")} -> A2_P100_Q_Grav | AG14: =IF(AND($E14="Oui",LEFT($M14,5) ="Sonde"),$F14,"") | AH14: {=IFERROR(INDEX($AG$13:$AG$94,SMALL(IF($AG$13:$AG$94<>"",ROW($AG$13:$AG$94)-ROW(INDIRECT("$AG$13"))+1),ROW(INDIRECT("A" & AB14 ) ))),"")} | AI14: =IF(AND($E14="Oui",$F14<>"",$M14=""),$F14,"") | AJ14: {=IFERROR(INDEX($AI$14:$AI$96,SMALL(IF($AI$14:$AI$96<>"",ROW($AI$14:$AI$96)-ROW(INDIRECT("$AI$13"))+1),ROW(INDIRECT("A" & AB14 ) ))),"")} -> PLUVIO_STEU_ee
E15: Ajouter un équipement réseau | AB15: =ROW(A15)- $AD$2 +1 -> 3 | AC15: =IF(AND($E15="Oui",$M15="Préleveur"),$F15,"") | AD15: {=IFERROR(INDEX($AC$13:$AC$94,SMALL(IF($AC$13:$AC$94<>"",ROW($AC$13:$AC$94)-ROW(INDIRECT("$AC$13"))+1),ROW(INDIRECT("A" & AB15 ) ))),"")} | AE15: =IF(AND($E15="Oui",LEFT($M15,10) ="Débitmètre"),$F15,"") | AF15: {=IFERROR(INDEX($AE$13:$AE$94,SMALL(IF($AE$13:$AE$94<>"",ROW($AE$13:$AE$94)-ROW(INDIRECT("$AE$13"))+1),ROW(INDIRECT("A" & AB15 ) ))),"")} -> A3_P102_Q_DEM | AG15: =IF(AND($E15="Oui",LEFT($M15,5) ="Sonde"),$F15,"") | AH15: {=IFERROR(INDEX($AG$13:$AG$94,SMALL(IF($AG$13:$AG$94<>"",ROW($AG$13:$AG$94)-ROW(INDIRECT("$AG$13"))+1),ROW(INDIRECT("A" & AB15 ) ))),"")} | AI15: =IF(AND($E15="Oui",$F15<>"",$M15=""),$F15,"") | AJ15: {=IFERROR(INDEX($AI$14:$AI$96,SMALL(IF($AI$14:$AI$96<>"",ROW($AI$14:$AI$96)-ROW(INDIRECT("$AI$13"))+1),ROW(INDIRECT("A" & AB15 ) ))),"")}
AB16: =ROW(A16)- $AD$2 +1 -> 4 | AC16: =IF(AND($E16="Oui",$M16="Préleveur"),$F16,"") | AD16: {=IFERROR(INDEX($AC$13:$AC$94,SMALL(IF($AC$13:$AC$94<>"",ROW($AC$13:$AC$94)-ROW(INDIRECT("$AC$13"))+1),ROW(INDIRECT("A" & AB16 ) ))),"")} | AE16: =IF(AND($E16="Oui",LEFT($M16,10) ="Débitmètre"),$F16,"") | AF16: {=IFERROR(INDEX($AE$13:$AE$94,SMALL(IF($AE$13:$AE$94<>"",ROW($AE$13:$AE$94)-ROW(INDIRECT("$AE$13"))+1),ROW(INDIRECT("A" & AB16 ) ))),"")} -> A4_P103_Q_Grav | AG16: =IF(AND($E16="Oui",LEFT($M16,5) ="Sonde"),$F16,"") | AH16: {=IFERROR(INDEX($AG$13:$AG$94,SMALL(IF($AG$13:$AG$94<>"",ROW($AG$13:$AG$94)-ROW(INDIRECT("$AG$13"))+1),ROW(INDIRECT("A" & AB16 ) ))),"")} | AI16: =IF(AND($E16="Oui",$F16<>"",$M16=""),$F16,"") | AJ16: {=IFERROR(INDEX($AI$14:$AI$96,SMALL(IF($AI$14:$AI$96<>"",ROW($AI$14:$AI$96)-ROW(INDIRECT("$AI$13"))+1),ROW(INDIRECT("A" & AB16 ) ))),"")}
AB17: =ROW(A17)- $AD$2 +1 -> 5 | AC17: =IF(AND($E17="Oui",$M17="Préleveur"),$F17,"") | AD17: {=IFERROR(INDEX($AC$13:$AC$94,SMALL(IF($AC$13:$AC$94<>"",ROW($AC$13:$AC$94)-ROW(INDIRECT("$AC$13"))+1),ROW(INDIRECT("A" & AB17 ) ))),"")} | AE17: =IF(AND($E17="Oui",LEFT($M17,10) ="Débitmètre"),$F17,"") | AF17: {=IFERROR(INDEX($AE$13:$AE$94,SMALL(IF($AE$13:$AE$94<>"",ROW($AE$13:$AE$94)-ROW(INDIRECT("$AE$13"))+1),ROW(INDIRECT("A" & AB17 ) ))),"")} -> A6_P104_Q_DEM | AG17: =IF(AND($E17="Oui",LEFT($M17,5) ="Sonde"),$F17,"") | AH17: {=IFERROR(INDEX($AG$13:$AG$94,SMALL(IF($AG$13:$AG$94<>"",ROW($AG$13:$AG$94)-ROW(INDIRECT("$AG$13"))+1),ROW(INDIRECT("A" & AB17 ) ))),"")} | AI17: =IF(AND($E17="Oui",$F17<>"",$M17=""),$F17,"") | AJ17: {=IFERROR(INDEX($AI$14:$AI$96,SMALL(IF($AI$14:$AI$96<>"",ROW($AI$14:$AI$96)-ROW(INDIRECT("$AI$13"))+1),ROW(INDIRECT("A" & AB17 ) ))),"")}
D18: Liste des pluviomètres du réseau | AB18: =ROW(A18)- $AD$2 +1 -> 6 | AC18: =IF(AND($E18="Oui",$M18="Préleveur"),$F18,"") | AD18: {=IFERROR(INDEX($AC$13:$AC$94,SMALL(IF($AC$13:$AC$94<>"",ROW($AC$13:$AC$94)-ROW(INDIRECT("$AC$13"))+1),ROW(INDIRECT("A" & AB18 ) ))),"")} | AE18: =IF(AND($E18="Oui",LEFT($M18,10) ="Débitmètre"),$F18,"") | AF18: {=IFERROR(INDEX($AE$14:$AE$96,SMALL(IF($AE$14:$AE$96<>"",ROW($AE$14:$AE$96)-ROW(INDIRECT("$AE$13"))+1),ROW(INDIRECT("A" & AB18 ) ))),"")} | AG18: =IF(AND($E18="Oui",LEFT($M18,5) ="Sonde"),$F18,"") | AH18: {=IFERROR(INDEX($AG$13:$AG$94,SMALL(IF($AG$13:$AG$94<>"",ROW($AG$13:$AG$94)-ROW(INDIRECT("$AG$13"))+1),ROW(INDIRECT("A" & AB18 ) ))),"")} | AI18: =IF(AND($E18="Oui",$F18<>"",$M18=""),$F18,"") | AJ18: {=IFERROR(INDEX($AI$14:$AI$96,SMALL(IF($AI$14:$AI$96<>"",ROW($AI$14:$AI$96)-ROW(INDIRECT("$AI$13"))+1),ROW(INDIRECT("A" & AB18 ) ))),"")}
AB19: =ROW(A19)- $AD$2 +1 -> 7 | AC19: =IF(AND($E19="Oui",$M19="Préleveur"),$F19,"") | AD19: {=IFERROR(INDEX($AC$13:$AC$94,SMALL(IF($AC$13:$AC$94<>"",ROW($AC$13:$AC$94)-ROW(INDIRECT("$AC$13"))+1),ROW(INDIRECT("A" & AB19 ) ))),"")} | AE19: =IF(AND($E19="Oui",LEFT($M19,10) ="Débitmètre"),$F19,"") | AF19: {=IFERROR(INDEX($AE$14:$AE$96,SMALL(IF($AE$14:$AE$96<>"",ROW($AE$14:$AE$96)-ROW(INDIRECT("$AE$13"))+1),ROW(INDIRECT("A" & AB19 ) ))),"")} | AG19: =IF(AND($E19="Oui",LEFT($M19,5) ="Sonde"),$F19,"") | AH19: {=IFERROR(INDEX($AG$13:$AG$94,SMALL(IF($AG$13:$AG$94<>"",ROW($AG$13:$AG$94)-ROW(INDIRECT("$AG$13"))+1),ROW(INDIRECT("A" & AB19 ) ))),"")} | AI19: =IF(AND($E19="Oui",$F19<>"",$M19=""),$F19,"") | AJ19: {=IFERROR(INDEX($AI$14:$AI$96,SMALL(IF($AI$14:$AI$96<>"",ROW($AI$14:$AI$96)-ROW(INDIRECT("$AI$13"))+1),ROW(INDIRECT("A" & AB19 ) ))),"")}
E20: Actif | F20: Lien vers l'onglet de l'équipement | AB20: =ROW(A20)- $AD$2 +1 -> 8 | AC20: =IF(AND($E20="Oui",$M20="Préleveur"),$F20,"") | AD20: {=IFERROR(INDEX($AC$13:$AC$94,SMALL(IF($AC$13:$AC$94<>"",ROW($AC$13:$AC$94)-ROW(INDIRECT("$AC$13"))+1),ROW(INDIRECT("A" & AB20 ) ))),"")} | AE20: =IF(AND($E20="Oui",LEFT($M20,10) ="Débitmètre"),$F20,"") | AF20: {=IFERROR(INDEX($AE$14:$AE$96,SMALL(IF($AE$14:$AE$96<>"",ROW($AE$14:$AE$96)-ROW(INDIRECT("$AE$13"))+1),ROW(INDIRECT("A" & AB20 ) ))),"")} | AG20: =IF(AND($E20="Oui",LEFT($M20,5) ="Sonde"),$F20,"") | AH20: {=IFERROR(INDEX($AG$14:$AG$96,SMALL(IF($AG$14:$AG$96<>"",ROW($AG$14:$AG$96)-ROW(INDIRECT("$AG$13"))+1),ROW(INDIRECT("A" & AB20 ) ))),"")} | AI20: =IF(AND($E20="Oui",$F20<>"",$M20=""),$F20,"") | AJ20: {=IFERROR(INDEX($AI$14:$AI$96,SMALL(IF($AI$14:$AI$96<>"",ROW($AI$14:$AI$96)-ROW(INDIRECT("$AI$13"))+1),ROW(INDIRECT("A" & AB20 ) ))),"")}
E21: Oui | F21: PLUVIO_SCL_ooo | H21: Gérer l'équipement | AB21: =ROW(A21)- $AD$2 +1 -> 9 | AC21: =IF(AND($E21="Oui",$M21="Préleveur"),$F21,"") | AD21: {=IFERROR(INDEX($AC$13:$AC$94,SMALL(IF($AC$13:$AC$94<>"",ROW($AC$13:$AC$94)-ROW(INDIRECT("$AC$13"))+1),ROW(INDIRECT("A" & AB21 ) ))),"")} | AE21: =IF(AND($E21="Oui",LEFT($M21,10) ="Débitmètre"),$F21,"") | AF21: {=IFERROR(INDEX($AE$14:$AE$96,SMALL(IF($AE$14:$AE$96<>"",ROW($AE$14:$AE$96)-ROW(INDIRECT("$AE$13"))+1),ROW(INDIRECT("A" & AB21 ) ))),"")} | AG21: =IF(AND($E21="Oui",LEFT($M21,5) ="Sonde"),$F21,"") | AH21: {=IFERROR(INDEX($AG$14:$AG$96,SMALL(IF($AG$14:$AG$96<>"",ROW($AG$14:$AG$96)-ROW(INDIRECT("$AG$13"))+1),ROW(INDIRECT("A" & AB21 ) ))),"")} | AI21: =IF(AND($E21="Oui",$F21<>"",$M21=""),$F21,"") -> PLUVIO_SCL_ooo | AJ21: {=IFERROR(INDEX($AI$14:$AI$96,SMALL(IF($AI$14:$AI$96<>"",ROW($AI$14:$AI$96)-ROW(INDIRECT("$AI$13"))+1),ROW(INDIRECT("A" & AB21 ) ))),"")}
E23: Ajouter un pluviomètre réseau | K23: Si pas de pluviomètre, veuillez ajouter en commentaire la provenance des données : | AB23: =ROW(A23)- $AD$2 +1 -> 11 | AC23: =IF(AND($E23="Oui",$M23="Préleveur"),$F23,"") | AD23: {=IFERROR(INDEX($AC$13:$AC$94,SMALL(IF($AC$13:$AC$94<>"",ROW($AC$13:$AC$94)-ROW(INDIRECT("$AC$13"))+1),ROW(INDIRECT("A" & AB23 ) ))),"")} | AE23: =IF(AND($E23="Oui",LEFT($M23,10) ="Débitmètre"),$F23,"") | AF23: {=IFERROR(INDEX($AE$14:$AE$96,SMALL(IF($AE$14:$AE$96<>"",ROW($AE$14:$AE$96)-ROW(INDIRECT("$AE$13"))+1),ROW(INDIRECT("A" & AB23 ) ))),"")} | AG23: =IF(AND($E23="Oui",LEFT($M23,5) ="Sonde"),$F23,"") | AH23: {=IFERROR(INDEX($AG$14:$AG$96,SMALL(IF($AG$14:$AG$96<>"",ROW($AG$14:$AG$96)-ROW(INDIRECT("$AG$13"))+1),ROW(INDIRECT("A" & AB23 ) ))),"")} | AI23: =IF(AND($E23="Oui",$F23<>"",$M23=""),$F23,"") | AJ23: {=IFERROR(INDEX($AI$14:$AI$96,SMALL(IF($AI$14:$AI$96<>"",ROW($AI$14:$AI$96)-ROW(INDIRECT("$AI$13"))+1),ROW(INDIRECT("A" & AB23 ) ))),"")}
AB24: =ROW(A24)- $AD$2 +1 -> 12 | AC24: =IF(AND($E24="Oui",$M24="Préleveur"),$F24,"") | AD24: {=IFERROR(INDEX($AC$14:$AC$96,SMALL(IF($AC$14:$AC$96<>"",ROW($AC$14:$AC$96)-ROW(INDIRECT("$AC$13"))+1),ROW(INDIRECT("A" & AB24 ) ))),"")} | AE24: =IF(AND($E24="Oui",LEFT($M24,10) ="Débitmètre"),$F24,"") | AF24: {=IFERROR(INDEX($AE$14:$AE$96,SMALL(IF($AE$14:$AE$96<>"",ROW($AE$14:$AE$96)-ROW(INDIRECT("$AE$13"))+1),ROW(INDIRECT("A" & AB24 ) ))),"")} | AG24: =IF(AND($E24="Oui",LEFT($M24,5) ="Sonde"),$F24,"") | AH24: {=IFERROR(INDEX($AG$14:$AG$96,SMALL(IF($AG$14:$AG$96<>"",ROW($AG$14:$AG$96)-ROW(INDIRECT("$AG$13"))+1),ROW(INDIRECT("A" & AB24 ) ))),"")} | AI24: =IF(AND($E24="Oui",$F24<>"",$M24=""),$F24,"") | AJ24: {=IFERROR(INDEX($AI$14:$AI$96,SMALL(IF($AI$14:$AI$96<>"",ROW($AI$14:$AI$96)-ROW(INDIRECT("$AI$13"))+1),ROW(INDIRECT("A" & AB24 ) ))),"")}
AB25: =ROW(A25)- $AD$2 +1 -> 13 | AC25: =IF(AND($E25="Oui",$M25="Préleveur"),$F25,"") | AD25: {=IFERROR(INDEX($AC$14:$AC$96,SMALL(IF($AC$14:$AC$96<>"",ROW($AC$14:$AC$96)-ROW(INDIRECT("$AC$13"))+1),ROW(INDIRECT("A" & AB25 ) ))),"")} | AE25: =IF(AND($E25="Oui",LEFT($M25,10) ="Débitmètre"),$F25,"") | AF25: {=IFERROR(INDEX($AE$14:$AE$96,SMALL(IF($AE$14:$AE$96<>"",ROW($AE$14:$AE$96)-ROW(INDIRECT("$AE$13"))+1),ROW(INDIRECT("A" & AB25 ) ))),"")} | AG25: =IF(AND($E25="Oui",LEFT($M25,5) ="Sonde"),$F25,"") | AH25: {=IFERROR(INDEX($AG$14:$AG$96,SMALL(IF($AG$14:$AG$96<>"",ROW($AG$14:$AG$96)-ROW(INDIRECT("$AG$13"))+1),ROW(INDIRECT("A" & AB25 ) ))),"")} | AI25: =IF(AND($E25="Oui",$F25<>"",$M25=""),$F25,"") | AJ25: {=IFERROR(INDEX($AI$14:$AI$96,SMALL(IF($AI$14:$AI$96<>"",ROW($AI$14:$AI$96)-ROW(INDIRECT("$AI$13"))+1),ROW(INDIRECT("A" & AB25 ) ))),"")}
AB26: =ROW(A26)- $AD$2 +1 -> 14 | AC26: =IF(AND($E26="Oui",$M26="Préleveur"),$F26,"") | AD26: {=IFERROR(INDEX($AC$14:$AC$96,SMALL(IF($AC$14:$AC$96<>"",ROW($AC$14:$AC$96)-ROW(INDIRECT("$AC$13"))+1),ROW(INDIRECT("A" & AB26 ) ))),"")} | AE26: =IF(AND($E26="Oui",LEFT($M26,10) ="Débitmètre"),$F26,"") | AF26: {=IFERROR(INDEX($AE$14:$AE$96,SMALL(IF($AE$14:$AE$96<>"",ROW($AE$14:$AE$96)-ROW(INDIRECT("$AE$13"))+1),ROW(INDIRECT("A" & AB26 ) ))),"")} | AG26: =IF(AND($E26="Oui",LEFT($M26,5) ="Sonde"),$F26,"") | AH26: {=IFERROR(INDEX($AG$14:$AG$96,SMALL(IF($AG$14:$AG$96<>"",ROW($AG$14:$AG$96)-ROW(INDIRECT("$AG$13"))+1),ROW(INDIRECT("A" & AB26 ) ))),"")} | AI26: =IF(AND($E26="Oui",$F26<>"",$M26=""),$F26,"") | AJ26: {=IFERROR(INDEX($AI$14:$AI$96,SMALL(IF($AI$14:$AI$96<>"",ROW($AI$14:$AI$96)-ROW(INDIRECT("$AI$13"))+1),ROW(INDIRECT("A" & AB26 ) ))),"")}
AB27: =ROW(A27)- $AD$2 +1 -> 15 | AC27: =IF(AND($E27="Oui",$M27="Préleveur"),$F27,"") | AD27: {=IFERROR(INDEX($AC$14:$AC$96,SMALL(IF($AC$14:$AC$96<>"",ROW($AC$14:$AC$96)-ROW(INDIRECT("$AC$13"))+1),ROW(INDIRECT("A" & AB27 ) ))),"")} | AE27: =IF(AND($E27="Oui",LEFT($M27,10) ="Débitmètre"),$F27,"") | AF27: {=IFERROR(INDEX($AE$14:$AE$96,SMALL(IF($AE$14:$AE$96<>"",ROW($AE$14:$AE$96)-ROW(INDIRECT("$AE$13"))+1),ROW(INDIRECT("A" & AB27 ) ))),"")} | AG27: =IF(AND($E27="Oui",LEFT($M27,5) ="Sonde"),$F27,"") | AH27: {=IFERROR(INDEX($AG$14:$AG$96,SMALL(IF($AG$14:$AG$96<>"",ROW($AG$14:$AG$96)-ROW(INDIRECT("$AG$13"))+1),ROW(INDIRECT("A" & AB27 ) ))),"")} | AI27: =IF(AND($E27="Oui",$F27<>"",$M27=""),$F27,"") | AJ27: {=IFERROR(INDEX($AI$14:$AI$96,SMALL(IF($AI$14:$AI$96<>"",ROW($AI$14:$AI$96)-ROW(INDIRECT("$AI$13"))+1),ROW(INDIRECT("A" & AB27 ) ))),"")}
C28: SYSTÈME DE TRAITEMENT | AB28: =ROW(A28)- $AD$2 +1 -> 16 | AC28: =IF(AND($E28="Oui",$M28="Préleveur"),$F28,"") | AD28: {=IFERROR(INDEX($AC$14:$AC$96,SMALL(IF($AC$14:$AC$96<>"",ROW($AC$14:$AC$96)-ROW(INDIRECT("$AC$13"))+1),ROW(INDIRECT("A" & AB28 ) ))),"")} | AE28: =IF(AND($E28="Oui",LEFT($M28,10) ="Débitmètre"),$F28,"") | AF28: {=IFERROR(INDEX($AE$14:$AE$96,SMALL(IF($AE$14:$AE$96<>"",ROW($AE$14:$AE$96)-ROW(INDIRECT("$AE$13"))+1),ROW(INDIRECT("A" & AB28 ) ))),"")} | AG28: =IF(AND($E28="Oui",LEFT($M28,5) ="Sonde"),$F28,"") | AH28: {=IFERROR(INDEX($AG$14:$AG$96,SMALL(IF($AG$14:$AG$96<>"",ROW($AG$14:$AG$96)-ROW(INDIRECT("$AG$13"))+1),ROW(INDIRECT("A" & AB28 ) ))),"")} | AI28: =IF(AND($E28="Oui",$F28<>"",$M28=""),$F28,"") | AJ28: {=IFERROR(INDEX($AI$14:$AI$96,SMALL(IF($AI$14:$AI$96<>"",ROW($AI$14:$AI$96)-ROW(INDIRECT("$AI$13"))+1),ROW(INDIRECT("A" & AB28 ) ))),"")}
AB29: =ROW(A29)- $AD$2 +1 -> 17 | AC29: =IF(AND($E29="Oui",$M29="Préleveur"),$F29,"") | AD29: {=IFERROR(INDEX($AC$14:$AC$96,SMALL(IF($AC$14:$AC$96<>"",ROW($AC$14:$AC$96)-ROW(INDIRECT("$AC$13"))+1),ROW(INDIRECT("A" & AB29 ) ))),"")} | AE29: =IF(AND($E29="Oui",LEFT($M29,10) ="Débitmètre"),$F29,"") | AF29: {=IFERROR(INDEX($AE$14:$AE$96,SMALL(IF($AE$14:$AE$96<>"",ROW($AE$14:$AE$96)-ROW(INDIRECT("$AE$13"))+1),ROW(INDIRECT("A" & AB29 ) ))),"")} | AG29: =IF(AND($E29="Oui",LEFT($M29,5) ="Sonde"),$F29,"") | AH29: {=IFERROR(INDEX($AG$14:$AG$96,SMALL(IF($AG$14:$AG$96<>"",ROW($AG$14:$AG$96)-ROW(INDIRECT("$AG$13"))+1),ROW(INDIRECT("A" & AB29 ) ))),"")} | AI29: =IF(AND($E29="Oui",$F29<>"",$M29=""),$F29,"") | AJ29: {=IFERROR(INDEX($AI$14:$AI$96,SMALL(IF($AI$14:$AI$96<>"",ROW($AI$14:$AI$96)-ROW(INDIRECT("$AI$13"))+1),ROW(INDIRECT("A" & AB29 ) ))),"")}
D30: Liste des équipements du système de traitement | AB30: =ROW(A30)- $AD$2 +1 -> 18 | AC30: =IF(AND($E30="Oui",$M30="Préleveur"),$F30,"") | AD30: {=IFERROR(INDEX($AC$14:$AC$96,SMALL(IF($AC$14:$AC$96<>"",ROW($AC$14:$AC$96)-ROW(INDIRECT("$AC$13"))+1),ROW(INDIRECT("A" & AB30 ) ))),"")} | AE30: =IF(AND($E30="Oui",LEFT($M30,10) ="Débitmètre"),$F30,"") | AF30: {=IFERROR(INDEX($AE$14:$AE$96,SMALL(IF($AE$14:$AE$96<>"",ROW($AE$14:$AE$96)-ROW(INDIRECT("$AE$13"))+1),ROW(INDIRECT("A" & AB30 ) ))),"")} | AG30: =IF(AND($E30="Oui",LEFT($M30,5) ="Sonde"),$F30,"") | AH30: {=IFERROR(INDEX($AG$14:$AG$96,SMALL(IF($AG$14:$AG$96<>"",ROW($AG$14:$AG$96)-ROW(INDIRECT("$AG$13"))+1),ROW(INDIRECT("A" & AB30 ) ))),"")} | AI30: =IF(AND($E30="Oui",$F30<>"",$M30=""),$F30,"") | AJ30: {=IFERROR(INDEX($AI$14:$AI$96,SMALL(IF($AI$14:$AI$96<>"",ROW($AI$14:$AI$96)-ROW(INDIRECT("$AI$13"))+1),ROW(INDIRECT("A" & AB30 ) ))),"")}
K31: mettre plutôt libellé de la localisation | P31: ok | AB31: =ROW(A31)- $AD$2 +1 -> 19 | AC31: =IF(AND($E31="Oui",$M31="Préleveur"),$F31,"") | AD31: {=IFERROR(INDEX($AC$14:$AC$96,SMALL(IF($AC$14:$AC$96<>"",ROW($AC$14:$AC$96)-ROW(INDIRECT("$AC$13"))+1),ROW(INDIRECT("A" & AB31 ) ))),"")} | AE31: =IF(AND($E31="Oui",LEFT($M31,10) ="Débitmètre"),$F31,"") | AF31: {=IFERROR(INDEX($AE$14:$AE$96,SMALL(IF($AE$14:$AE$96<>"",ROW($AE$14:$AE$96)-ROW(INDIRECT("$AE$13"))+1),ROW(INDIRECT("A" & AB31 ) ))),"")} | AG31: =IF(AND($E31="Oui",LEFT($M31,5) ="Sonde"),$F31,"") | AH31: {=IFERROR(INDEX($AG$14:$AG$96,SMALL(IF($AG$14:$AG$96<>"",ROW($AG$14:$AG$96)-ROW(INDIRECT("$AG$13"))+1),ROW(INDIRECT("A" & AB31 ) ))),"")} | AI31: =IF(AND($E31="Oui",$F31<>"",$M31=""),$F31,"") | AJ31: {=IFERROR(INDEX($AI$14:$AI$96,SMALL(IF($AI$14:$AI$96<>"",ROW($AI$14:$AI$96)-ROW(INDIRECT("$AI$13"))+1),ROW(INDIRECT("A" & AB31 ) ))),"")}
E32: Actif | F32: Lien vers l'onglet de l'équipement | H32: Point réglementaire | I32: Localisation (cf. MAS) | J32: Code du point (cf. MAS) | K32: Libellé du point | M32: Type d'équipement | O32: Type de matériel | AB32: =ROW(A32)- $AD$2 +1 -> 20 | AC32: =IF(AND($E32="Oui",$M32="Préleveur"),$F32,"") | AD32: {=IFERROR(INDEX($AC$14:$AC$96,SMALL(IF($AC$14:$AC$96<>"",ROW($AC$14:$AC$96)-ROW(INDIRECT("$AC$13"))+1),ROW(INDIRECT("A" & AB32 ) ))),"")} | AE32: =IF(AND($E32="Oui",LEFT($M32,10) ="Débitmètre"),$F32,"") | AF32: {=IFERROR(INDEX($AE$14:$AE$96,SMALL(IF($AE$14:$AE$96<>"",ROW($AE$14:$AE$96)-ROW(INDIRECT("$AE$13"))+1),ROW(INDIRECT("A" & AB32 ) ))),"")} | AG32: =IF(AND($E32="Oui",LEFT($M32,5) ="Sonde"),$F32,"") | AH32: {=IFERROR(INDEX($AG$14:$AG$96,SMALL(IF($AG$14:$AG$96<>"",ROW($AG$14:$AG$96)-ROW(INDIRECT("$AG$13"))+1),ROW(INDIRECT("A" & AB32 ) ))),"")} | AI32: =IF(AND($E32="Oui",$F32<>"",$M32=""),$F32,"") | AJ32: {=IFERROR(INDEX($AI$14:$AI$96,SMALL(IF($AI$14:$AI$96<>"",ROW($AI$14:$AI$96)-ROW(INDIRECT("$AI$13"))+1),ROW(INDIRECT("A" & AB32 ) ))),"")}
E33: Oui | F33: A2_P100_Q_Grav | H33: A2 | I33: =IF(ISBLANK(A2_P100_Q_Grav!J5), "", A2_P100_Q_Grav!J5) -> A2 | J33: =IF(ISBLANK(A2_P100_Q_Grav!J4), "", A2_P100_Q_Grav!J4) -> P100 | K33: =IF(ISBLANK(A2_P100_Q_Grav!J3), "", A2_P100_Q_Grav!J3) -> test | M33: Débitmètre gravitaire | O33: =IF(ISBLANK(A2_P100_Q_Grav!D40), "", A2_P100_Q_Grav!D40) -> Hauteur/Vitesse | R33: Gérer l'équipement | AB33: =ROW(A33)- $AD$2 +1 -> 21 | AC33: =IF(AND($E33="Oui",$M33="Préleveur"),$F33,"") | AD33: {=IFERROR(INDEX($AC$14:$AC$93,SMALL(IF($AC$14:$AC$93<>"",ROW($AC$14:$AC$93)-ROW(INDIRECT("$AC$13"))+1),ROW(INDIRECT("A" & AB33 ) ))),"")} | AE33: =IF(AND($E33="Oui",LEFT($M33,10) ="Débitmètre"),$F33,"") -> A2_P100_Q_Grav | AF33: {=IFERROR(INDEX($AE$14:$AE$93,SMALL(IF($AE$14:$AE$93<>"",ROW($AE$14:$AE$93)-ROW(INDIRECT("$AE$13"))+1),ROW(INDIRECT("A" & AB33 ) ))),"")} | AG33: =IF(AND($E33="Oui",LEFT($M33,5) ="Sonde"),$F33,"") | AH33: {=IFERROR(INDEX($AG$14:$AG$93,SMALL(IF($AG$14:$AG$93<>"",ROW($AG$14:$AG$93)-ROW(INDIRECT("$AG$13"))+1),ROW(INDIRECT("A" & AB33 ) ))),"")} | AI33: =IF(AND($E33="Oui", $M33 <> "", $M33 = ""),$F33,"") | AJ33: {=IFERROR(INDEX($AI$14:$AI$93,SMALL(IF($AI$14:$AI$93<>"",ROW($AI$14:$AI$93)-ROW(INDIRECT("$AI$13"))+1),ROW(INDIRECT("A" & AB33 ) ))),"")}
E34: Oui | F34: A3_P102_Q_DEM | H34: A3 | I34: =IF(ISBLANK(A3_P102_Q_DEM!J5), "", A3_P102_Q_DEM!J5) -> A3 | J34: =IF(ISBLANK(A3_P102_Q_DEM!J4), "", A3_P102_Q_DEM!J4) -> P102 | K34: =IF(ISBLANK(A3_P102_Q_DEM!J3), "", A3_P102_Q_DEM!J3) -> P102 | M34: Débitmètre en charge | O34: =IF(ISBLANK(A3_P102_Q_DEM!D32), "", A3_P102_Q_DEM!D32) -> Débitmètre électromagnétique (eau) | R34: Gérer l'équipement | AB34: =ROW(A34)- $AD$2 +1 -> 22 | AC34: =IF(AND($E34="Oui",$M34="Préleveur"),$F34,"") | AD34: {=IFERROR(INDEX($AC$14:$AC$95,SMALL(IF($AC$14:$AC$95<>"",ROW($AC$14:$AC$95)-ROW(INDIRECT("$AC$13"))+1),ROW(INDIRECT("A" & AB34 ) ))),"")} | AE34: =IF(AND($E34="Oui",LEFT($M34,10) ="Débitmètre"),$F34,"") -> A3_P102_Q_DEM | AF34: {=IFERROR(INDEX($AE$14:$AE$95,SMALL(IF($AE$14:$AE$95<>"",ROW($AE$14:$AE$95)-ROW(INDIRECT("$AE$13"))+1),ROW(INDIRECT("A" & AB34 ) ))),"")} | AG34: =IF(AND($E34="Oui",LEFT($M34,5) ="Sonde"),$F34,"") | AH34: {=IFERROR(INDEX($AG$14:$AG$95,SMALL(IF($AG$14:$AG$95<>"",ROW($AG$14:$AG$95)-ROW(INDIRECT("$AG$13"))+1),ROW(INDIRECT("A" & AB34 ) ))),"")} | AI34: =IF(AND($E34="Oui", $M34 <> "", $M34 = ""),$F34,"") | AJ34: {=IFERROR(INDEX($AI$14:$AI$95,SMALL(IF($AI$14:$AI$95<>"",ROW($AI$14:$AI$95)-ROW(INDIRECT("$AI$13"))+1),ROW(INDIRECT("A" & AB34 ) ))),"")}
E35: Oui | F35: A3_P102_PREL | H35: A3 | I35: =IF(ISBLANK(A3_P102_PREL!J5), "", A3_P102_PREL!J5) -> A3 | J35: =IF(ISBLANK(A3_P102_PREL!J4), "", A3_P102_PREL!J4) -> P102 | K35: =IF(ISBLANK(A3_P102_PREL!J3), "", A3_P102_PREL!J3) -> P102 | M35: Préleveur | O35: =IF(ISBLANK(A3_P102_PREL!D37), "", A3_P102_PREL!D37) -> Préleveur Automatique | R35: Gérer l'équipement | AB35: =ROW(A35)- $AD$2 +1 -> 23 | AC35: =IF(AND($E35="Oui",$M35="Préleveur"),$F35,"") -> A3_P102_PREL | AD35: {=IFERROR(INDEX($AC$14:$AC$98,SMALL(IF($AC$14:$AC$98<>"",ROW($AC$14:$AC$98)-ROW(INDIRECT("$AC$13"))+1),ROW(INDIRECT("A" & AB35 ) ))),"")} | AE35: =IF(AND($E35="Oui",LEFT($M35,10) ="Débitmètre"),$F35,"") | AF35: {=IFERROR(INDEX($AE$14:$AE$98,SMALL(IF($AE$14:$AE$98<>"",ROW($AE$14:$AE$98)-ROW(INDIRECT("$AE$13"))+1),ROW(INDIRECT("A" & AB35 ) ))),"")} | AG35: =IF(AND($E35="Oui",LEFT($M35,5) ="Sonde"),$F35,"") | AH35: {=IFERROR(INDEX($AG$14:$AG$98,SMALL(IF($AG$14:$AG$98<>"",ROW($AG$14:$AG$98)-ROW(INDIRECT("$AG$13"))+1),ROW(INDIRECT("A" & AB35 ) ))),"")} | AI35: =IF(AND($E35="Oui", $M35 <> "", $M35 = ""),$F35,"") | AJ35: {=IFERROR(INDEX($AI$14:$AI$98,SMALL(IF($AI$14:$AI$98<>"",ROW($AI$14:$AI$98)-ROW(INDIRECT("$AI$13"))+1),ROW(INDIRECT("A" & AB35 ) ))),"")}
E36: Oui | F36: A4_P103_Q_Grav | H36: A4 | I36: =IF(ISBLANK(A4_P103_Q_Grav!J5), "", A4_P103_Q_Grav!J5) -> A4 | J36: =IF(ISBLANK(A4_P103_Q_Grav!J4), "", A4_P103_Q_Grav!J4) -> P103 | K36: =IF(ISBLANK(A4_P103_Q_Grav!J3), "", A4_P103_Q_Grav!J3) -> P103 | M36: Débitmètre gravitaire | O36: =IF(ISBLANK(A4_P103_Q_Grav!D40), "", A4_P103_Q_Grav!D40) -> Canal Venturi | R36: Gérer l'équipement | AB36: =ROW(A36)- $AD$2 +1 -> 24 | AC36: =IF(AND($E36="Oui",$M36="Préleveur"),$F36,"") | AD36: {=IFERROR(INDEX($AC$14:$AC$98,SMALL(IF($AC$14:$AC$98<>"",ROW($AC$14:$AC$98)-ROW(INDIRECT("$AC$13"))+1),ROW(INDIRECT("A" & AB36 ) ))),"")} | AE36: =IF(AND($E36="Oui",LEFT($M36,10) ="Débitmètre"),$F36,"") -> A4_P103_Q_Grav | AF36: {=IFERROR(INDEX($AE$14:$AE$98,SMALL(IF($AE$14:$AE$98<>"",ROW($AE$14:$AE$98)-ROW(INDIRECT("$AE$13"))+1),ROW(INDIRECT("A" & AB36 ) ))),"")} | AG36: =IF(AND($E36="Oui",LEFT($M36,5) ="Sonde"),$F36,"") | AH36: {=IFERROR(INDEX($AG$14:$AG$98,SMALL(IF($AG$14:$AG$98<>"",ROW($AG$14:$AG$98)-ROW(INDIRECT("$AG$13"))+1),ROW(INDIRECT("A" & AB36 ) ))),"")} | AI36: =IF(AND($E36="Oui", $M36 <> "", $M36 = ""),$F36,"") | AJ36: {=IFERROR(INDEX($AI$14:$AI$98,SMALL(IF($AI$14:$AI$98<>"",ROW($AI$14:$AI$98)-ROW(INDIRECT("$AI$13"))+1),ROW(INDIRECT("A" & AB36 ) ))),"")}
E37: Oui | F37: A4_P103_PREL | H37: A4 | I37: =IF(ISBLANK(A4_P103_PREL!J5), "", A4_P103_PREL!J5) -> A4 | J37: =IF(ISBLANK(A4_P103_PREL!J4), "", A4_P103_PREL!J4) -> P103 | K37: =IF(ISBLANK(A4_P103_PREL!J3), "", A4_P103_PREL!J3) -> P103 | M37: Préleveur | O37: =IF(ISBLANK(A4_P103_PREL!D37), "", A4_P103_PREL!D37) -> Préleveur Automatique | R37: Gérer l'équipement | AB37: =ROW(A37)- $AD$2 +1 -> 25 | AC37: =IF(AND($E37="Oui",$M37="Préleveur"),$F37,"") -> A4_P103_PREL | AD37: {=IFERROR(INDEX($AC$14:$AC$97,SMALL(IF($AC$14:$AC$97<>"",ROW($AC$14:$AC$97)-ROW(INDIRECT("$AC$13"))+1),ROW(INDIRECT("A" & AB37 ) ))),"")} | AE37: =IF(AND($E37="Oui",LEFT($M37,10) ="Débitmètre"),$F37,"") | AF37: {=IFERROR(INDEX($AE$14:$AE$97,SMALL(IF($AE$14:$AE$97<>"",ROW($AE$14:$AE$97)-ROW(INDIRECT("$AE$13"))+1),ROW(INDIRECT("A" & AB37 ) ))),"")} | AG37: =IF(AND($E37="Oui",LEFT($M37,5) ="Sonde"),$F37,"") | AH37: {=IFERROR(INDEX($AG$14:$AG$97,SMALL(IF($AG$14:$AG$97<>"",ROW($AG$14:$AG$97)-ROW(INDIRECT("$AG$13"))+1),ROW(INDIRECT("A" & AB37 ) ))),"")} | AI37: =IF(AND($E37="Oui", $M37 <> "", $M37 = ""),$F37,"") | AJ37: {=IFERROR(INDEX($AI$14:$AI$97,SMALL(IF($AI$14:$AI$97<>"",ROW($AI$14:$AI$97)-ROW(INDIRECT("$AI$13"))+1),ROW(INDIRECT("A" & AB37 ) ))),"")}
E38: Oui | F38: A6_P104_Q_DEM | H38: A6 | I38: =IF(ISBLANK(A6_P104_Q_DEM!J5), "", A6_P104_Q_DEM!J5) -> A6 | J38: =IF(ISBLANK(A6_P104_Q_DEM!J4), "", A6_P104_Q_DEM!J4) -> P104 | K38: =IF(ISBLANK(A6_P104_Q_DEM!J3), "", A6_P104_Q_DEM!J3) -> P104 | M38: Débitmètre en charge | O38: =IF(ISBLANK(A6_P104_Q_DEM!D32), "", A6_P104_Q_DEM!D32) -> Débitmètre électromagnétique (boue/MDV) | R38: Gérer l'équipement | AB38: =ROW(A38)- $AD$2 +1 -> 26 | AC38: =IF(AND($E38="Oui",$M38="Préleveur"),$F38,"") | AD38: {=IFERROR(INDEX($AC$14:$AC$96,SMALL(IF($AC$14:$AC$96<>"",ROW($AC$14:$AC$96)-ROW(INDIRECT("$AC$13"))+1),ROW(INDIRECT("A" & AB38 ) ))),"")} | AE38: =IF(AND($E38="Oui",LEFT($M38,10) ="Débitmètre"),$F38,"") -> A6_P104_Q_DEM | AF38: {=IFERROR(INDEX($AE$14:$AE$96,SMALL(IF($AE$14:$AE$96<>"",ROW($AE$14:$AE$96)-ROW(INDIRECT("$AE$13"))+1),ROW(INDIRECT("A" & AB38 ) ))),"")} | AG38: =IF(AND($E38="Oui",LEFT($M38,5) ="Sonde"),$F38,"") | AH38: {=IFERROR(INDEX($AG$14:$AG$96,SMALL(IF($AG$14:$AG$96<>"",ROW($AG$14:$AG$96)-ROW(INDIRECT("$AG$13"))+1),ROW(INDIRECT("A" & AB38 ) ))),"")} | AI38: =IF(AND($E38="Oui", $M38 <> "", $M38 = ""),$F38,"") | AJ38: {=IFERROR(INDEX($AI$14:$AI$96,SMALL(IF($AI$14:$AI$96<>"",ROW($AI$14:$AI$96)-ROW(INDIRECT("$AI$13"))+1),ROW(INDIRECT("A" & AB38 ) ))),"")}
E39: Oui | F39: A4_P103_TEMP | H39: A4 | I39: =IF(ISBLANK(A4_P103_TEMP!J5), "", A4_P103_TEMP!J5) -> A4 | J39: =IF(ISBLANK(A4_P103_TEMP!J4), "", A4_P103_TEMP!J4) -> P103 | K39: =IF(ISBLANK(A4_P103_TEMP!J4), "", A4_P103_TEMP!J4) -> P103 | M39: Sonde de température | R39: Gérer l'équipement | AB39: =ROW(A39)- $AD$2 +1 -> 27 | AC39: =IF(AND($E39="Oui",$M39="Préleveur"),$F39,"") | AD39: {=IFERROR(INDEX($AC$14:$AC$95,SMALL(IF($AC$14:$AC$95<>"",ROW($AC$14:$AC$95)-ROW(INDIRECT("$AC$13"))+1),ROW(INDIRECT("A" & AB39 ) ))),"")} | AE39: =IF(AND($E39="Oui",LEFT($M39,10) ="Débitmètre"),$F39,"") | AF39: {=IFERROR(INDEX($AE$14:$AE$95,SMALL(IF($AE$14:$AE$95<>"",ROW($AE$14:$AE$95)-ROW(INDIRECT("$AE$13"))+1),ROW(INDIRECT("A" & AB39 ) ))),"")} | AG39: =IF(AND($E39="Oui",LEFT($M39,5) ="Sonde"),$F39,"") -> A4_P103_TEMP | AH39: {=IFERROR(INDEX($AG$14:$AG$95,SMALL(IF($AG$14:$AG$95<>"",ROW($AG$14:$AG$95)-ROW(INDIRECT("$AG$13"))+1),ROW(INDIRECT("A" & AB39 ) ))),"")} | AI39: =IF(AND($E39="Oui", $M39 <> "", $M39 = ""),$F39,"") | AJ39: {=IFERROR(INDEX($AI$14:$AI$95,SMALL(IF($AI$14:$AI$95<>"",ROW($AI$14:$AI$95)-ROW(INDIRECT("$AI$13"))+1),ROW(INDIRECT("A" & AB39 ) ))),"")}
J40: ok | L40: ok | AB40: =ROW(A40)- $AD$2 +1 -> 28 | AC40: =IF(AND($E40="Oui",$M40="Préleveur"),$F40,"") | AD40: {=IFERROR(INDEX($AC$14:$AC$96,SMALL(IF($AC$14:$AC$96<>"",ROW($AC$14:$AC$96)-ROW(INDIRECT("$AC$13"))+1),ROW(INDIRECT("A" & AB40 ) ))),"")} | AE40: =IF(AND($E40="Oui",LEFT($M40,10) ="Débitmètre"),$F40,"") | AF40: {=IFERROR(INDEX($AE$14:$AE$96,SMALL(IF($AE$14:$AE$96<>"",ROW($AE$14:$AE$96)-ROW(INDIRECT("$AE$13"))+1),ROW(INDIRECT("A" & AB40 ) ))),"")} | AG40: =IF(AND($E40="Oui",LEFT($M40,5) ="Sonde"),$F40,"") | AH40: {=IFERROR(INDEX($AG$14:$AG$96,SMALL(IF($AG$14:$AG$96<>"",ROW($AG$14:$AG$96)-ROW(INDIRECT("$AG$13"))+1),ROW(INDIRECT("A" & AB40 ) ))),"")} | AI40: =IF(AND($E40="Oui",$F40<>"",$M40=""),$F40,"") | AJ40: {=IFERROR(INDEX($AI$14:$AI$96,SMALL(IF($AI$14:$AI$96<>"",ROW($AI$14:$AI$96)-ROW(INDIRECT("$AI$13"))+1),ROW(INDIRECT("A" & AB40 ) ))),"")}
E41: Ajouter un équipement station | H41: ok | AB41: =ROW(A41)- $AD$2 +1 -> 29 | AC41: =IF(AND($E41="Oui",$M41="Préleveur"),$F41,"") | AD41: {=IFERROR(INDEX($AC$14:$AC$96,SMALL(IF($AC$14:$AC$96<>"",ROW($AC$14:$AC$96)-ROW(INDIRECT("$AC$13"))+1),ROW(INDIRECT("A" & AB41 ) ))),"")} | AE41: =IF(AND($E41="Oui",LEFT($M41,10) ="Débitmètre"),$F41,"") | AF41: {=IFERROR(INDEX($AE$14:$AE$96,SMALL(IF($AE$14:$AE$96<>"",ROW($AE$14:$AE$96)-ROW(INDIRECT("$AE$13"))+1),ROW(INDIRECT("A" & AB41 ) ))),"")} | AG41: =IF(AND($E41="Oui",LEFT($M41,5) ="Sonde"),$F41,"") | AH41: {=IFERROR(INDEX($AG$14:$AG$96,SMALL(IF($AG$14:$AG$96<>"",ROW($AG$14:$AG$96)-ROW(INDIRECT("$AG$13"))+1),ROW(INDIRECT("A" & AB41 ) ))),"")} | AI41: =IF(AND($E41="Oui",$F41<>"",$M41=""),$F41,"") | AJ41: {=IFERROR(INDEX($AI$14:$AI$96,SMALL(IF($AI$14:$AI$96<>"",ROW($AI$14:$AI$96)-ROW(INDIRECT("$AI$13"))+1),ROW(INDIRECT("A" & AB41 ) ))),"")}
AB42: =ROW(A42)- $AD$2 +1 -> 30 | AC42: =IF(AND($E42="Oui",$M42="Préleveur"),$F42,"") | AD42: {=IFERROR(INDEX($AC$14:$AC$96,SMALL(IF($AC$14:$AC$96<>"",ROW($AC$14:$AC$96)-ROW(INDIRECT("$AC$13"))+1),ROW(INDIRECT("A" & AB42 ) ))),"")} | AE42: =IF(AND($E42="Oui",LEFT($M42,10) ="Débitmètre"),$F42,"") | AF42: {=IFERROR(INDEX($AE$14:$AE$96,SMALL(IF($AE$14:$AE$96<>"",ROW($AE$14:$AE$96)-ROW(INDIRECT("$AE$13"))+1),ROW(INDIRECT("A" & AB42 ) ))),"")} | AG42: =IF(AND($E42="Oui",LEFT($M42,5) ="Sonde"),$F42,"") | AH42: {=IFERROR(INDEX($AG$14:$AG$96,SMALL(IF($AG$14:$AG$96<>"",ROW($AG$14:$AG$96)-ROW(INDIRECT("$AG$13"))+1),ROW(INDIRECT("A" & AB42 ) ))),"")} | AI42: =IF(AND($E42="Oui",$F42<>"",$M42=""),$F42,"") | AJ42: {=IFERROR(INDEX($AI$14:$AI$96,SMALL(IF($AI$14:$AI$96<>"",ROW($AI$14:$AI$96)-ROW(INDIRECT("$AI$13"))+1),ROW(INDIRECT("A" & AB42 ) ))),"")}
AB43: =ROW(A43)- $AD$2 +1 -> 31 | AC43: =IF(AND($E43="Oui",$M43="Préleveur"),$F43,"") | AD43: {=IFERROR(INDEX($AC$14:$AC$96,SMALL(IF($AC$14:$AC$96<>"",ROW($AC$14:$AC$96)-ROW(INDIRECT("$AC$13"))+1),ROW(INDIRECT("A" & AB43 ) ))),"")} | AE43: =IF(AND($E43="Oui",LEFT($M43,10) ="Débitmètre"),$F43,"") | AF43: {=IFERROR(INDEX($AE$14:$AE$96,SMALL(IF($AE$14:$AE$96<>"",ROW($AE$14:$AE$96)-ROW(INDIRECT("$AE$13"))+1),ROW(INDIRECT("A" & AB43 ) ))),"")} | AG43: =IF(AND($E43="Oui",LEFT($M43,5) ="Sonde"),$F43,"") | AH43: {=IFERROR(INDEX($AG$14:$AG$96,SMALL(IF($AG$14:$AG$96<>"",ROW($AG$14:$AG$96)-ROW(INDIRECT("$AG$13"))+1),ROW(INDIRECT("A" & AB43 ) ))),"")} | AI43: =IF(AND($E43="Oui",$F43<>"",$M43=""),$F43,"") | AJ43: {=IFERROR(INDEX($AI$14:$AI$96,SMALL(IF($AI$14:$AI$96<>"",ROW($AI$14:$AI$96)-ROW(INDIRECT("$AI$13"))+1),ROW(INDIRECT("A" & AB43 ) ))),"")}
D44: Liste des pluviomètres de la station | AB44: =ROW(A44)- $AD$2 +1 -> 32 | AC44: =IF(AND($E44="Oui",$M44="Préleveur"),$F44,"") | AD44: {=IFERROR(INDEX($AC$14:$AC$96,SMALL(IF($AC$14:$AC$96<>"",ROW($AC$14:$AC$96)-ROW(INDIRECT("$AC$13"))+1),ROW(INDIRECT("A" & AB44 ) ))),"")} | AE44: =IF(AND($E44="Oui",LEFT($M44,10) ="Débitmètre"),$F44,"") | AF44: {=IFERROR(INDEX($AE$14:$AE$96,SMALL(IF($AE$14:$AE$96<>"",ROW($AE$14:$AE$96)-ROW(INDIRECT("$AE$13"))+1),ROW(INDIRECT("A" & AB44 ) ))),"")} | AG44: =IF(AND($E44="Oui",LEFT($M44,5) ="Sonde"),$F44,"") | AH44: {=IFERROR(INDEX($AG$14:$AG$96,SMALL(IF($AG$14:$AG$96<>"",ROW($AG$14:$AG$96)-ROW(INDIRECT("$AG$13"))+1),ROW(INDIRECT("A" & AB44 ) ))),"")} | AI44: =IF(AND($E44="Oui",$F44<>"",$M44=""),$F44,"") | AJ44: {=IFERROR(INDEX($AI$14:$AI$96,SMALL(IF($AI$14:$AI$96<>"",ROW($AI$14:$AI$96)-ROW(INDIRECT("$AI$13"))+1),ROW(INDIRECT("A" & AB44 ) ))),"")}
...

Sheet SYNTHESE
C2: CONTRÔLE ANNUEL DES DISPOSITIFS D'AUTOSURVEILLANCE DES SYSTÈMES D'ASSAINISSEMENT COLLECTIF
C3: NOM DU SYSTÈME D'ASSAINISSEMENT : | G3: =IF(ISBLANK(Descriptif!G3),"",Descriptif!G3) -> BARJAC (30) | K3: NOM SYSTÈME DE TRAITEMENT : | N3: =IF(ISBLANK(Descriptif!N3),"",Descriptif!N3) -> BARJAC (30) | T3: NOM SYSTÈME DE COLLECTE : | Y3: =IF(ISBLANK(Descriptif!T3),"",Descriptif!T3)
C4: CODE SANDRE DE L'AGGLOMERATION : | G4: =IF(ISBLANK(Descriptif!G4),"",Descriptif!G4) | K4: CODE SANDRE DE LA STATION : | N4: =IF(ISBLANK(Descriptif!N4),"",Descriptif!N4) -> 060930290002 | T4: CODE SANDRE DU RESEAU : | Y4: =IF(ISBLANK(Descriptif!T4),"",Descriptif!T4)
C5: NOM DU MAITRE D'OUVRAGE : | G5: =IF(ISBLANK(Descriptif!G5),"",Descriptif!G5) -> Commune de Barjac | K5: CAPACITE DE LA STATION : | N5: =IF(ISBLANK(Descriptif!N5),"",Descriptif!N5) -> 5 000 EH | T5: EXPLOITANT DU RESEAU : | Y5: =IF(ISBLANK(Descriptif!T5),"",Descriptif!T5)
C6: ORGANISME DE CONTRÔLE : | G6: =IF(ISBLANK(Descriptif!G6),"",Descriptif!G6) -> CEREG Ingénierie | K6: EXPLOITANT DE LA STATION : | N6: =IF(ISBLANK(Descriptif!N6),"",Descriptif!N6) -> Régie | T6: NOM DU LABORATOIRE : | Y6: =IF(ISBLANK(Analytique!O3),"",Analytique!O3) -> test labo
C8: EVALUATIONS
D10: Evaluation des points règlementaires
G11: ENTREE et SORTIE | J11: Score | L11: DEVERSEMENT STATION | P11: Score | T11: BOUE et Apports extérieurs | Y11: Score
G12: Point A3 | I12: =IF(Recap_equipements!E115<>"",Recap_equipements!E115,"") -> Non validé | J12: =Recap_equipements!E62 -> 78.333333 | L12: Point A2 | N12: =IF(Recap_equipements!E127<>"",Recap_equipements!E127,"") -> Validé avec réserve | P12: =Recap_equipements!E74 -> 80 | T12: Point A6 | X12: =IF(Recap_equipements!E139<>"",Recap_equipements!E139,"") -> Non validé | Y12: =Recap_equipements!E86 -> 40
G13: Débitmètre | I13: =IF(Recap_equipements!F117<>"",Recap_equipements!F117,"") -> Non validé | J13: =IF(Recap_equipements!F64<>"",Recap_equipements!F64,"") -> 60 | L13: Débitmètre | N13: =IF(Recap_equipements!F129<>"",Recap_equipements!F129,"") -> Validé avec réserve | P13: =Recap_equipements!F76 -> 80 | T13: Débitmètre | X13: =IF(Recap_equipements!F141<>"",Recap_equipements!F141,"") -> Non validé | Y13: =Recap_equipements!F88 -> 40
G14: Préleveur | I14: =IF(Recap_equipements!F118<>"",Recap_equipements!F118,"") -> Validé | J14: =IF(Recap_equipements!F65<>"",Recap_equipements!F65,"") -> 85 | L14: Préleveur | N14: =IF(Recap_equipements!F130<>"",Recap_equipements!F130,"") | P14: =Recap_equipements!F77 | T14: Préleveur | X14: =IF(Recap_equipements!F142<>"",Recap_equipements!F142,"") | Y14: =Recap_equipements!F89
G15: Analytique | I15: =IF(Recap_equipements!F119<>"",Recap_equipements!F119,"") -> Validé | J15: =IF(Recap_equipements!F66<>"",Recap_equipements!F66,"") -> 90 | L15: Analytique | N15: =IF(Recap_equipements!F131<>"",Recap_equipements!F131,"") | P15: =Recap_equipements!F78 | T15: Analytique | X15: =IF(Recap_equipements!F143<>"",Recap_equipements!F143,"") | Y15: =Recap_equipements!F90
G16: Point A4 | I16: =IF(Recap_equipements!E121<>"",Recap_equipements!E121,"") -> Non validé | J16: =Recap_equipements!E68 -> 63.333333 | L16: Point A5 | N16: =IF(Recap_equipements!E133<>"",Recap_equipements!E133,"") | P16: =Recap_equipements!E80 | T16: Point A7 | X16: =IF(Recap_equipements!E145<>"",Recap_equipements!E145,"") | Y16: =Recap_equipements!E92
G17: Débitmètre | I17: =IF(Recap_equipements!F123<>"",Recap_equipements!F123,"") -> Non validé | J17: =IF(Recap_equipements!F70<>"",Recap_equipements!F70,"") -> 0 | L17: Débitmètre | N17: =IF(Recap_equipements!F135<>"",Recap_equipements!F135,"") | P17: =Recap_equipements!F82 | T17: Débitmètre | X17: =IF(Recap_equipements!F147<>"",Recap_equipements!F147,"") | Y17: =Recap_equipements!F94
G18: Préleveur | I18: =IF(Recap_equipements!F124<>"",Recap_equipements!F124,"") -> Validé | J18: =IF(Recap_equipements!F71<>"",Recap_equipements!F71,"") -> 100 | L18: Préleveur | N18: =IF(Recap_equipements!F136<>"",Recap_equipements!F136,"") | P18: =Recap_equipements!F83 | T18: Préleveur | X18: =IF(Recap_equipements!F148<>"",Recap_equipements!F148,"") | Y18: =Recap_equipements!F95
G19: Analytique | I19: =IF(Recap_equipements!F125<>"",Recap_equipements!F125,"") -> Validé | J19: =IF(Recap_equipements!F72<>"",Recap_equipements!F72,"") -> 90 | L19: Analytique | N19: =IF(Recap_equipements!F137<>"",Recap_equipements!F137,"") | P19: =Recap_equipements!F84 | T19: Analytique | X19: =IF(Recap_equipements!F149<>"",Recap_equipements!F149,"") | Y19: =Recap_equipements!F96
D22: Evaluation documentaire | O22: Commentaire évaluation :
F23: ok | G23: Manuel d'autosurveillance à jour ou en cours d'expertise | K23: =IF(Qualité!L10<>"",Qualité!L10,"Non contrôlé") -> Validé | M23: Coef Qualité | O23: =IF(Qualité!D29<>"",Qualité!D29,"") -> Le système Qualité mis en œuvre est performant.
G24: Système qualité interne suivi AS | K24: =IF(Qualité!L26<>"",Qualité!L26,"Non contrôlé") -> Validé | M24: =IF(Qualité!L26="Non validé",0.9,1) -> 1
D27: Evaluation des pratiques analytiques | N27: Commentaire évaluation :
G28: EAU | I28: Fractionnement | K28: =Analytique!L12 -> Validé | N28: =IF(Analytique!D31<>"",Analytique!D31,"")
I29: Température | K29: =Analytique!L13 -> Validé
I30: Transport | K30: =Analytique!L14 -> Validé
I31: Analytique | K31: =IF(Analytique!Q27<>"",Analytique!Q27,"") -> Validé
I32: Conclusion | K32: =IF(Analytique!J29<>"",Analytique!J29,"") -> Validé
G33: SDE | I33: Aquaref | K33: =Analytique!L11 -> Non validé
D36: Autres évaluations
G37: Sonde température | I37: {=IFERROR(INDEX(Equipements!$K$16:$K$72,SMALL(IF(Equipements!$I$16:$I$72="Sonde de température",ROW(Equipements!$I$16:$I$72)-ROW(Equipements!$I$16)+1),ROW(1:1))),"")} -> A4_P103_TEMP | K37: {=IFERROR(INDEX(Equipements!$P$16:$P$72,SMALL(IF(Equipements!$I$16:$I$72="Sonde de température",ROW(Equipements!$I$16:$I$72)-ROW(Equipements!$I$16)+1),ROW(1:1))),"")} -> Validé avec réserve | P37: Pluviomètre | T37: {=IFERROR(INDEX(Equipements!$K$16:$K$72,SMALL(IF(Equipements!$I$16:$I$72="Pluviomètre",ROW(Equipements!$I$16:$I$72)-ROW(Equipements!$I$16)+1),ROW(1:1))),"")} -> PLUVIO_SCL_ooo | X37: {=IFERROR(INDEX(Equipements!$P$16:$P$72,SMALL(IF(Equipements!$I$16:$I$72="Pluviomètre",ROW(Equipements!$I$16:$I$72)-ROW(Equipements!$I$16)+1),ROW(1:1))),"")}
I38: {=IFERROR(INDEX(Equipements!$K$16:$K$72,SMALL(IF(Equipements!$I$16:$I$72="Sonde de température",ROW(Equipements!$I$16:$I$72)-ROW(Equipements!$I$16)+1),ROW(2:2))),"")} | K38: {=IFERROR(INDEX(Equipements!$P$16:$P$72,SMALL(IF(Equipements!$I$16:$I$72="Sonde de température",ROW(Equipements!$I$16:$I$72)-ROW(Equipements!$I$16)+1),ROW(2:2))),"")} | M38: Ok | T38: {=IFERROR(INDEX(Equipements!$K$16:$K$72,SMALL(IF(Equipements!$I$16:$I$72="Pluviomètre",ROW(Equipements!$I$16:$I$72)-ROW(Equipements!$I$16)+1),ROW(2:2))),"")} -> PLUVIO_STEU_P1 | X38: {=IFERROR(INDEX(Equipements!$P$16:$P$72,SMALL(IF(Equipements!$I$16:$I$72="Pluviomètre",ROW(Equipements!$I$16:$I$72)-ROW(Equipements!$I$16)+1),ROW(2:2))),"")} -> Validé avec réserve | Z38: Ok
I39: {=IFERROR(INDEX(Equipements!$K$16:$K$72,SMALL(IF(Equipements!$I$16:$I$72="Sonde de température",ROW(Equipements!$I$16:$I$72)-ROW(Equipements!$I$16)+1),ROW(3:3))),"")} | K39: {=IFERROR(INDEX(Equipements!$P$16:$P$72,SMALL(IF(Equipements!$I$16:$I$72="Sonde de température",ROW(Equipements!$I$16:$I$72)-ROW(Equipements!$I$16)+1),ROW(3:3))),"")} | T39: {=IFERROR(INDEX(Equipements!$K$16:$K$72,SMALL(IF(Equipements!$I$16:$I$72="Pluviomètre",ROW(Equipements!$I$16:$I$72)-ROW(Equipements!$I$16)+1),ROW(3:3))),"")} | X39: {=IFERROR(INDEX(Equipements!$P$16:$P$72,SMALL(IF(Equipements!$I$16:$I$72="Pluviomètre",ROW(Equipements!$I$16:$I$72)-ROW(Equipements!$I$16)+1),ROW(3:3))),"")}
G40: Commentaire évaluation :
D45: Commentaire général
C51: SYNTHESE DISPOSITIFS AUTOSURVEILLANCE DE LA STATION D'ÉPURATION
D53: Détails des équipements contrôlés | M53: Score sur 100 | N53: Critères d'évaluation | X53: Commentaires d'évaluation
D54: Libellé | F54: Localisation | G54: Type | I54: Type d'équipement | K54: Evaluation controleur | N54: 1 | O54: 2 | P54: 3 | Q54: 4 | R54: 5 | S54: 6 | T54: 7 | U54: 8 | V54: 9 | W54: 10
D55: =Equipements!G16 -> A1_DO1_Q_Grav | F55: =Equipements!H16 -> A1 | G55: =Equipements!I16 -> Débitmètre gravitaire | I55: =Equipements!J16 -> Seuil | K55: =Equipements!P16 -> Validé | M55: =Equipements!N16 -> 100 | N55: =Equipements!W16 -> Validé | O55: =Equipements!X16 -> Validé | P55: =Equipements!Y16 -> Validé | Q55: =Equipements!Z16 -> Validé | R55: =Equipements!AA16 -> Validé | S55: =Equipements!AB16 -> Validé | T55: =Equipements!AC16 -> Validé | U55: =Equipements!AD16 -> Validé | ... W55: =Equipements!AF16 -> Oui | X55: =IF(Equipements!R16<>"",Equipements!R16,"") -> aaaaaaaa
D56: =Equipements!G17 -> PLUVIO_SCL_ooo | F56: =Equipements!H17 -> A1 | G56: =Equipements!I17 -> Pluviomètre | I56: =Equipements!J17 -> Pluviomètre | K56: =Equipements!P17 | M56: =Equipements!N17 -> 0 | N56: =Equipements!W17 | O56: =Equipements!X17 -> Non contrôlé | P56: =Equipements!Y17 | Q56: =Equipements!Z17 | R56: =Equipements!AA17 -> Non contrôlé | S56: =Equipements!AB17 -> Evaluation finale | T56: =Equipements!AC17 | U56: =Equipements!AD17 | ... W56: =Equipements!AF17 | X56: =IF(Equipements!R17<>"",Equipements!R17,"")
D57: =Equipements!G18 -> A2_P100_Q_Grav | F57: =Equipements!H18 -> A2 | G57: =Equipements!I18 -> Débitmètre gravitaire | I57: =Equipements!J18 -> Hauteur/Vitesse | K57: =Equipements!P18 -> Validé avec réserve | M57: =Equipements!N18 -> 80 | N57: =Equipements!W18 -> Validé | O57: =Equipements!X18 -> Validé | P57: =Equipements!Y18 -> Validé | Q57: =Equipements!Z18 -> Validé | R57: =Equipements!AA18 -> Validé | S57: =Equipements!AB18 -> Validé | T57: =Equipements!AC18 -> Non contrôlé | U57: =Equipements!AD18 -> Non contrôlé | ... W57: =Equipements!AF18 -> Oui | X57: =IF(Equipements!R18<>"",Equipements!R18,"")
D58: =Equipements!G19 -> A3_P102_Q_DEM | F58: =Equipements!H19 -> A3 | G58: =Equipements!I19 -> Débitmètre en charge | I58: =Equipements!J19 -> Débitmètre électromagnétique (eau) | K58: =Equipements!P19 -> Non Validé | M58: =Equipements!N19 -> 60 | N58: =Equipements!W19 -> Validé | O58: =Equipements!X19 -> Validé | P58: =Equipements!Y19 -> Validé | Q58: =Equipements!Z19 -> Non validé (>10%) | R58: =Equipements!AA19 -> Non validé | S58: =Equipements!AB19 -> Non validé | T58: =Equipements!AC19 -> Non validé | U58: =Equipements!AD19 -> Validé | ... W58: =Equipements!AF19 | X58: =IF(Equipements!R19<>"",Equipements!R19,"") -> Le dispositif en place
D59: =Equipements!G20 -> A3_P102_PREL | F59: =Equipements!H20 -> A3 | G59: =Equipements!I20 -> Préleveur | I59: =Equipements!J20 -> Préleveur Automatique | K59: =Equipements!P20 -> Validé | M59: =Equipements!N20 -> 85 | N59: =Equipements!W20 -> Validé | O59: =Equipements!X20 -> Non validé | P59: =Equipements!Y20 -> Validé | Q59: =Equipements!Z20 -> Validé | R59: =Equipements!AA20 -> Validé | S59: =Equipements!AB20 -> Validé | T59: =Equipements!AC20 -> Validé | U59: =Equipements!AD20 -> Validé | ... W59: =Equipements!AF20 -> Validé | X59: =IF(Equipements!R20<>"",Equipements!R20,"") -> Pb de positionnement
...

Sheet PARAM
A3: Equipement Q | B3: Equipement Prel | C3: Type | D3: Liste des statuts | E3: Code | F3: Code | G3: Liste des statuts | H3: Liste des statuts | I3: Code
A4: Canal Venturi | B4: Préleveur Automatique | C4: Débitmètre en charge | D4: Validé | E4: A2 | F4: A1 | G4: Oui | H4: Agréé | I4: A2
A5: Débitmètre électromagnétique (eau) | B5: Vanne de prélèvement asservie | C5: Débitmètre gravitaire | D5: Non validé | E5: A3 | F5: R1 | G5: Non | H5: Non agréé | I5: A3
A6: Débitmètre électromagnétique (boue/MDV) | B6: Prélèvement ponctuel | C6: Préleveur | D6: Non contrôlé | E6: A4 | F6: R2 | I6: A4
A7: Seuil | C7: Sonde de température | D7: Validé avec réserve | E7: A5 | F7: R3 | I7: A5
A8: Caisson | D8: Non validé (absence d'équipement) | E8: A6 | I8: A6
A9: Loi COACHs | D9: Non validé (équipement insuffisant) | E9: A7 | I9: A7
A10: Débitmètre électromagnétique partiellement plein | E10: A8 | I10: A8
A11: Clapet | E11: S1 | I11: S1
A12: Détecteur de surverse | E12: S2 | I12: S2
A13: Modélisation | E13: S3 | I13: S3
A14: Hauteur/Vitesse | E14: S4 | I14: S4
A15: Point non existant | E15: S5 | I15: S5
E16: S12 | I16: S12
E17: S13 | I17: S13
E18: S16 | I18: S16
E19: S19 | I19: S19
A20: LISTE_1 | B20: LISTE_2 | C20: LISTE_3 | D20: LISTE_4 | F20: LISTE_5
A21: Oui | B21: Validé | C21: Validé | D21: Validé | F21: Validé
A22: Non | B22: Non validé | C22: Non validé | D22: Non validé | F22: Entre 5 et 10%
B23: Non contrôlé | C23: Non contrôlé | D23: Non contrôlé | F23: Non validé (>10%)
C24: Validé avec réserve | D24: Validé avec réserve | F24: Non contrôlé
D25: Non validé (absence d'équipement)
D26: Non validé (équipement insuffisant)
A28: Type équipement : débimètre
A29: Q en charge | B29: Q Gravitaire | C29: Equipement de contrôle H
A30: Débitmètre électromagnétique (eau) | B30: Canal Venturi | C30: Réglet
A31: Débitmètre électromagnétique (boue/MDV) | B31: Seuil | C31: Sonde
A32: Organe deprimogène (pito...) | B32: Caisson | C32: Câble
A33: Débitmètre Ultrason | B33: Loi COACHs
A34: Modélisation | B34: Débitmètre électromagnétique partiellement plein
A35: compteur mécanique | B35: Clapet
A36: Point non existant | B36: Détecteur de surverse
B37: Modélisation
B38: Hauteur/Vitesse
B39: Point non existant
A42: Listes fiches terrain
A43: Asservissement | B43: Conformité | C43: Type_capteur | D43: Satisfaction | E43: Fréquence | F43: Conditions météo | G43: Montage sonde
A44: Au débit | B44: Conforme | C44: Ultrason | D44: Satisfaisant | E44: Journalière | F44: Temps sec | G44: En /
A45: Au temps | B45: Conforme avec réserve | C45: Radar | D45: Non satisfaisant | E45: Hebdomadaire | F45: Temps de pluie | G45: En V
...

Sheet Recap_equipements
B1: Préparation des données pour la feuilles synthèse et pour les exports
B2: Paramètres de localisation des données dans les cellules
B4: Facteur Qualité | D4: Type Equipement | E4: Type
B5: =IF(Qualité!L26="Non validé",0.9,1) -> 1 | E5: cellule typeE | F5: cellule score | G5: cellule eval | H5: cellule commentaire score | I5: cellule commentaire
D6: Pluviomètre | E6: D24 | F6: P32 | G6: N32 | H6: D32 | I6: C36
D7: =PARAM!$C4 -> Débitmètre en charge | E7: D32 | F7: P45 | G7: N45 | H7: D45 | I7: C49
D8: =PARAM!$C5 -> Débitmètre gravitaire | E8: D40 | F8: P53 | G8: N53 | H8: D53 | I8: C57
D9: =PARAM!$C6 -> Préleveur | E9: D37 | F9: P50 | G9: N50 | H9: D50 | I9: C54
D10: =PARAM!$C7 -> Sonde de température | E10: D26 | F10: P33 | G10: N33 | H10: D33 | I10: C37
D12: Type ligne | E12: Ligne
D13: Ligne STEU | E13: =Descriptif!$AD$3 -> 33 | F13: =E13+1 -> 34 | G13: =F13+1 -> 35 | H13: =G13+1 -> 36 | I13: =H13+1 -> 37 | J13: =I13+1 -> 38 | K13: =J13+1 -> 39 | L13: =K13+1 -> 40 | M13: =L13+1 -> 41 | ... S13: =R13+1 -> 47
D14: Ligne SCL | E14: =Descriptif!$AD$2 -> 13 | F14: =E14+1 -> 14 | G14: =F14+1 -> 15 | H14: =G14+1 -> 16 | I14: =H14+1 -> 17 | J14: =I14+1 -> 18 | K14: =J14+1 -> 19 | L14: =K14+1 -> 20 | M14: =L14+1 -> 21 | ... S14: =R14+1 -> 27
B16: Identification des feuilles de données
B18: Reg. | C18: Log. | F18: Point 1 | G18: Point 2 | H18: Point 3 | I18: Point 4 | J18: Point 5 | K18: Point 6 | L18: Point 7 | M18: Point 8 | N18: Point 9 | O18: Point 10 | P18: Point 11 | Q18: Point 12 | R18: Point 13 | S18: Point 14 | T18: Point 15
B19: A3 | C19: S1 | D19: =$D$7 -> Débitmètre en charge | F19: =IF(AND(OR(INDIRECT("Descriptif!I"&E$13)=Recap_equipements!$B19,INDIRECT("Descriptif!I"&E$13)=Recap_equipements!$C19),INDIRECT("Descriptif!M"&E$13)=$D19),INDIRECT("Descriptif!F"&E$13),"") | G19: =IF(AND(OR(INDIRECT("Descriptif!I"&F$13)=Recap_equipements!$B19,INDIRECT("Descriptif!I"&F$13)=Recap_equipements!$C19),INDIRECT("Descriptif!M"&F$13)=$D19),INDIRECT("Descriptif!F"&F$13),"") -> A3_P102_Q_DEM | H19: =IF(AND(OR(INDIRECT("Descriptif!I"&G$13)=Recap_equipements!$B19,INDIRECT("Descriptif!I"&G$13)=Recap_equipements!$C19),INDIRECT("Descriptif!M"&G$13)=$D19),INDIRECT("Descriptif!F"&G$13),"") | I19: =IF(AND(OR(INDIRECT("Descriptif!I"&H$13)=Recap_equipements!$B19,INDIRECT("Descriptif!I"&H$13)=Recap_equipements!$C19),INDIRECT("Descriptif!M"&H$13)=$D19),INDIRECT("Descriptif!F"&H$13),"") | J19: =IF(AND(OR(INDIRECT("Descriptif!I"&I$13)=Recap_equipements!$B19,INDIRECT("Descriptif!I"&I$13)=Recap_equipements!$C19),INDIRECT("Descriptif!M"&I$13)=$D19),INDIRECT("Descriptif!F"&I$13),"") | K19: =IF(AND(OR(INDIRECT("Descriptif!I"&J$13)=Recap_equipements!$B19,INDIRECT("Descriptif!I"&J$13)=Recap_equipements!$C19),INDIRECT("Descriptif!M"&J$13)=$D19),INDIRECT("Descriptif!F"&J$13),"") | L19: =IF(AND(OR(INDIRECT("Descriptif!I"&K$13)=Recap_equipements!$B19,INDIRECT("Descriptif!I"&K$13)=Recap_equipements!$C19),INDIRECT("Descriptif!M"&K$13)=$D19),INDIRECT("Descriptif!F"&K$13),"") | M19: =IF(AND(OR(INDIRECT("Descriptif!I"&L$13)=Recap_equipements!$B19,INDIRECT("Descriptif!I"&L$13)=Recap_equipements!$C19),INDIRECT("Descriptif!M"&L$13)=$D19),INDIRECT("Descriptif!F"&L$13),"") | ... T19: =IF(AND(OR(INDIRECT("Descriptif!I"&S$13)=Recap_equipements!$B19,INDIRECT("Descriptif!I"&S$13)=Recap_equipements!$C19),INDIRECT("Descriptif!M"&S$13)=$D19),INDIRECT("Descriptif!F"&S$13),"")
D20: =$D$8 -> Débitmètre gravitaire | F20: =IF(AND(OR(INDIRECT("Descriptif!I"&E$13)=Recap_equipements!$B19,INDIRECT("Descriptif!I"&E$13)=Recap_equipements!$C19),INDIRECT("Descriptif!M"&E$13)=$D20),INDIRECT("Descriptif!F"&E$13),"") | G20: =IF(AND(OR(INDIRECT("Descriptif!I"&F$13)=Recap_equipements!$B19,INDIRECT("Descriptif!I"&F$13)=Recap_equipements!$C19),INDIRECT("Descriptif!M"&F$13)=$D20),INDIRECT("Descriptif!F"&F$13),"") | H20: =IF(AND(OR(INDIRECT("Descriptif!I"&G$13)=Recap_equipements!$B19,INDIRECT("Descriptif!I"&G$13)=Recap_equipements!$C19),INDIRECT("Descriptif!M"&G$13)=$D20),INDIRECT("Descriptif!F"&G$13),"") | I20: =IF(AND(OR(INDIRECT("Descriptif!I"&H$13)=Recap_equipements!$B19,INDIRECT("Descriptif!I"&H$13)=Recap_equipements!$C19),INDIRECT("Descriptif!M"&H$13)=$D20),INDIRECT("Descriptif!F"&H$13),"") | J20: =IF(AND(OR(INDIRECT("Descriptif!I"&I$13)=Recap_equipements!$B19,INDIRECT("Descriptif!I"&I$13)=Recap_equipements!$C19),INDIRECT("Descriptif!M"&I$13)=$D20),INDIRECT("Descriptif!F"&I$13),"") | K20: =IF(AND(OR(INDIRECT("Descriptif!I"&J$13)=Recap_equipements!$B19,INDIRECT("Descriptif!I"&J$13)=Recap_equipements!$C19),INDIRECT("Descriptif!M"&J$13)=$D20),INDIRECT("Descriptif!F"&J$13),"") | L20: =IF(AND(OR(INDIRECT("Descriptif!I"&K$13)=Recap_equipements!$B19,INDIRECT("Descriptif!I"&K$13)=Recap_equipements!$C19),INDIRECT("Descriptif!M"&K$13)=$D20),INDIRECT("Descriptif!F"&K$13),"") | M20: =IF(AND(OR(INDIRECT("Descriptif!I"&L$13)=Recap_equipements!$B19,INDIRECT("Descriptif!I"&L$13)=Recap_equipements!$C19),INDIRECT("Descriptif!M"&L$13)=$D20),INDIRECT("Descriptif!F"&L$13),"") | ... T20: =IF(AND(OR(INDIRECT("Descriptif!I"&S$13)=Recap_equipements!$B19,INDIRECT("Descriptif!I"&S$13)=Recap_equipements!$C19),INDIRECT("Descriptif!M"&S$13)=$D20),INDIRECT("Descriptif!F"&S$13),"")
D21: =$D$9 -> Préleveur | F21: =IF(AND(OR(INDIRECT("Descriptif!I"&E$13)=Recap_equipements!$B19,INDIRECT("Descriptif!I"&E$13)=Recap_equipements!$C19),INDIRECT("Descriptif!M"&E$13)=$D21),INDIRECT("Descriptif!F"&E$13),"") | G21: =IF(AND(OR(INDIRECT("Descriptif!I"&F$13)=Recap_equipements!$B19,INDIRECT("Descriptif!I"&F$13)=Recap_equipements!$C19),INDIRECT("Descriptif!M"&F$13)=$D21),INDIRECT("Descriptif!F"&F$13),"") | H21: =IF(AND(OR(INDIRECT("Descriptif!I"&G$13)=Recap_equipements!$B19,INDIRECT("Descriptif!I"&G$13)=Recap_equipements!$C19),INDIRECT("Descriptif!M"&G$13)=$D21),INDIRECT("Descriptif!F"&G$13),"") -> A3_P102_PREL | I21: =IF(AND(OR(INDIRECT("Descriptif!I"&H$13)=Recap_equipements!$B19,INDIRECT("Descriptif!I"&H$13)=Recap_equipements!$C19),INDIRECT("Descriptif!M"&H$13)=$D21),INDIRECT("Descriptif!F"&H$13),"") | J21: =IF(AND(OR(INDIRECT("Descriptif!I"&I$13)=Recap_equipements!$B19,INDIRECT("Descriptif!I"&I$13)=Recap_equipements!$C19),INDIRECT("Descriptif!M"&I$13)=$D21),INDIRECT("Descriptif!F"&I$13),"") | K21: =IF(AND(OR(INDIRECT("Descriptif!I"&J$13)=Recap_equipements!$B19,INDIRECT("Descriptif!I"&J$13)=Recap_equipements!$C19),INDIRECT("Descriptif!M"&J$13)=$D21),INDIRECT("Descriptif!F"&J$13),"") | L21: =IF(AND(OR(INDIRECT("Descriptif!I"&K$13)=Recap_equipements!$B19,INDIRECT("Descriptif!I"&K$13)=Recap_equipements!$C19),INDIRECT("Descriptif!M"&K$13)=$D21),INDIRECT("Descriptif!F"&K$13),"") | M21: =IF(AND(OR(INDIRECT("Descriptif!I"&L$13)=Recap_equipements!$B19,INDIRECT("Descriptif!I"&L$13)=Recap_equipements!$C19),INDIRECT("Descriptif!M"&L$13)=$D21),INDIRECT("Descriptif!F"&L$13),"") | ... T21: =IF(AND(OR(INDIRECT("Descriptif!I"&S$13)=Recap_equipements!$B19,INDIRECT("Descriptif!I"&S$13)=Recap_equipements!$C19),INDIRECT("Descriptif!M"&S$13)=$D21),INDIRECT("Descriptif!F"&S$13),"")
D22: Analytique | F22: =IF(F21<>"",VLOOKUP(F21,Analytique!$X$3:$AD$33,1,FALSE),"") | G22: =IF(G21<>"",VLOOKUP(G21,Analytique!$X$3:$AD$33,1,FALSE),"") | H22: =IF(H21<>"",VLOOKUP(H21,Analytique!$X$3:$AD$33,1,FALSE),"") -> A3_P102_PREL | I22: =IF(I21<>"",VLOOKUP(I21,Analytique!$X$3:$AD$33,1,FALSE),"") | J22: =IF(J21<>"",VLOOKUP(J21,Analytique!$X$3:$AD$33,1,FALSE),"") | K22: =IF(K21<>"",VLOOKUP(K21,Analytique!$X$3:$AD$33,1,FALSE),"") | L22: =IF(L21<>"",VLOOKUP(L21,Analytique!$X$3:$AD$33,1,FALSE),"") | M22: =IF(M21<>"",VLOOKUP(M21,Analytique!$X$3:$AD$33,1,FALSE),"") | ... T22: =IF(T21<>"",VLOOKUP(T21,Analytique!$X$3:$AD$33,1,FALSE),"")
D23: =$D$10 -> Sonde de température | F23: =IF(AND(OR(INDIRECT("Descriptif!I"&E$13)=Recap_equipements!$B19,INDIRECT("Descriptif!I"&E$13)=Recap_equipements!$C19),INDIRECT("Descriptif!M"&E$13)=$D23),INDIRECT("Descriptif!F"&E$13),"") | G23: =IF(AND(OR(INDIRECT("Descriptif!I"&F$13)=Recap_equipements!$B19,INDIRECT("Descriptif!I"&F$13)=Recap_equipements!$C19),INDIRECT("Descriptif!M"&F$13)=$D23),INDIRECT("Descriptif!F"&F$13),"") | H23: =IF(AND(OR(INDIRECT("Descriptif!I"&G$13)=Recap_equipements!$B19,INDIRECT("Descriptif!I"&G$13)=Recap_equipements!$C19),INDIRECT("Descriptif!M"&G$13)=$D23),INDIRECT("Descriptif!F"&G$13),"") | I23: =IF(AND(OR(INDIRECT("Descriptif!I"&H$13)=Recap_equipements!$B19,INDIRECT("Descriptif!I"&H$13)=Recap_equipements!$C19),INDIRECT("Descriptif!M"&H$13)=$D23),INDIRECT("Descriptif!F"&H$13),"") | J23: =IF(AND(OR(INDIRECT("Descriptif!I"&I$13)=Recap_equipements!$B19,INDIRECT("Descriptif!I"&I$13)=Recap_equipements!$C19),INDIRECT("Descriptif!M"&I$13)=$D23),INDIRECT("Descriptif!F"&I$13),"") | K23: =IF(AND(OR(INDIRECT("Descriptif!I"&J$13)=Recap_equipements!$B19,INDIRECT("Descriptif!I"&J$13)=Recap_equipements!$C19),INDIRECT("Descriptif!M"&J$13)=$D23),INDIRECT("Descriptif!F"&J$13),"") | L23: =IF(AND(OR(INDIRECT("Descriptif!I"&K$13)=Recap_equipements!$B19,INDIRECT("Descriptif!I"&K$13)=Recap_equipements!$C19),INDIRECT("Descriptif!M"&K$13)=$D23),INDIRECT("Descriptif!F"&K$13),"") | M23: =IF(AND(OR(INDIRECT("Descriptif!I"&L$13)=Recap_equipements!$B19,INDIRECT("Descriptif!I"&L$13)=Recap_equipements!$C19),INDIRECT("Descriptif!M"&L$13)=$D23),INDIRECT("Descriptif!F"&L$13),"") | ... T23: =IF(AND(OR(INDIRECT("Descriptif!I"&S$13)=Recap_equipements!$B19,INDIRECT("Descriptif!I"&S$13)=Recap_equipements!$C19),INDIRECT("Descriptif!M"&S$13)=$D23),INDIRECT("Descriptif!F"&S$13),"")
B24: A4 | C24: S2 | D24: =$D$7 -> Débitmètre en charge | F24: =IF(AND(OR(INDIRECT("Descriptif!I"&E$13)=Recap_equipements!$B24,INDIRECT("Descriptif!I"&E$13)=Recap_equipements!$C24),INDIRECT("Descriptif!M"&E$13)=$D24),INDIRECT("Descriptif!F"&E$13),"") | G24: =IF(AND(OR(INDIRECT("Descriptif!I"&F$13)=Recap_equipements!$B24,INDIRECT("Descriptif!I"&F$13)=Recap_equipements!$C24),INDIRECT("Descriptif!M"&F$13)=$D24),INDIRECT("Descriptif!F"&F$13),"") | H24: =IF(AND(OR(INDIRECT("Descriptif!I"&G$13)=Recap_equipements!$B24,INDIRECT("Descriptif!I"&G$13)=Recap_equipements!$C24),INDIRECT("Descriptif!M"&G$13)=$D24),INDIRECT("Descriptif!F"&G$13),"") | I24: =IF(AND(OR(INDIRECT("Descriptif!I"&H$13)=Recap_equipements!$B24,INDIRECT("Descriptif!I"&H$13)=Recap_equipements!$C24),INDIRECT("Descriptif!M"&H$13)=$D24),INDIRECT("Descriptif!F"&H$13),"") | J24: =IF(AND(OR(INDIRECT("Descriptif!I"&I$13)=Recap_equipements!$B24,INDIRECT("Descriptif!I"&I$13)=Recap_equipements!$C24),INDIRECT("Descriptif!M"&I$13)=$D24),INDIRECT("Descriptif!F"&I$13),"") | K24: =IF(AND(OR(INDIRECT("Descriptif!I"&J$13)=Recap_equipements!$B24,INDIRECT("Descriptif!I"&J$13)=Recap_equipements!$C24),INDIRECT("Descriptif!M"&J$13)=$D24),INDIRECT("Descriptif!F"&J$13),"") | L24: =IF(AND(OR(INDIRECT("Descriptif!I"&K$13)=Recap_equipements!$B24,INDIRECT("Descriptif!I"&K$13)=Recap_equipements!$C24),INDIRECT("Descriptif!M"&K$13)=$D24),INDIRECT("Descriptif!F"&K$13),"") | M24: =IF(AND(OR(INDIRECT("Descriptif!I"&L$13)=Recap_equipements!$B24,INDIRECT("Descriptif!I"&L$13)=Recap_equipements!$C24),INDIRECT("Descriptif!M"&L$13)=$D24),INDIRECT("Descriptif!F"&L$13),"") | ... T24: =IF(AND(OR(INDIRECT("Descriptif!I"&S$13)=Recap_equipements!$B24,INDIRECT("Descriptif!I"&S$13)=Recap_equipements!$C24),INDIRECT("Descriptif!M"&S$13)=$D24),INDIRECT("Descriptif!F"&S$13),"")
