Workbook
Name Asservissement: PARAM!$A$44:$A$46
Name CODE_SANDRE_3: PARAM!$I$4:$J$33
Name CODE_SANDRE_SCL: PARAM!$F$4:$F$7
Name CODE_SANDRE_STEU: PARAM!$E$4:$E$19
Name conditions_meteo: PARAM!$F$44:$F$46
Name Conformité: PARAM!$B$44:$B$48
Name diam_debitmetre: 'BD Débitmètres'!$B$11:$B$38
Name Eq_h_controle: PARAM!$C$30:$C$32
Name EQUIPEMENT_PREL: PARAM!$B$4:$B$6
Name EQUIPEMENT_Q: PARAM!$A$4:$A$15
Name Frequence: PARAM!$E$44:$E$51
Name LISTE_1: PARAM!$A$21:$A$23
Name LISTE_2: PARAM!$B$21:$B$24
Name LISTE_3: PARAM!$C$21:$C$25
Name LISTE_4: PARAM!$D$21:$D$25
Name LISTE_5: PARAM!$F$21:$F$25
Name LISTE_6: PARAM!$G$21
Name LISTE_7: PARAM!$H$21:$H$23
Name listeDebimetres: INDIRECT("Descriptif!"&ADDRESS(Descriptif!$AD$2,COLUMN(Descriptif!$AF$1))):INDEX(INDIRECT("Descriptif!AF"&Descriptif!$AD$2&":AF101"),COUNTIF(INDIRECT("Descriptif!AF"&Descriptif!$AD$2&":AF101"),"?*"))
Name listePluviometres: INDIRECT("Descriptif!"&ADDRESS(Descriptif!$AD$2,COLUMN(Descriptif!$AJ$1))):INDEX(INDIRECT("Descriptif!AJ"&Descriptif!$AD$2&":AJ101"),COUNTIF(INDIRECT("Descriptif!AJ"&Descriptif!$AD$2&":AJ101"),"?*"))
Name listePreleveurs: INDIRECT("Descriptif!"&ADDRESS(Descriptif!$AD$2,COLUMN(Descriptif!$AD$1))):INDEX(INDIRECT("Descriptif!AD"&Descriptif!$AD$2&":AD101"),COUNTIF(INDIRECT("Descriptif!AD"&Descriptif!$AD$2&":AD101"),"?*"))
Name listeSondeTemp: INDIRECT("Descriptif!"&ADDRESS(Descriptif!$AD$2,COLUMN(Descriptif!$AH$1))):INDEX(INDIRECT("Descriptif!AH"&Descriptif!$AD$2&":AH101"),COUNTIF(INDIRECT("Descriptif!AH"&Descriptif!$AD$2&":AH101"),"?*"))
Name Méthode: PARAM!$A$55:$A$57
Name Montage_sonde: PARAM!$G$44:$G$47
Name PLUVIO_SCL: Descriptif!$E$24:$E$24
Name Print_Area: LimitequantificationSDE!$A$1:$F$21
Name Print_Area: 'SeuilsComparaison-EMT'!$A$1:$K$29
Name Q_en_charge: PARAM!$A$30:$A$34
Name Q_en_charge_boues: PARAM!$E$30
Name Q_Gravitaire: PARAM!$B$30:$B$38
Name Satisfaction: PARAM!$D$44:$D$46
Name STATUT_EQ: PARAM!$G$4:$G$6
Name Type_capteur: PARAM!$C$44:$C$48
Name Type_equipement: PARAM!$C$4:$C$7
Name Type_reseau: PARAM!$D$30:$D$32
Name TypeDeMesure: PARAM!$B$55:$B$56

Sheet Lisez moi
C2: CONTRÔLE DES DISPOSITIFS D'AUTOSURVEILLANCE DES SYSTÈMES D'ASSAINISSEMENT COLLECTIF | AC2: début données sys collect | AD2: =ROW(E20)+1 -> 21 | AE2: fin données sys collect | AF2: =ROW(D22)-1 -> 21 | AG2: pluvio SCL | AH2: =ROW(#REF!)+1 -> #REF! | AI2: =ROW(#REF!)-1 -> #REF!
C4: Version grille CDA | D4: 1.17.5
C5: Version module | D5: 1.beta
C8: Présentation
C10: Le Contrôle Annuel des dispositifs d’Autosurveillance (CDA) constitue une étape réglementaire majeure dans la gestion des systèmes d'assainissement collectif. Ce diagnostic technique a pour fonction de vérifier la fiabilité et la conformité des données d'autosurveillance produites par les exploitants de Stations de Traitement des Eaux Usées (STEU) et deSystème de Collecte (SCL).
C11: L’autosurveillance repose sur la mesure en continue des débits et la réalisation de prélèvements d'échantillons représentatifs des rejets. Le CDA intervient comme un audit externe visant à : • Valider la métrologie : Vérifier l’étalonnage et la précision des débitmètres et des préleveurs automatiques. • Certifier les données : Garantir que les volumes et les charges polluantes déclarés aux agences de l’eau et aux services de l’État sont exacts. • Assurer la conformité : Vérifier le respect des prescriptions techniques de l’arrêté d'autorisation de l’ouvrage.
C13: Instructions pour la réalisation du CDA
C15: Le contrôle doit être réalisé par un organisme tiers indépendant et compétant (bureaux d’études spécialisés ou services d’assistance technique départementaux : SATESE). Il donne lieu à un rapport technique détaillé (dont une trame est exportable depuis cette feuille Excel) qui consigne les écarts de mesure, l'état de l'instrumentation et la qualité de la chaîne d'acquisition des données des stations de traitement et de leur système de collecte.
C16: Afin de structurer cette collecte et de sécuriser la transmission des informations, le formulaire Excel permet une saisie directe et standardisée des données de contrôle. Cet outil vise à harmoniser les rapports, à réduire les risques d’erreurs de retranscription et à faciliter le suivi des dispositifs d’autosurveillance.
C17: Le formulaire pourra être à terme être pré-généré et déposé sur la plateforme « Port'Aus » mise à disposition par les Agences de l’Eau.
C18: La réalisation du CDA et les modalités de remplissage de la grille conrrespondante doivent respecter les consignes suivantes : • Une grille CDA ne peut au maximum contenir que les inforations pour un système de collecte et une station. Pour les agglomerations disposant de plusieurs système de traitement, il est impératif de générer une grille par système de traitement. • Il est recommandé de faire un CDA distinct pour la partie système de collecte et pour la partie système de traitement. • Dans le cas ou le contrôle s'effectue sur plusieurs jours, une seule grille peut être renseigné les jours sont consécutifs et si les conditions météorologiques sont stables pendant le contrôle. A défaut il faudra fournir plusieurs plusieurs grilles CDA.
C20: Documentation de la grille
C22: Les fichiers sources dans leur dernières version sont disponibles à cette adresse : https://github.com/ndhuygelaere/autosurveillance_steu_excel
C23: L'archive est constituée: • de la grille CDA (fichier GRILLES_CDA_Vxxx.xlsx) • d'un module complémentaire à Excel (fichier autosurveillanceSTEU.xlam) • de fichiers de modèle dans le répertoire "AutosurveillanceTemplates" • de la documentation d'installation Pour chaque mise à jour de la grille, il vous faudra suivre les instructions du manuel d'installation afin de vous assurez d'utiliser la nouvelle version de la grille et du module.
C24: Crédits
... C27: sous la direction du GT Autosurveillance des Agences de l'Eau

Sheet Descriptif
AC1: Ne rien mettre dans cette colonne | AD1: Ne rien mettre dans cette colonne | AE1: Ne rien mettre dans cette colonne | AF1: Ne rien mettre dans cette colonne | AG1: Ne rien mettre dans cette colonne | AH1: Ne rien mettre dans cette colonne | AI1: Ne rien mettre dans cette colonne | AJ1: Ne rien mettre dans cette colonne
C2: CONTRÔLE DES DISPOSITIFS D'AUTOSURVEILLANCE DES SYSTÈMES D'ASSAINISSEMENT COLLECTIF | AC2: début données sys collect | AD2: =ROW(E13)+1 -> 14 | AE2: fin données sys collect | AF2: =ROW(D15)-1 -> 14 | AG2: pluvio SCL | AH2: =ROW(E22)+1 -> 23 | AI2: =ROW(D24)-1 -> 23
C3: NOM DU SYSTÈME D'ASSAINISSEMENT : | I3: NOM DU SYSTÈME DE TRAITEMENT : | N3: NOM DU SYSTÈME DE COLLECTE : | S3: NOM DE L'ORGANISME DE CONTRÔLE : | AC3: début données station | AD3: =ROW(E33)+1 -> 34 | AE3: fin données station | AF3: =ROW(D35)-1 -> 34 | AG3: pluvio STEU | AH3: =ROW(E42)+1 -> 43 | AI3: =ROW(D44)-1 -> 43
C4: CODE SANDRE DE L'AGGLOMÉRATION : | I4: CODE SANDRE DE LA STATION : | N4: CODE SANDRE DU RÉSEAU : | S4: NOM(S) DU(ES) CONTROLEUR(S) :
C5: MAITRE D'OUVRAGE DE LA STATION : | I5: TYPE DE TRAITEMENT : | N5: TYPE DE RÉSEAU : | S5: DATE(S) D'INTERVENTION :
C6: EXPLOITANT DE LA STATION : | I6: CAPACITÉ DE LA STATION : | N6: EXPLOITANT DU RÉSEAU : | S6: CONDITION(S) MÉTÉO :
C8: SYSTÈME DE COLLECTE
D9: Remarques : | E9: Les estimations et les apports par camion ne rentrent pas dans le CDA
D10: Liste des équipements du système de collecte pour chaque point d’autosurveillance
H12: Les informations de codification sont à reprendre du MAS
E13: Statut | F13: Lien vers l'onglet de l'équipement | H13: Point réglementaire | I13: Localisation (cf. MAS) | J13: Code du point (cf MAS) | K13: Libellé de l'équipement | M13: Type d'équipement | O13: Type de matériel | Q13: Pluviomètre de référence | S13: Certaines informations d'un équipement ne sont pas modifiables. Au besoin il est préférable de supprimer et de recréer l'équipement. | AC13: Liste préleveurs | AE13: Liste débimètres | AG13: Liste thermo | AI13: Liste pluvio
AB14: =ROW(A14)- $AD$2 +1 -> 1 | AC14: =IF(AND(OR($E14="Contrôlé",$E14="Non contrôlé"),$M14="Préleveur"),$F14,"") | AD14: {=IFERROR(INDEX($AC$14:$AC$102,SMALL(IF($AC$14:$AC$102<>"",ROW($AC$14:$AC$102)-ROW(INDIRECT("$AC$14"))+1),ROW(INDIRECT("A" & AB14 ) ))),"")} | AE14: =IF(AND(OR($E14="Contrôlé",$E14="Non contrôlé"),LEFT($M14,10) ="Débitmètre"),$F14,"") | AF14: {=IFERROR(INDEX($AE$14:$AE$102,SMALL(IF($AE$14:$AE$102<>"",ROW($AE$14:$AE$102)-ROW(INDIRECT("$AE$14"))+1),ROW(INDIRECT("A" & AB14 ) ))),"")} | AG14: =IF(AND(OR($E14="Contrôlé",$E14="Non contrôlé"),LEFT($M14,5) ="Sonde"),$F14,"") | AH14: {=IFERROR(INDEX($AG$14:$AG$102,SMALL(IF($AG$14:$AG$102<>"",ROW($AG$14:$AG$102)-ROW(INDIRECT("$AG$14"))+1),ROW(INDIRECT("A" & AB14 ) ))),"")} | AI14: =IF(AND(OR($E14="Contrôlé",$E14="Non contrôlé"), $F14 <> "", $M14 = ""),$F14,"") | AJ14: {=IFERROR(INDEX($AI$14:$AI$102,SMALL(IF($AI$14:$AI$102<>"",ROW($AI$14:$AI$102)-ROW(INDIRECT("$AI$14"))+1),ROW(INDIRECT("A" & AB14 ) ))),"")}
E15: Ajouter un équipement réseau | K15: Si certains points ne sont pas équipés, veuillez les indiquer en commentaire : | AB15: =ROW(A15)- $AD$2 +1 -> 2 | AC15: =IF(AND(OR($E15="Contrôlé",$E15="Non contrôlé"),$M15="Préleveur"),$F15,"") | AD15: {=IFERROR(INDEX($AC$14:$AC$102,SMALL(IF($AC$14:$AC$102<>"",ROW($AC$14:$AC$102)-ROW(INDIRECT("$AC$14"))+1),ROW(INDIRECT("A" & AB15 ) ))),"")} | AE15: =IF(AND(OR($E15="Contrôlé",$E15="Non contrôlé"),LEFT($M15,10) ="Débitmètre"),$F15,"") | AF15: {=IFERROR(INDEX($AE$14:$AE$102,SMALL(IF($AE$14:$AE$102<>"",ROW($AE$14:$AE$102)-ROW(INDIRECT("$AE$14"))+1),ROW(INDIRECT("A" & AB15 ) ))),"")} | AG15: =IF(AND(OR($E15="Contrôlé",$E15="Non contrôlé"),LEFT($M15,5) ="Sonde"),$F15,"") | AH15: {=IFERROR(INDEX($AG$14:$AG$102,SMALL(IF($AG$14:$AG$102<>"",ROW($AG$14:$AG$102)-ROW(INDIRECT("$AG$14"))+1),ROW(INDIRECT("A" & AB15 ) ))),"")} | AI15: =IF(AND(OR($E15="Contrôlé",$E15="Non contrôlé"), $F15 <> "", $M15 = ""),$F15,"") | AJ15: {=IFERROR(INDEX($AI$14:$AI$102,SMALL(IF($AI$14:$AI$102<>"",ROW($AI$14:$AI$102)-ROW(INDIRECT("$AI$14"))+1),ROW(INDIRECT("A" & AB15 ) ))),"")}
AB16: =ROW(A16)- $AD$2 +1 -> 3 | AC16: =IF(AND(OR($E16="Contrôlé",$E16="Non contrôlé"),$M16="Préleveur"),$F16,"") | AD16: {=IFERROR(INDEX($AC$14:$AC$102,SMALL(IF($AC$14:$AC$102<>"",ROW($AC$14:$AC$102)-ROW(INDIRECT("$AC$14"))+1),ROW(INDIRECT("A" & AB16 ) ))),"")} | AE16: =IF(AND(OR($E16="Contrôlé",$E16="Non contrôlé"),LEFT($M16,10) ="Débitmètre"),$F16,"") | AF16: {=IFERROR(INDEX($AE$14:$AE$102,SMALL(IF($AE$14:$AE$102<>"",ROW($AE$14:$AE$102)-ROW(INDIRECT("$AE$14"))+1),ROW(INDIRECT("A" & AB16 ) ))),"")} | AG16: =IF(AND(OR($E16="Contrôlé",$E16="Non contrôlé"),LEFT($M16,5) ="Sonde"),$F16,"") | AH16: {=IFERROR(INDEX($AG$14:$AG$102,SMALL(IF($AG$14:$AG$102<>"",ROW($AG$14:$AG$102)-ROW(INDIRECT("$AG$14"))+1),ROW(INDIRECT("A" & AB16 ) ))),"")} | AI16: =IF(AND(OR($E16="Contrôlé",$E16="Non contrôlé"), $F16 <> "", $M16 = ""),$F16,"") | AJ16: {=IFERROR(INDEX($AI$14:$AI$102,SMALL(IF($AI$14:$AI$102<>"",ROW($AI$14:$AI$102)-ROW(INDIRECT("$AI$14"))+1),ROW(INDIRECT("A" & AB16 ) ))),"")}
AB17: =ROW(A17)- $AD$2 +1 -> 4 | AC17: =IF(AND(OR($E17="Contrôlé",$E17="Non contrôlé"),$M17="Préleveur"),$F17,"") | AD17: {=IFERROR(INDEX($AC$14:$AC$102,SMALL(IF($AC$14:$AC$102<>"",ROW($AC$14:$AC$102)-ROW(INDIRECT("$AC$14"))+1),ROW(INDIRECT("A" & AB17 ) ))),"")} | AE17: =IF(AND(OR($E17="Contrôlé",$E17="Non contrôlé"),LEFT($M17,10) ="Débitmètre"),$F17,"") | AF17: {=IFERROR(INDEX($AE$14:$AE$102,SMALL(IF($AE$14:$AE$102<>"",ROW($AE$14:$AE$102)-ROW(INDIRECT("$AE$14"))+1),ROW(INDIRECT("A" & AB17 ) ))),"")} | AG17: =IF(AND(OR($E17="Contrôlé",$E17="Non contrôlé"),LEFT($M17,5) ="Sonde"),$F17,"") | AH17: {=IFERROR(INDEX($AG$14:$AG$102,SMALL(IF($AG$14:$AG$102<>"",ROW($AG$14:$AG$102)-ROW(INDIRECT("$AG$14"))+1),ROW(INDIRECT("A" & AB17 ) ))),"")} | AI17: =IF(AND(OR($E17="Contrôlé",$E17="Non contrôlé"), $F17 <> "", $M17 = ""),$F17,"") | AJ17: {=IFERROR(INDEX($AI$14:$AI$102,SMALL(IF($AI$14:$AI$102<>"",ROW($AI$14:$AI$102)-ROW(INDIRECT("$AI$14"))+1),ROW(INDIRECT("A" & AB17 ) ))),"")}
AB18: =ROW(A18)- $AD$2 +1 -> 5 | AC18: =IF(AND(OR($E18="Contrôlé",$E18="Non contrôlé"),$M18="Préleveur"),$F18,"") | AD18: {=IFERROR(INDEX($AC$14:$AC$102,SMALL(IF($AC$14:$AC$102<>"",ROW($AC$14:$AC$102)-ROW(INDIRECT("$AC$14"))+1),ROW(INDIRECT("A" & AB18 ) ))),"")} | AE18: =IF(AND(OR($E18="Contrôlé",$E18="Non contrôlé"),LEFT($M18,10) ="Débitmètre"),$F18,"") | AF18: {=IFERROR(INDEX($AE$14:$AE$102,SMALL(IF($AE$14:$AE$102<>"",ROW($AE$14:$AE$102)-ROW(INDIRECT("$AE$14"))+1),ROW(INDIRECT("A" & AB18 ) ))),"")} | AG18: =IF(AND(OR($E18="Contrôlé",$E18="Non contrôlé"),LEFT($M18,5) ="Sonde"),$F18,"") | AH18: {=IFERROR(INDEX($AG$14:$AG$102,SMALL(IF($AG$14:$AG$102<>"",ROW($AG$14:$AG$102)-ROW(INDIRECT("$AG$14"))+1),ROW(INDIRECT("A" & AB18 ) ))),"")} | AI18: =IF(AND(OR($E18="Contrôlé",$E18="Non contrôlé"), $F18 <> "", $M18 = ""),$F18,"") | AJ18: {=IFERROR(INDEX($AI$14:$AI$102,SMALL(IF($AI$14:$AI$102<>"",ROW($AI$14:$AI$102)-ROW(INDIRECT("$AI$14"))+1),ROW(INDIRECT("A" & AB18 ) ))),"")}
AB19: =ROW(A19)- $AD$2 +1 -> 6 | AC19: =IF(AND(OR($E19="Contrôlé",$E19="Non contrôlé"),$M19="Préleveur"),$F19,"") | AD19: {=IFERROR(INDEX($AC$14:$AC$102,SMALL(IF($AC$14:$AC$102<>"",ROW($AC$14:$AC$102)-ROW(INDIRECT("$AC$14"))+1),ROW(INDIRECT("A" & AB19 ) ))),"")} | AE19: =IF(AND(OR($E19="Contrôlé",$E19="Non contrôlé"),LEFT($M19,10) ="Débitmètre"),$F19,"") | AF19: {=IFERROR(INDEX($AE$14:$AE$102,SMALL(IF($AE$14:$AE$102<>"",ROW($AE$14:$AE$102)-ROW(INDIRECT("$AE$14"))+1),ROW(INDIRECT("A" & AB19 ) ))),"")} | AG19: =IF(AND(OR($E19="Contrôlé",$E19="Non contrôlé"),LEFT($M19,5) ="Sonde"),$F19,"") | AH19: {=IFERROR(INDEX($AG$14:$AG$102,SMALL(IF($AG$14:$AG$102<>"",ROW($AG$14:$AG$102)-ROW(INDIRECT("$AG$14"))+1),ROW(INDIRECT("A" & AB19 ) ))),"")} | AI19: =IF(AND(OR($E19="Contrôlé",$E19="Non contrôlé"), $F19 <> "", $M19 = ""),$F19,"") | AJ19: {=IFERROR(INDEX($AI$14:$AI$102,SMALL(IF($AI$14:$AI$102<>"",ROW($AI$14:$AI$102)-ROW(INDIRECT("$AI$14"))+1),ROW(INDIRECT("A" & AB19 ) ))),"")}
D20: Liste des pluviomètres de référence du réseau | AB20: =ROW(A20)- $AD$2 +1 -> 7 | AC20: =IF(AND(OR($E20="Contrôlé",$E20="Non contrôlé"),$M20="Préleveur"),$F20,"") | AD20: {=IFERROR(INDEX($AC$14:$AC$102,SMALL(IF($AC$14:$AC$102<>"",ROW($AC$14:$AC$102)-ROW(INDIRECT("$AC$14"))+1),ROW(INDIRECT("A" & AB20 ) ))),"")} | AE20: =IF(AND(OR($E20="Contrôlé",$E20="Non contrôlé"),LEFT($M20,10) ="Débitmètre"),$F20,"") | AF20: {=IFERROR(INDEX($AE$14:$AE$102,SMALL(IF($AE$14:$AE$102<>"",ROW($AE$14:$AE$102)-ROW(INDIRECT("$AE$14"))+1),ROW(INDIRECT("A" & AB20 ) ))),"")} | AG20: =IF(AND(OR($E20="Contrôlé",$E20="Non contrôlé"),LEFT($M20,5) ="Sonde"),$F20,"") | AH20: {=IFERROR(INDEX($AG$14:$AG$102,SMALL(IF($AG$14:$AG$102<>"",ROW($AG$14:$AG$102)-ROW(INDIRECT("$AG$14"))+1),ROW(INDIRECT("A" & AB20 ) ))),"")} | AI20: =IF(AND(OR($E20="Contrôlé",$E20="Non contrôlé"), $F20 <> "", $M20 = ""),$F20,"") | AJ20: {=IFERROR(INDEX($AI$14:$AI$102,SMALL(IF($AI$14:$AI$102<>"",ROW($AI$14:$AI$102)-ROW(INDIRECT("$AI$14"))+1),ROW(INDIRECT("A" & AB20 ) ))),"")}
AB21: =ROW(A21)- $AD$2 +1 -> 8 | AC21: =IF(AND(OR($E21="Contrôlé",$E21="Non contrôlé"),$M21="Préleveur"),$F21,"") | AD21: {=IFERROR(INDEX($AC$14:$AC$102,SMALL(IF($AC$14:$AC$102<>"",ROW($AC$14:$AC$102)-ROW(INDIRECT("$AC$14"))+1),ROW(INDIRECT("A" & AB21 ) ))),"")} | AE21: =IF(AND(OR($E21="Contrôlé",$E21="Non contrôlé"),LEFT($M21,10) ="Débitmètre"),$F21,"") | AF21: {=IFERROR(INDEX($AE$14:$AE$102,SMALL(IF($AE$14:$AE$102<>"",ROW($AE$14:$AE$102)-ROW(INDIRECT("$AE$14"))+1),ROW(INDIRECT("A" & AB21 ) ))),"")} | AG21: =IF(AND(OR($E21="Contrôlé",$E21="Non contrôlé"),LEFT($M21,5) ="Sonde"),$F21,"") | AH21: {=IFERROR(INDEX($AG$14:$AG$102,SMALL(IF($AG$14:$AG$102<>"",ROW($AG$14:$AG$102)-ROW(INDIRECT("$AG$14"))+1),ROW(INDIRECT("A" & AB21 ) ))),"")} | AI21: =IF(AND(OR($E21="Contrôlé",$E21="Non contrôlé"), $F21 <> "", $M21 = ""),$F21,"") | AJ21: {=IFERROR(INDEX($AI$14:$AI$102,SMALL(IF($AI$14:$AI$102<>"",ROW($AI$14:$AI$102)-ROW(INDIRECT("$AI$14"))+1),ROW(INDIRECT("A" & AB21 ) ))),"")}
E22: Statut | F22: Lien vers l'onglet de l'équipement | AB22: =ROW(A22)- $AD$2 +1 -> 9 | AC22: =IF(AND(OR($E22="Contrôlé",$E22="Non contrôlé"),$M22="Préleveur"),$F22,"") | AD22: {=IFERROR(INDEX($AC$14:$AC$102,SMALL(IF($AC$14:$AC$102<>"",ROW($AC$14:$AC$102)-ROW(INDIRECT("$AC$14"))+1),ROW(INDIRECT("A" & AB22 ) ))),"")} | AE22: =IF(AND(OR($E22="Contrôlé",$E22="Non contrôlé"),LEFT($M22,10) ="Débitmètre"),$F22,"") | AF22: {=IFERROR(INDEX($AE$14:$AE$102,SMALL(IF($AE$14:$AE$102<>"",ROW($AE$14:$AE$102)-ROW(INDIRECT("$AE$14"))+1),ROW(INDIRECT("A" & AB22 ) ))),"")} | AG22: =IF(AND(OR($E22="Contrôlé",$E22="Non contrôlé"),LEFT($M22,5) ="Sonde"),$F22,"") | AH22: {=IFERROR(INDEX($AG$14:$AG$102,SMALL(IF($AG$14:$AG$102<>"",ROW($AG$14:$AG$102)-ROW(INDIRECT("$AG$14"))+1),ROW(INDIRECT("A" & AB22 ) ))),"")} | AI22: =IF(AND(OR($E22="Contrôlé",$E22="Non contrôlé"), $F22 <> "", $M22 = ""),$F22,"") | AJ22: {=IFERROR(INDEX($AI$14:$AI$102,SMALL(IF($AI$14:$AI$102<>"",ROW($AI$14:$AI$102)-ROW(INDIRECT("$AI$14"))+1),ROW(INDIRECT("A" & AB22 ) ))),"")}
AB23: =ROW(A23)- $AD$2 +1 -> 10 | AC23: =IF(AND(OR($E23="Contrôlé",$E23="Non contrôlé"),$M23="Préleveur"),$F23,"") | AD23: {=IFERROR(INDEX($AC$14:$AC$102,SMALL(IF($AC$14:$AC$102<>"",ROW($AC$14:$AC$102)-ROW(INDIRECT("$AC$14"))+1),ROW(INDIRECT("A" & AB23 ) ))),"")} | AE23: =IF(AND(OR($E23="Contrôlé",$E23="Non contrôlé"),LEFT($M23,10) ="Débitmètre"),$F23,"") | AF23: {=IFERROR(INDEX($AE$14:$AE$102,SMALL(IF($AE$14:$AE$102<>"",ROW($AE$14:$AE$102)-ROW(INDIRECT("$AE$14"))+1),ROW(INDIRECT("A" & AB23 ) ))),"")} | AG23: =IF(AND(OR($E23="Contrôlé",$E23="Non contrôlé"),LEFT($M23,5) ="Sonde"),$F23,"") | AH23: {=IFERROR(INDEX($AG$14:$AG$102,SMALL(IF($AG$14:$AG$102<>"",ROW($AG$14:$AG$102)-ROW(INDIRECT("$AG$14"))+1),ROW(INDIRECT("A" & AB23 ) ))),"")} | AI23: =IF(AND(OR($E23="Contrôlé",$E23="Non contrôlé"), $F23 <> "", $M23 = ""),$F23,"") | AJ23: {=IFERROR(INDEX($AI$14:$AI$102,SMALL(IF($AI$14:$AI$102<>"",ROW($AI$14:$AI$102)-ROW(INDIRECT("$AI$14"))+1),ROW(INDIRECT("A" & AB23 ) ))),"")}
E24: Ajouter un pluviomètre réseau | K24: Si pas de pluviomètre, veuillez ajouter en commentaire la provenance des données : | AB24: =ROW(A24)- $AD$2 +1 -> 11 | AC24: =IF(AND(OR($E24="Contrôlé",$E24="Non contrôlé"),$M24="Préleveur"),$F24,"") | AD24: {=IFERROR(INDEX($AC$14:$AC$102,SMALL(IF($AC$14:$AC$102<>"",ROW($AC$14:$AC$102)-ROW(INDIRECT("$AC$14"))+1),ROW(INDIRECT("A" & AB24 ) ))),"")} | AE24: =IF(AND(OR($E24="Contrôlé",$E24="Non contrôlé"),LEFT($M24,10) ="Débitmètre"),$F24,"") | AF24: {=IFERROR(INDEX($AE$14:$AE$102,SMALL(IF($AE$14:$AE$102<>"",ROW($AE$14:$AE$102)-ROW(INDIRECT("$AE$14"))+1),ROW(INDIRECT("A" & AB24 ) ))),"")} | AG24: =IF(AND(OR($E24="Contrôlé",$E24="Non contrôlé"),LEFT($M24,5) ="Sonde"),$F24,"") | AH24: {=IFERROR(INDEX($AG$14:$AG$102,SMALL(IF($AG$14:$AG$102<>"",ROW($AG$14:$AG$102)-ROW(INDIRECT("$AG$14"))+1),ROW(INDIRECT("A" & AB24 ) ))),"")} | AI24: =IF(AND(OR($E24="Contrôlé",$E24="Non contrôlé"), $F24 <> "", $M24 = ""),$F24,"") | AJ24: {=IFERROR(INDEX($AI$14:$AI$102,SMALL(IF($AI$14:$AI$102<>"",ROW($AI$14:$AI$102)-ROW(INDIRECT("$AI$14"))+1),ROW(INDIRECT("A" & AB24 ) ))),"")}
AB25: =ROW(A25)- $AD$2 +1 -> 12 | AC25: =IF(AND(OR($E25="Contrôlé",$E25="Non contrôlé"),$M25="Préleveur"),$F25,"") | AD25: {=IFERROR(INDEX($AC$14:$AC$102,SMALL(IF($AC$14:$AC$102<>"",ROW($AC$14:$AC$102)-ROW(INDIRECT("$AC$14"))+1),ROW(INDIRECT("A" & AB25 ) ))),"")} | AE25: =IF(AND(OR($E25="Contrôlé",$E25="Non contrôlé"),LEFT($M25,10) ="Débitmètre"),$F25,"") | AF25: {=IFERROR(INDEX($AE$14:$AE$102,SMALL(IF($AE$14:$AE$102<>"",ROW($AE$14:$AE$102)-ROW(INDIRECT("$AE$14"))+1),ROW(INDIRECT("A" & AB25 ) ))),"")} | AG25: =IF(AND(OR($E25="Contrôlé",$E25="Non contrôlé"),LEFT($M25,5) ="Sonde"),$F25,"") | AH25: {=IFERROR(INDEX($AG$14:$AG$102,SMALL(IF($AG$14:$AG$102<>"",ROW($AG$14:$AG$102)-ROW(INDIRECT("$AG$14"))+1),ROW(INDIRECT("A" & AB25 ) ))),"")} | AI25: =IF(AND(OR($E25="Contrôlé",$E25="Non contrôlé"), $F25 <> "", $M25 = ""),$F25,"") | AJ25: {=IFERROR(INDEX($AI$14:$AI$102,SMALL(IF($AI$14:$AI$102<>"",ROW($AI$14:$AI$102)-ROW(INDIRECT("$AI$14"))+1),ROW(INDIRECT("A" & AB25 ) ))),"")}
AB26: =ROW(A26)- $AD$2 +1 -> 13 | AC26: =IF(AND(OR($E26="Contrôlé",$E26="Non contrôlé"),$M26="Préleveur"),$F26,"") | AD26: {=IFERROR(INDEX($AC$14:$AC$102,SMALL(IF($AC$14:$AC$102<>"",ROW($AC$14:$AC$102)-ROW(INDIRECT("$AC$14"))+1),ROW(INDIRECT("A" & AB26 ) ))),"")} | AE26: =IF(AND(OR($E26="Contrôlé",$E26="Non contrôlé"),LEFT($M26,10) ="Débitmètre"),$F26,"") | AF26: {=IFERROR(INDEX($AE$14:$AE$102,SMALL(IF($AE$14:$AE$102<>"",ROW($AE$14:$AE$102)-ROW(INDIRECT("$AE$14"))+1),ROW(INDIRECT("A" & AB26 ) ))),"")} | AG26: =IF(AND(OR($E26="Contrôlé",$E26="Non contrôlé"),LEFT($M26,5) ="Sonde"),$F26,"") | AH26: {=IFERROR(INDEX($AG$14:$AG$102,SMALL(IF($AG$14:$AG$102<>"",ROW($AG$14:$AG$102)-ROW(INDIRECT("$AG$14"))+1),ROW(INDIRECT("A" & AB26 ) ))),"")} | AI26: =IF(AND(OR($E26="Contrôlé",$E26="Non contrôlé"), $F26 <> "", $M26 = ""),$F26,"") | AJ26: {=IFERROR(INDEX($AI$14:$AI$102,SMALL(IF($AI$14:$AI$102<>"",ROW($AI$14:$AI$102)-ROW(INDIRECT("$AI$14"))+1),ROW(INDIRECT("A" & AB26 ) ))),"")}
AB27: =ROW(A27)- $AD$2 +1 -> 14 | AC27: =IF(AND(OR($E27="Contrôlé",$E27="Non contrôlé"),$M27="Préleveur"),$F27,"") | AD27: {=IFERROR(INDEX($AC$14:$AC$102,SMALL(IF($AC$14:$AC$102<>"",ROW($AC$14:$AC$102)-ROW(INDIRECT("$AC$14"))+1),ROW(INDIRECT("A" & AB27 ) ))),"")} | AE27: =IF(AND(OR($E27="Contrôlé",$E27="Non contrôlé"),LEFT($M27,10) ="Débitmètre"),$F27,"") | AF27: {=IFERROR(INDEX($AE$14:$AE$102,SMALL(IF($AE$14:$AE$102<>"",ROW($AE$14:$AE$102)-ROW(INDIRECT("$AE$14"))+1),ROW(INDIRECT("A" & AB27 ) ))),"")} | AG27: =IF(AND(OR($E27="Contrôlé",$E27="Non contrôlé"),LEFT($M27,5) ="Sonde"),$F27,"") | AH27: {=IFERROR(INDEX($AG$14:$AG$102,SMALL(IF($AG$14:$AG$102<>"",ROW($AG$14:$AG$102)-ROW(INDIRECT("$AG$14"))+1),ROW(INDIRECT("A" & AB27 ) ))),"")} | AI27: =IF(AND(OR($E27="Contrôlé",$E27="Non contrôlé"), $F27 <> "", $M27 = ""),$F27,"") | AJ27: {=IFERROR(INDEX($AI$14:$AI$102,SMALL(IF($AI$14:$AI$102<>"",ROW($AI$14:$AI$102)-ROW(INDIRECT("$AI$14"))+1),ROW(INDIRECT("A" & AB27 ) ))),"")}
AB28: =ROW(A28)- $AD$2 +1 -> 15 | AC28: =IF(AND(OR($E28="Contrôlé",$E28="Non contrôlé"),$M28="Préleveur"),$F28,"") | AD28: {=IFERROR(INDEX($AC$14:$AC$102,SMALL(IF($AC$14:$AC$102<>"",ROW($AC$14:$AC$102)-ROW(INDIRECT("$AC$14"))+1),ROW(INDIRECT("A" & AB28 ) ))),"")} | AE28: =IF(AND(OR($E28="Contrôlé",$E28="Non contrôlé"),LEFT($M28,10) ="Débitmètre"),$F28,"") | AF28: {=IFERROR(INDEX($AE$14:$AE$102,SMALL(IF($AE$14:$AE$102<>"",ROW($AE$14:$AE$102)-ROW(INDIRECT("$AE$14"))+1),ROW(INDIRECT("A" & AB28 ) ))),"")} | AG28: =IF(AND(OR($E28="Contrôlé",$E28="Non contrôlé"),LEFT($M28,5) ="Sonde"),$F28,"") | AH28: {=IFERROR(INDEX($AG$14:$AG$102,SMALL(IF($AG$14:$AG$102<>"",ROW($AG$14:$AG$102)-ROW(INDIRECT("$AG$14"))+1),ROW(INDIRECT("A" & AB28 ) ))),"")} | AI28: =IF(AND(OR($E28="Contrôlé",$E28="Non contrôlé"), $F28 <> "", $M28 = ""),$F28,"") | AJ28: {=IFERROR(INDEX($AI$14:$AI$102,SMALL(IF($AI$14:$AI$102<>"",ROW($AI$14:$AI$102)-ROW(INDIRECT("$AI$14"))+1),ROW(INDIRECT("A" & AB28 ) ))),"")}
C29: SYSTÈME DE TRAITEMENT | AB29: =ROW(A29)- $AD$2 +1 -> 16 | AC29: =IF(AND(OR($E29="Contrôlé",$E29="Non contrôlé"),$M29="Préleveur"),$F29,"") | AD29: {=IFERROR(INDEX($AC$14:$AC$102,SMALL(IF($AC$14:$AC$102<>"",ROW($AC$14:$AC$102)-ROW(INDIRECT("$AC$14"))+1),ROW(INDIRECT("A" & AB29 ) ))),"")} | AE29: =IF(AND(OR($E29="Contrôlé",$E29="Non contrôlé"),LEFT($M29,10) ="Débitmètre"),$F29,"") | AF29: {=IFERROR(INDEX($AE$14:$AE$102,SMALL(IF($AE$14:$AE$102<>"",ROW($AE$14:$AE$102)-ROW(INDIRECT("$AE$14"))+1),ROW(INDIRECT("A" & AB29 ) ))),"")} | AG29: =IF(AND(OR($E29="Contrôlé",$E29="Non contrôlé"),LEFT($M29,5) ="Sonde"),$F29,"") | AH29: {=IFERROR(INDEX($AG$14:$AG$102,SMALL(IF($AG$14:$AG$102<>"",ROW($AG$14:$AG$102)-ROW(INDIRECT("$AG$14"))+1),ROW(INDIRECT("A" & AB29 ) ))),"")} | AI29: =IF(AND(OR($E29="Contrôlé",$E29="Non contrôlé"), $F29 <> "", $M29 = ""),$F29,"") | AJ29: {=IFERROR(INDEX($AI$14:$AI$102,SMALL(IF($AI$14:$AI$102<>"",ROW($AI$14:$AI$102)-ROW(INDIRECT("$AI$14"))+1),ROW(INDIRECT("A" & AB29 ) ))),"")}
D30: Remarques : | E30: Les estimations et les apports par camion ne rentrent pas dans le CDA | AB30: =ROW(A30)- $AD$2 +1 -> 17 | AC30: =IF(AND(OR($E30="Contrôlé",$E30="Non contrôlé"),$M30="Préleveur"),$F30,"") | AD30: {=IFERROR(INDEX($AC$14:$AC$102,SMALL(IF($AC$14:$AC$102<>"",ROW($AC$14:$AC$102)-ROW(INDIRECT("$AC$14"))+1),ROW(INDIRECT("A" & AB30 ) ))),"")} | AE30: =IF(AND(OR($E30="Contrôlé",$E30="Non contrôlé"),LEFT($M30,10) ="Débitmètre"),$F30,"") | AF30: {=IFERROR(INDEX($AE$14:$AE$102,SMALL(IF($AE$14:$AE$102<>"",ROW($AE$14:$AE$102)-ROW(INDIRECT("$AE$14"))+1),ROW(INDIRECT("A" & AB30 ) ))),"")} | AG30: =IF(AND(OR($E30="Contrôlé",$E30="Non contrôlé"),LEFT($M30,5) ="Sonde"),$F30,"") | AH30: {=IFERROR(INDEX($AG$14:$AG$102,SMALL(IF($AG$14:$AG$102<>"",ROW($AG$14:$AG$102)-ROW(INDIRECT("$AG$14"))+1),ROW(INDIRECT("A" & AB30 ) ))),"")} | AI30: =IF(AND(OR($E30="Contrôlé",$E30="Non contrôlé"), $F30 <> "", $M30 = ""),$F30,"") | AJ30: {=IFERROR(INDEX($AI$14:$AI$102,SMALL(IF($AI$14:$AI$102<>"",ROW($AI$14:$AI$102)-ROW(INDIRECT("$AI$14"))+1),ROW(INDIRECT("A" & AB30 ) ))),"")}
D31: Liste des équipements du système de traitement pour chaque point d’autosurveillance | AB31: =ROW(A31)- $AD$2 +1 -> 18 | AC31: =IF(AND(OR($E31="Contrôlé",$E31="Non contrôlé"),$M31="Préleveur"),$F31,"") | AD31: {=IFERROR(INDEX($AC$14:$AC$102,SMALL(IF($AC$14:$AC$102<>"",ROW($AC$14:$AC$102)-ROW(INDIRECT("$AC$14"))+1),ROW(INDIRECT("A" & AB31 ) ))),"")} | AE31: =IF(AND(OR($E31="Contrôlé",$E31="Non contrôlé"),LEFT($M31,10) ="Débitmètre"),$F31,"") | AF31: {=IFERROR(INDEX($AE$14:$AE$102,SMALL(IF($AE$14:$AE$102<>"",ROW($AE$14:$AE$102)-ROW(INDIRECT("$AE$14"))+1),ROW(INDIRECT("A" & AB31 ) ))),"")} | AG31: =IF(AND(OR($E31="Contrôlé",$E31="Non contrôlé"),LEFT($M31,5) ="Sonde"),$F31,"") | AH31: {=IFERROR(INDEX($AG$14:$AG$102,SMALL(IF($AG$14:$AG$102<>"",ROW($AG$14:$AG$102)-ROW(INDIRECT("$AG$14"))+1),ROW(INDIRECT("A" & AB31 ) ))),"")} | AI31: =IF(AND(OR($E31="Contrôlé",$E31="Non contrôlé"), $F31 <> "", $M31 = ""),$F31,"") | AJ31: {=IFERROR(INDEX($AI$14:$AI$102,SMALL(IF($AI$14:$AI$102<>"",ROW($AI$14:$AI$102)-ROW(INDIRECT("$AI$14"))+1),ROW(INDIRECT("A" & AB31 ) ))),"")}
AB32: =ROW(A32)- $AD$2 +1 -> 19 | AC32: =IF(AND(OR($E32="Contrôlé",$E32="Non contrôlé"),$M32="Préleveur"),$F32,"") | AD32: {=IFERROR(INDEX($AC$14:$AC$102,SMALL(IF($AC$14:$AC$102<>"",ROW($AC$14:$AC$102)-ROW(INDIRECT("$AC$14"))+1),ROW(INDIRECT("A" & AB32 ) ))),"")} | AE32: =IF(AND(OR($E32="Contrôlé",$E32="Non contrôlé"),LEFT($M32,10) ="Débitmètre"),$F32,"") | AF32: {=IFERROR(INDEX($AE$14:$AE$102,SMALL(IF($AE$14:$AE$102<>"",ROW($AE$14:$AE$102)-ROW(INDIRECT("$AE$14"))+1),ROW(INDIRECT("A" & AB32 ) ))),"")} | AG32: =IF(AND(OR($E32="Contrôlé",$E32="Non contrôlé"),LEFT($M32,5) ="Sonde"),$F32,"") | AH32: {=IFERROR(INDEX($AG$14:$AG$102,SMALL(IF($AG$14:$AG$102<>"",ROW($AG$14:$AG$102)-ROW(INDIRECT("$AG$14"))+1),ROW(INDIRECT("A" & AB32 ) ))),"")} | AI32: =IF(AND(OR($E32="Contrôlé",$E32="Non contrôlé"), $F32 <> "", $M32 = ""),$F32,"") | AJ32: {=IFERROR(INDEX($AI$14:$AI$102,SMALL(IF($AI$14:$AI$102<>"",ROW($AI$14:$AI$102)-ROW(INDIRECT("$AI$14"))+1),ROW(INDIRECT("A" & AB32 ) ))),"")}
E33: Statut | F33: Lien vers l'onglet de l'équipement | H33: Point réglementaire | I33: Localisation (cf. MAS) | J33: Code du point (cf MAS) | K33: Libellé de l'équipement | M33: Type d'équipement | O33: Type de matériel | R33: Certaines informations d'un équipement ne sont pas modifiables. Au besoin il est préférable de supprimer et de recréer l'équipement. | AB33: =ROW(A33)- $AD$2 +1 -> 20 | AC33: =IF(AND(OR($E33="Contrôlé",$E33="Non contrôlé"),$M33="Préleveur"),$F33,"") | AD33: {=IFERROR(INDEX($AC$14:$AC$102,SMALL(IF($AC$14:$AC$102<>"",ROW($AC$14:$AC$102)-ROW(INDIRECT("$AC$14"))+1),ROW(INDIRECT("A" & AB33 ) ))),"")} | AE33: =IF(AND(OR($E33="Contrôlé",$E33="Non contrôlé"),LEFT($M33,10) ="Débitmètre"),$F33,"") | AF33: {=IFERROR(INDEX($AE$14:$AE$102,SMALL(IF($AE$14:$AE$102<>"",ROW($AE$14:$AE$102)-ROW(INDIRECT("$AE$14"))+1),ROW(INDIRECT("A" & AB33 ) ))),"")} | AG33: =IF(AND(OR($E33="Contrôlé",$E33="Non contrôlé"),LEFT($M33,5) ="Sonde"),$F33,"") | AH33: {=IFERROR(INDEX($AG$14:$AG$102,SMALL(IF($AG$14:$AG$102<>"",ROW($AG$14:$AG$102)-ROW(INDIRECT("$AG$14"))+1),ROW(INDIRECT("A" & AB33 ) ))),"")} | AI33: =IF(AND(OR($E33="Contrôlé",$E33="Non contrôlé"), $F33 <> "", $M33 = ""),$F33,"") | AJ33: {=IFERROR(INDEX($AI$14:$AI$102,SMALL(IF($AI$14:$AI$102<>"",ROW($AI$14:$AI$102)-ROW(INDIRECT("$AI$14"))+1),ROW(INDIRECT("A" & AB33 ) ))),"")}
AB34: =ROW(A34)- $AD$2 +1 -> 21 | AC34: =IF(AND(OR($E34="Contrôlé",$E34="Non contrôlé"),$M34="Préleveur"),$F34,"") | AD34: {=IFERROR(INDEX($AC$14:$AC$102,SMALL(IF($AC$14:$AC$102<>"",ROW($AC$14:$AC$102)-ROW(INDIRECT("$AC$14"))+1),ROW(INDIRECT("A" & AB34 ) ))),"")} | AE34: =IF(AND(OR($E34="Contrôlé",$E34="Non contrôlé"),LEFT($M34,10) ="Débitmètre"),$F34,"") | AF34: {=IFERROR(INDEX($AE$14:$AE$102,SMALL(IF($AE$14:$AE$102<>"",ROW($AE$14:$AE$102)-ROW(INDIRECT("$AE$14"))+1),ROW(INDIRECT("A" & AB34 ) ))),"")} | AG34: =IF(AND(OR($E34="Contrôlé",$E34="Non contrôlé"),LEFT($M34,5) ="Sonde"),$F34,"") | AH34: {=IFERROR(INDEX($AG$14:$AG$102,SMALL(IF($AG$14:$AG$102<>"",ROW($AG$14:$AG$102)-ROW(INDIRECT("$AG$14"))+1),ROW(INDIRECT("A" & AB34 ) ))),"")} | AI34: =IF(AND(OR($E34="Contrôlé",$E34="Non contrôlé"), $F34 <> "", $M34 = ""),$F34,"") | AJ34: {=IFERROR(INDEX($AI$14:$AI$102,SMALL(IF($AI$14:$AI$102<>"",ROW($AI$14:$AI$102)-ROW(INDIRECT("$AI$14"))+1),ROW(INDIRECT("A" & AB34 ) ))),"")}
E35: Ajouter un équipement station | K35: Si certains points ne sont pas équipés, veuillez les indiquer en commentaire : | AB35: =ROW(A35)- $AD$2 +1 -> 22 | AC35: =IF(AND(OR($E35="Contrôlé",$E35="Non contrôlé"),$M35="Préleveur"),$F35,"") | AD35: {=IFERROR(INDEX($AC$14:$AC$102,SMALL(IF($AC$14:$AC$102<>"",ROW($AC$14:$AC$102)-ROW(INDIRECT("$AC$14"))+1),ROW(INDIRECT("A" & AB35 ) ))),"")} | AE35: =IF(AND(OR($E35="Contrôlé",$E35="Non contrôlé"),LEFT($M35,10) ="Débitmètre"),$F35,"") | AF35: {=IFERROR(INDEX($AE$14:$AE$102,SMALL(IF($AE$14:$AE$102<>"",ROW($AE$14:$AE$102)-ROW(INDIRECT("$AE$14"))+1),ROW(INDIRECT("A" & AB35 ) ))),"")} | AG35: =IF(AND(OR($E35="Contrôlé",$E35="Non contrôlé"),LEFT($M35,5) ="Sonde"),$F35,"") | AH35: {=IFERROR(INDEX($AG$14:$AG$102,SMALL(IF($AG$14:$AG$102<>"",ROW($AG$14:$AG$102)-ROW(INDIRECT("$AG$14"))+1),ROW(INDIRECT("A" & AB35 ) ))),"")} | AI35: =IF(AND(OR($E35="Contrôlé",$E35="Non contrôlé"), $F35 <> "", $M35 = ""),$F35,"") | AJ35: {=IFERROR(INDEX($AI$14:$AI$102,SMALL(IF($AI$14:$AI$102<>"",ROW($AI$14:$AI$102)-ROW(INDIRECT("$AI$14"))+1),ROW(INDIRECT("A" & AB35 ) ))),"")}
AB36: =ROW(A36)- $AD$2 +1 -> 23 | AC36: =IF(AND(OR($E36="Contrôlé",$E36="Non contrôlé"),$M36="Préleveur"),$F36,"") | AD36: {=IFERROR(INDEX($AC$14:$AC$102,SMALL(IF($AC$14:$AC$102<>"",ROW($AC$14:$AC$102)-ROW(INDIRECT("$AC$14"))+1),ROW(INDIRECT("A" & AB36 ) ))),"")} | AE36: =IF(AND(OR($E36="Contrôlé",$E36="Non contrôlé"),LEFT($M36,10) ="Débitmètre"),$F36,"") | AF36: {=IFERROR(INDEX($AE$14:$AE$102,SMALL(IF($AE$14:$AE$102<>"",ROW($AE$14:$AE$102)-ROW(INDIRECT("$AE$14"))+1),ROW(INDIRECT("A" & AB36 ) ))),"")} | AG36: =IF(AND(OR($E36="Contrôlé",$E36="Non contrôlé"),LEFT($M36,5) ="Sonde"),$F36,"") | AH36: {=IFERROR(INDEX($AG$14:$AG$102,SMALL(IF($AG$14:$AG$102<>"",ROW($AG$14:$AG$102)-ROW(INDIRECT("$AG$14"))+1),ROW(INDIRECT("A" & AB36 ) ))),"")} | AI36: =IF(AND(OR($E36="Contrôlé",$E36="Non contrôlé"), $F36 <> "", $M36 = ""),$F36,"") | AJ36: {=IFERROR(INDEX($AI$14:$AI$102,SMALL(IF($AI$14:$AI$102<>"",ROW($AI$14:$AI$102)-ROW(INDIRECT("$AI$14"))+1),ROW(INDIRECT("A" & AB36 ) ))),"")}
AB37: =ROW(A37)- $AD$2 +1 -> 24 | AC37: =IF(AND(OR($E37="Contrôlé",$E37="Non contrôlé"),$M37="Préleveur"),$F37,"") | AD37: {=IFERROR(INDEX($AC$14:$AC$102,SMALL(IF($AC$14:$AC$102<>"",ROW($AC$14:$AC$102)-ROW(INDIRECT("$AC$14"))+1),ROW(INDIRECT("A" & AB37 ) ))),"")} | AE37: =IF(AND(OR($E37="Contrôlé",$E37="Non contrôlé"),LEFT($M37,10) ="Débitmètre"),$F37,"") | AF37: {=IFERROR(INDEX($AE$14:$AE$102,SMALL(IF($AE$14:$AE$102<>"",ROW($AE$14:$AE$102)-ROW(INDIRECT("$AE$14"))+1),ROW(INDIRECT("A" & AB37 ) ))),"")} | AG37: =IF(AND(OR($E37="Contrôlé",$E37="Non contrôlé"),LEFT($M37,5) ="Sonde"),$F37,"") | AH37: {=IFERROR(INDEX($AG$14:$AG$102,SMALL(IF($AG$14:$AG$102<>"",ROW($AG$14:$AG$102)-ROW(INDIRECT("$AG$14"))+1),ROW(INDIRECT("A" & AB37 ) ))),"")} | AI37: =IF(AND(OR($E37="Contrôlé",$E37="Non contrôlé"), $F37 <> "", $M37 = ""),$F37,"") | AJ37: {=IFERROR(INDEX($AI$14:$AI$102,SMALL(IF($AI$14:$AI$102<>"",ROW($AI$14:$AI$102)-ROW(INDIRECT("$AI$14"))+1),ROW(INDIRECT("A" & AB37 ) ))),"")}
AB38: =ROW(A38)- $AD$2 +1 -> 25 | AC38: =IF(AND(OR($E38="Contrôlé",$E38="Non contrôlé"),$M38="Préleveur"),$F38,"") | AD38: {=IFERROR(INDEX($AC$14:$AC$102,SMALL(IF($AC$14:$AC$102<>"",ROW($AC$14:$AC$102)-ROW(INDIRECT("$AC$14"))+1),ROW(INDIRECT("A" & AB38 ) ))),"")} | AE38: =IF(AND(OR($E38="Contrôlé",$E38="Non contrôlé"),LEFT($M38,10) ="Débitmètre"),$F38,"") | AF38: {=IFERROR(INDEX($AE$14:$AE$102,SMALL(IF($AE$14:$AE$102<>"",ROW($AE$14:$AE$102)-ROW(INDIRECT("$AE$14"))+1),ROW(INDIRECT("A" & AB38 ) ))),"")} | AG38: =IF(AND(OR($E38="Contrôlé",$E38="Non contrôlé"),LEFT($M38,5) ="Sonde"),$F38,"") | AH38: {=IFERROR(INDEX($AG$14:$AG$102,SMALL(IF($AG$14:$AG$102<>"",ROW($AG$14:$AG$102)-ROW(INDIRECT("$AG$14"))+1),ROW(INDIRECT("A" & AB38 ) ))),"")} | AI38: =IF(AND(OR($E38="Contrôlé",$E38="Non contrôlé"), $F38 <> "", $M38 = ""),$F38,"") | AJ38: {=IFERROR(INDEX($AI$14:$AI$102,SMALL(IF($AI$14:$AI$102<>"",ROW($AI$14:$AI$102)-ROW(INDIRECT("$AI$14"))+1),ROW(INDIRECT("A" & AB38 ) ))),"")}
AB39: =ROW(A39)- $AD$2 +1 -> 26 | AC39: =IF(AND(OR($E39="Contrôlé",$E39="Non contrôlé"),$M39="Préleveur"),$F39,"") | AD39: {=IFERROR(INDEX($AC$14:$AC$102,SMALL(IF($AC$14:$AC$102<>"",ROW($AC$14:$AC$102)-ROW(INDIRECT("$AC$14"))+1),ROW(INDIRECT("A" & AB39 ) ))),"")} | AE39: =IF(AND(OR($E39="Contrôlé",$E39="Non contrôlé"),LEFT($M39,10) ="Débitmètre"),$F39,"") | AF39: {=IFERROR(INDEX($AE$14:$AE$102,SMALL(IF($AE$14:$AE$102<>"",ROW($AE$14:$AE$102)-ROW(INDIRECT("$AE$14"))+1),ROW(INDIRECT("A" & AB39 ) ))),"")} | AG39: =IF(AND(OR($E39="Contrôlé",$E39="Non contrôlé"),LEFT($M39,5) ="Sonde"),$F39,"") | AH39: {=IFERROR(INDEX($AG$14:$AG$102,SMALL(IF($AG$14:$AG$102<>"",ROW($AG$14:$AG$102)-ROW(INDIRECT("$AG$14"))+1),ROW(INDIRECT("A" & AB39 ) ))),"")} | AI39: =IF(AND(OR($E39="Contrôlé",$E39="Non contrôlé"), $F39 <> "", $M39 = ""),$F39,"") | AJ39: {=IFERROR(INDEX($AI$14:$AI$102,SMALL(IF($AI$14:$AI$102<>"",ROW($AI$14:$AI$102)-ROW(INDIRECT("$AI$14"))+1),ROW(INDIRECT("A" & AB39 ) ))),"")}
D40: Liste des pluviomètres de référence de la station | AB40: =ROW(A40)- $AD$2 +1 -> 27 | AC40: =IF(AND(OR($E40="Contrôlé",$E40="Non contrôlé"),$M40="Préleveur"),$F40,"") | AD40: {=IFERROR(INDEX($AC$14:$AC$102,SMALL(IF($AC$14:$AC$102<>"",ROW($AC$14:$AC$102)-ROW(INDIRECT("$AC$14"))+1),ROW(INDIRECT("A" & AB40 ) ))),"")} | AE40: =IF(AND(OR($E40="Contrôlé",$E40="Non contrôlé"),LEFT($M40,10) ="Débitmètre"),$F40,"") | AF40: {=IFERROR(INDEX($AE$14:$AE$102,SMALL(IF($AE$14:$AE$102<>"",ROW($AE$14:$AE$102)-ROW(INDIRECT("$AE$14"))+1),ROW(INDIRECT("A" & AB40 ) ))),"")} | AG40: =IF(AND(OR($E40="Contrôlé",$E40="Non contrôlé"),LEFT($M40,5) ="Sonde"),$F40,"") | AH40: {=IFERROR(INDEX($AG$14:$AG$102,SMALL(IF($AG$14:$AG$102<>"",ROW($AG$14:$AG$102)-ROW(INDIRECT("$AG$14"))+1),ROW(INDIRECT("A" & AB40 ) ))),"")} | AI40: =IF(AND(OR($E40="Contrôlé",$E40="Non contrôlé"), $F40 <> "", $M40 = ""),$F40,"") | AJ40: {=IFERROR(INDEX($AI$14:$AI$102,SMALL(IF($AI$14:$AI$102<>"",ROW($AI$14:$AI$102)-ROW(INDIRECT("$AI$14"))+1),ROW(INDIRECT("A" & AB40 ) ))),"")}
AB41: =ROW(A41)- $AD$2 +1 -> 28 | AC41: =IF(AND(OR($E41="Contrôlé",$E41="Non contrôlé"),$M41="Préleveur"),$F41,"") | AD41: {=IFERROR(INDEX($AC$14:$AC$102,SMALL(IF($AC$14:$AC$102<>"",ROW($AC$14:$AC$102)-ROW(INDIRECT("$AC$14"))+1),ROW(INDIRECT("A" & AB41 ) ))),"")} | AE41: =IF(AND(OR($E41="Contrôlé",$E41="Non contrôlé"),LEFT($M41,10) ="Débitmètre"),$F41,"") | AF41: {=IFERROR(INDEX($AE$14:$AE$102,SMALL(IF($AE$14:$AE$102<>"",ROW($AE$14:$AE$102)-ROW(INDIRECT("$AE$14"))+1),ROW(INDIRECT("A" & AB41 ) ))),"")} | AG41: =IF(AND(OR($E41="Contrôlé",$E41="Non contrôlé"),LEFT($M41,5) ="Sonde"),$F41,"") | AH41: {=IFERROR(INDEX($AG$14:$AG$102,SMALL(IF($AG$14:$AG$102<>"",ROW($AG$14:$AG$102)-ROW(INDIRECT("$AG$14"))+1),ROW(INDIRECT("A" & AB41 ) ))),"")} | AI41: =IF(AND(OR($E41="Contrôlé",$E41="Non contrôlé"), $F41 <> "", $M41 = ""),$F41,"") | AJ41: {=IFERROR(INDEX($AI$14:$AI$102,SMALL(IF($AI$14:$AI$102<>"",ROW($AI$14:$AI$102)-ROW(INDIRECT("$AI$14"))+1),ROW(INDIRECT("A" & AB41 ) ))),"")}
E42: Actif | F42: Lien vers l'onglet de l'équipement | AB42: =ROW(A42)- $AD$2 +1 -> 29 | AC42: =IF(AND(OR($E42="Contrôlé",$E42="Non contrôlé"),$M42="Préleveur"),$F42,"") | AD42: {=IFERROR(INDEX($AC$14:$AC$102,SMALL(IF($AC$14:$AC$102<>"",ROW($AC$14:$AC$102)-ROW(INDIRECT("$AC$14"))+1),ROW(INDIRECT("A" & AB42 ) ))),"")} | AE42: =IF(AND(OR($E42="Contrôlé",$E42="Non contrôlé"),LEFT($M42,10) ="Débitmètre"),$F42,"") | AF42: {=IFERROR(INDEX($AE$14:$AE$102,SMALL(IF($AE$14:$AE$102<>"",ROW($AE$14:$AE$102)-ROW(INDIRECT("$AE$14"))+1),ROW(INDIRECT("A" & AB42 ) ))),"")} | AG42: =IF(AND(OR($E42="Contrôlé",$E42="Non contrôlé"),LEFT($M42,5) ="Sonde"),$F42,"") | AH42: {=IFERROR(INDEX($AG$14:$AG$102,SMALL(IF($AG$14:$AG$102<>"",ROW($AG$14:$AG$102)-ROW(INDIRECT("$AG$14"))+1),ROW(INDIRECT("A" & AB42 ) ))),"")} | AI42: =IF(AND(OR($E42="Contrôlé",$E42="Non contrôlé"), $F42 <> "", $M42 = ""),$F42,"") | AJ42: {=IFERROR(INDEX($AI$14:$AI$102,SMALL(IF($AI$14:$AI$102<>"",ROW($AI$14:$AI$102)-ROW(INDIRECT("$AI$14"))+1),ROW(INDIRECT("A" & AB42 ) ))),"")}
...

Sheet SYNTHESE_SCL
C2: CONTRÔLE DES DISPOSITIFS D'AUTOSURVEILLANCE DU SYSTÈME DE COLLECTE | Y2: Exporter en Word
C3: NOM DU SYSTÈME D'ASSAINISSEMENT : | G3: =IF(ISBLANK(Descriptif!F3),"",Descriptif!F3) | J3: NOM DU SYSTÈME DE TRAITEMENT : | M3: =IF(ISBLANK(Descriptif!L3),"",Descriptif!L3) | P3: NOM DU SYSTÈME DE COLLECTE : | S3: =IF(ISBLANK(Descriptif!Q3),"",Descriptif!Q3) | V3: NOM DE L'ORGANISME DE CONTRÔLE : | Y3: =IF(ISBLANK(Descriptif!U3),"",Descriptif!U3)
C4: CODE SANDRE DE L'AGGLOMÉRATION : | G4: =IF(ISBLANK(Descriptif!F4),"",Descriptif!F4) | J4: CODE SANDRE DE LA STATION : | M4: =IF(ISBLANK(Descriptif!L4),"",Descriptif!L4) | P4: CODE SANDRE DU RÉSEAU : | S4: =IF(ISBLANK(Descriptif!Q4),"",Descriptif!Q4) | V4: NOM(S) DU(ES) CONTROLEUR(S) : | Y4: =IF(ISBLANK(Descriptif!U4),"",Descriptif!U4)
C5: MAITRE D'OUVRAGE DE LA STATION : | G5: =IF(ISBLANK(Descriptif!F5),"",Descriptif!F5) | J5: TYPE DE TRAITEMENT : | M5: =IF(ISBLANK(Descriptif!L5),"",Descriptif!L5) | P5: TYPE DE RÉSEAU : | S5: =IF(ISBLANK(Descriptif!Q5),"",Descriptif!Q5) | V5: DATE(S) D'INTERVENTION : | Y5: =IF(ISBLANK(Descriptif!U5),"",Descriptif!U5)
C6: EXPLOITANT DE LA STATION : | G6: =IF(ISBLANK(Descriptif!F6),"",Descriptif!F6) | J6: CAPACITÉ DE LA STATION : | M6: =IF(ISBLANK(Descriptif!L6),"",Descriptif!L6) | P6: EXPLOITANT DU RÉSEAU : | S6: =IF(ISBLANK(Descriptif!Q6),"",Descriptif!Q6) | V6: CONDITION(S) MÉTÉO : | Y6: =IF(ISBLANK(Descriptif!U6),"",Descriptif!U6)
C8: SYNTHÈSE DES CONTRÔLES RÉALISÉS SUR LES DISPOSITIFS AUTOSURVEILLANCE
D10: Évaluation documentaire
M11: Coefficient Qualité | N11: Commentaires sur l'évaluation :
G12: Manuel autosurveillance à jour, validé ou en cours d'expertise ? | L12: =IF(Qualité!$L$10<>"",Qualité!$L$10,"Non contrôlé") -> Non contrôlé | N12: =IF(Qualité!$M$10<>"",Qualité!$M$10,"")
G13: Existe-t-il un système Qualité performant ? | L13: =IF(Qualité!$L$29<>"",Qualité!$L$29,"Non contrôlé") -> Non contrôlé | M13: =IF(Qualité!$L$29="Oui",1,0.9) -> 0.9 | N13: =IF(Qualité!$D$32<>"",Qualité!$D$32,"")
D16: Évaluation des pratiques de fractionnement et de transport des échantillons
K17: Penalité | N17: Commentaires sur l'évaluation :
G18: SDE | I18: Aquaref | K18: =IF(Analytique!N11<>"",Analytique!N11,"") | N18: =IF(Analytique!D17<>"",Analytique!D17,"")
G19: Eaux résiduaires | I19: Fractionnement | K19: =IF(Analytique!N12<>"",Analytique!N12,"")
I20: Température | K20: =IF(Analytique!N13<>"",Analytique!N13,"")
I21: Transport | K21: =IF(Analytique!N14<>"",Analytique!N14,"")
D24: Autres évaluations
K25: Score | N25: Commentaires sur l'évaluation :
G26: Sonde température | I26: {=IFERROR(INDEX(Equipements_SCL!$L$16:$L$72,SMALL(IF(Equipements_SCL!$J$16:$J$72="Sonde de température",ROW(Equipements_SCL!$J$16:$J$72)-ROW(Equipements_SCL!$J$16)+1),ROW(1:1))),"")} | K26: {=IFERROR(INDEX(Equipements_SCL!$P$16:$P$72,SMALL(IF(Equipements_SCL!$J$16:$J$72="Sonde de température",ROW(Equipements_SCL!$J$16:$J$72)-ROW(Equipements_SCL!$J$16)+1),ROW(1:1))),"")} | N26: {=IFERROR(INDEX(Equipements_SCL!$T$16:$T$72,SMALL(IF(Equipements_SCL!$J$16:$J$72="Sonde de température",ROW(Equipements_SCL!$J$16:$J$72)-ROW(Equipements_SCL!$J$16)+1),ROW(1:1))),"")}
I27: {=IFERROR(INDEX(Equipements_SCL!$L$16:$L$72,SMALL(IF(Equipements_SCL!$J$16:$J$72="Sonde de température",ROW(Equipements_SCL!$J$16:$J$72)-ROW(Equipements_SCL!$J$16)+1),ROW(2:2))),"")} | K27: {=IFERROR(INDEX(Equipements_SCL!$R$16:$R$72,SMALL(IF(Equipements_SCL!$J$16:$J$72="Sonde de température",ROW(Equipements_SCL!$J$16:$J$72)-ROW(Equipements_SCL!$J$16)+1),ROW(2:2))),"")} | N27: {=IFERROR(INDEX(Equipements_SCL!$T$16:$T$72,SMALL(IF(Equipements_SCL!$J$16:$J$72="Sonde de température",ROW(Equipements_SCL!$J$16:$J$72)-ROW(Equipements_SCL!$J$16)+1),ROW(2:2))),"")}
I28: {=IFERROR(INDEX(Equipements_SCL!$L$16:$L$72,SMALL(IF(Equipements_SCL!$J$16:$J$72="Sonde de température",ROW(Equipements_SCL!$J$16:$J$72)-ROW(Equipements_SCL!$J$16)+1),ROW(3:3))),"")} | K28: {=IFERROR(INDEX(Equipements_SCL!$R$16:$R$72,SMALL(IF(Equipements_SCL!$J$16:$J$72="Sonde de température",ROW(Equipements_SCL!$J$16:$J$72)-ROW(Equipements_SCL!$J$16)+1),ROW(3:3))),"")} | N28: {=IFERROR(INDEX(Equipements_SCL!$T$16:$T$72,SMALL(IF(Equipements_SCL!$J$16:$J$72="Sonde de température",ROW(Equipements_SCL!$J$16:$J$72)-ROW(Equipements_SCL!$J$16)+1),ROW(3:3))),"")}
K30: Score | N30: Commentaires sur l'évaluation :
G31: Pluviomètre | I31: {=IFERROR(INDEX(Equipements_SCL!$L$16:$L$72,SMALL(IF(Equipements_SCL!$J$16:$J$72="Pluviomètre",ROW(Equipements_SCL!$J$16:$J$72)-ROW(Equipements_SCL!$J$16)+1),ROW(1:1))),"")} | K31: {=IFERROR(INDEX(Equipements_SCL!$P$16:$P$72,SMALL(IF(Equipements_SCL!$J$16:$J$72="Pluviomètre",ROW(Equipements_SCL!$J$16:$J$72)-ROW(Equipements_SCL!$J$16)+1),ROW(1:1))),"")} | N31: {=IFERROR(INDEX(Equipements_SCL!$T$16:$T$72,SMALL(IF(Equipements_SCL!$J$16:$J$72="Pluviomètre",ROW(Equipements_SCL!$J$16:$J$72)-ROW(Equipements_SCL!$J$16)+1),ROW(1:1))),"")}
I32: {=IFERROR(INDEX(Equipements_SCL!$L$16:$L$72,SMALL(IF(Equipements_SCL!$J$16:$J$72="Pluviomètre",ROW(Equipements_SCL!$J$16:$J$72)-ROW(Equipements_SCL!$J$16)+1),ROW(2:2))),"")} | K32: {=IFERROR(INDEX(Equipements_SCL!$P$16:$P$72,SMALL(IF(Equipements_SCL!$J$16:$J$72="Pluviomètre",ROW(Equipements_SCL!$J$16:$J$72)-ROW(Equipements_SCL!$J$16)+1),ROW(2:2))),"")} | N32: {=IFERROR(INDEX(Equipements_SCL!$T$16:$T$72,SMALL(IF(Equipements_SCL!$J$16:$J$72="Pluviomètre",ROW(Equipements_SCL!$J$16:$J$72)-ROW(Equipements_SCL!$J$16)+1),ROW(2:2))),"")}
I33: {=IFERROR(INDEX(Equipements_SCL!$L$16:$L$72,SMALL(IF(Equipements_SCL!$J$16:$J$72="Pluviomètre",ROW(Equipements_SCL!$J$16:$J$72)-ROW(Equipements_SCL!$J$16)+1),ROW(3:3))),"")} | K33: {=IFERROR(INDEX(Equipements_SCL!$P$16:$P$72,SMALL(IF(Equipements_SCL!$J$16:$J$72="Pluviomètre",ROW(Equipements_SCL!$J$16:$J$72)-ROW(Equipements_SCL!$J$16)+1),ROW(3:3))),"")} | N33: {=IFERROR(INDEX(Equipements_SCL!$T$16:$T$72,SMALL(IF(Equipements_SCL!$J$16:$J$72="Pluviomètre",ROW(Equipements_SCL!$J$16:$J$72)-ROW(Equipements_SCL!$J$16)+1),ROW(3:3))),"")}
D36: Évaluation des points règlementaires du réseau
G37: Point | H37: Score | I37: Débitmètre | J37: Préleveur | K37: Analytique | AD37: Débitmètre gravitaire | AE37: Débitmètre en charge
G38: {=_xlfn._xlws.SORT(_xlfn.UNIQUE(_xlfn._xlws.FILTER(Equipements_SCL!$M$16:M100, Equipements_SCL!$M$16:M100<>"", "")))} | H38: =IF(AND($G38<>"",OR($I38<>"",$J38<>"",$K38<>"")),AVERAGE($I38,$J38,$K38),"") | I38: =IF(AND($G38<>"",OR($AD38<>"",$AE38<>"")),MAX($AD38,$AE38),"") | J38: =IF($G38="", "", IF(COUNTIFS(Equipements_SCL!$M$16:$M$100, $G38, Equipements_SCL!$J$16:$J$100, J$37)=0, "", IF(SUMIFS(Equipements_SCL!$AV$16:$AV$100, Equipements_SCL!$M$16:$M$100, $G38, Equipements_SCL!$J$16:$J$100, J$37)=-1, "", SUMIFS(Equipements_SCL!$P$16:$P$100, Equipements_SCL!$M$16:$M$100, $G38, Equipements_SCL!$J$16:$J$100, J$37)))) | K38: =IF( $G38="", "", IF( SUMIFS(Analytique!$AD$3:$AD$20, Analytique!$Z$3:$Z$20, $G38, Analytique!$Y$3:$Y$20, "A1")=0, "", SUMIFS(Analytique!$AD$3:$AD$20, Analytique!$Z$3:$Z$20, $G38, Analytique!$Y$3:$Y$20, "A1") ) ) | AD38: =IF($G38="", "", IF(COUNTIFS(Equipements_SCL!$M$16:$M$100, $G38, Equipements_SCL!$J$16:$J$100, AD$37)=0, "", IF(SUMIFS(Equipements_SCL!$AV$16:$AV$100, Equipements_SCL!$M$16:$M$100, $G38, Equipements_SCL!$J$16:$J$100, AD$37)=-1, "", SUMIFS(Equipements_SCL!$P$16:$P$100, Equipements_SCL!$M$16:$M$100, $G38, Equipements_SCL!$J$16:$J$100, AD$37)))) | AE38: =IF($G38="", "", IF(COUNTIFS(Equipements_SCL!$M$16:$M$100, $G38, Equipements_SCL!$J$16:$J$100, AE$37)=0, "", IF(SUMIFS(Equipements_SCL!$AV$16:$AV$100, Equipements_SCL!$M$16:$M$100, $G38, Equipements_SCL!$J$16:$J$100, AE$37)=-1, "", SUMIFS(Equipements_SCL!$P$16:$P$100, Equipements_SCL!$M$16:$M$100, $G38, Equipements_SCL!$J$16:$J$100, AE$37))))
H39: =IF(AND($G39<>"",OR($I39<>"",$J39<>"",$K39<>"")),AVERAGE($I39,$J39,$K39),"") | I39: =IF(AND($G39<>"",OR($AD39<>"",$AE39<>"")),MAX($AD39,$AE39),"") | J39: =IF($G39="", "", IF(COUNTIFS(Equipements_SCL!$M$16:$M$100, $G39, Equipements_SCL!$J$16:$J$100, J$37)=0, "", IF(SUMIFS(Equipements_SCL!$AV$16:$AV$100, Equipements_SCL!$M$16:$M$100, $G39, Equipements_SCL!$J$16:$J$100, J$37)=-1, "", SUMIFS(Equipements_SCL!$P$16:$P$100, Equipements_SCL!$M$16:$M$100, $G39, Equipements_SCL!$J$16:$J$100, J$37)))) | K39: =IF( $G39="", "", IF( SUMIFS(Analytique!$AD$3:$AD$20, Analytique!$Z$3:$Z$20, $G39, Analytique!$Y$3:$Y$20, "A1")=0, "", SUMIFS(Analytique!$AD$3:$AD$20, Analytique!$Z$3:$Z$20, $G39, Analytique!$Y$3:$Y$20, "A1") ) ) | AD39: =IF($G39="", "", IF(COUNTIFS(Equipements_SCL!$M$16:$M$100, $G39, Equipements_SCL!$J$16:$J$100, AD$37)=0, "", IF(SUMIFS(Equipements_SCL!$AV$16:$AV$100, Equipements_SCL!$M$16:$M$100, $G39, Equipements_SCL!$J$16:$J$100, AD$37)=-1, "", SUMIFS(Equipements_SCL!$P$16:$P$100, Equipements_SCL!$M$16:$M$100, $G39, Equipements_SCL!$J$16:$J$100, AD$37)))) | AE39: =IF($G39="", "", IF(COUNTIFS(Equipements_SCL!$M$16:$M$100, $G39, Equipements_SCL!$J$16:$J$100, AE$37)=0, "", IF(SUMIFS(Equipements_SCL!$AV$16:$AV$100, Equipements_SCL!$M$16:$M$100, $G39, Equipements_SCL!$J$16:$J$100, AE$37)=-1, "", SUMIFS(Equipements_SCL!$P$16:$P$100, Equipements_SCL!$M$16:$M$100, $G39, Equipements_SCL!$J$16:$J$100, AE$37))))
H40: =IF(AND($G40<>"",OR($I40<>"",$J40<>"",$K40<>"")),AVERAGE($I40,$J40,$K40),"") | I40: =IF(AND($G40<>"",OR($AD40<>"",$AE40<>"")),MAX($AD40,$AE40),"") | J40: =IF($G40="", "", IF(COUNTIFS(Equipements_SCL!$M$16:$M$100, $G40, Equipements_SCL!$J$16:$J$100, J$37)=0, "", IF(SUMIFS(Equipements_SCL!$AV$16:$AV$100, Equipements_SCL!$M$16:$M$100, $G40, Equipements_SCL!$J$16:$J$100, J$37)=-1, "", SUMIFS(Equipements_SCL!$P$16:$P$100, Equipements_SCL!$M$16:$M$100, $G40, Equipements_SCL!$J$16:$J$100, J$37)))) | K40: =IF( $G40="", "", IF( SUMIFS(Analytique!$AD$3:$AD$20, Analytique!$Z$3:$Z$20, $G40, Analytique!$Y$3:$Y$20, "A1")=0, "", SUMIFS(Analytique!$AD$3:$AD$20, Analytique!$Z$3:$Z$20, $G40, Analytique!$Y$3:$Y$20, "A1") ) ) | AD40: =IF($G40="", "", IF(COUNTIFS(Equipements_SCL!$M$16:$M$100, $G40, Equipements_SCL!$J$16:$J$100, AD$37)=0, "", IF(SUMIFS(Equipements_SCL!$AV$16:$AV$100, Equipements_SCL!$M$16:$M$100, $G40, Equipements_SCL!$J$16:$J$100, AD$37)=-1, "", SUMIFS(Equipements_SCL!$P$16:$P$100, Equipements_SCL!$M$16:$M$100, $G40, Equipements_SCL!$J$16:$J$100, AD$37)))) | AE40: =IF($G40="", "", IF(COUNTIFS(Equipements_SCL!$M$16:$M$100, $G40, Equipements_SCL!$J$16:$J$100, AE$37)=0, "", IF(SUMIFS(Equipements_SCL!$AV$16:$AV$100, Equipements_SCL!$M$16:$M$100, $G40, Equipements_SCL!$J$16:$J$100, AE$37)=-1, "", SUMIFS(Equipements_SCL!$P$16:$P$100, Equipements_SCL!$M$16:$M$100, $G40, Equipements_SCL!$J$16:$J$100, AE$37))))
H41: =IF(AND($G41<>"",OR($I41<>"",$J41<>"",$K41<>"")),AVERAGE($I41,$J41,$K41),"") | I41: =IF(AND($G41<>"",OR($AD41<>"",$AE41<>"")),MAX($AD41,$AE41),"") | J41: =IF($G41="", "", IF(COUNTIFS(Equipements_SCL!$M$16:$M$100, $G41, Equipements_SCL!$J$16:$J$100, J$37)=0, "", IF(SUMIFS(Equipements_SCL!$AV$16:$AV$100, Equipements_SCL!$M$16:$M$100, $G41, Equipements_SCL!$J$16:$J$100, J$37)=-1, "", SUMIFS(Equipements_SCL!$P$16:$P$100, Equipements_SCL!$M$16:$M$100, $G41, Equipements_SCL!$J$16:$J$100, J$37)))) | K41: =IF( $G41="", "", IF( SUMIFS(Analytique!$AD$3:$AD$20, Analytique!$Z$3:$Z$20, $G41, Analytique!$Y$3:$Y$20, "A1")=0, "", SUMIFS(Analytique!$AD$3:$AD$20, Analytique!$Z$3:$Z$20, $G41, Analytique!$Y$3:$Y$20, "A1") ) ) | AD41: =IF($G41="", "", IF(COUNTIFS(Equipements_SCL!$M$16:$M$100, $G41, Equipements_SCL!$J$16:$J$100, AD$37)=0, "", IF(SUMIFS(Equipements_SCL!$AV$16:$AV$100, Equipements_SCL!$M$16:$M$100, $G41, Equipements_SCL!$J$16:$J$100, AD$37)=-1, "", SUMIFS(Equipements_SCL!$P$16:$P$100, Equipements_SCL!$M$16:$M$100, $G41, Equipements_SCL!$J$16:$J$100, AD$37)))) | AE41: =IF($G41="", "", IF(COUNTIFS(Equipements_SCL!$M$16:$M$100, $G41, Equipements_SCL!$J$16:$J$100, AE$37)=0, "", IF(SUMIFS(Equipements_SCL!$AV$16:$AV$100, Equipements_SCL!$M$16:$M$100, $G41, Equipements_SCL!$J$16:$J$100, AE$37)=-1, "", SUMIFS(Equipements_SCL!$P$16:$P$100, Equipements_SCL!$M$16:$M$100, $G41, Equipements_SCL!$J$16:$J$100, AE$37))))
H42: =IF(AND($G42<>"",OR($I42<>"",$J42<>"",$K42<>"")),AVERAGE($I42,$J42,$K42),"") | I42: =IF(AND($G42<>"",OR($AD42<>"",$AE42<>"")),MAX($AD42,$AE42),"") | J42: =IF($G42="", "", IF(COUNTIFS(Equipements_SCL!$M$16:$M$100, $G42, Equipements_SCL!$J$16:$J$100, J$37)=0, "", IF(SUMIFS(Equipements_SCL!$AV$16:$AV$100, Equipements_SCL!$M$16:$M$100, $G42, Equipements_SCL!$J$16:$J$100, J$37)=-1, "", SUMIFS(Equipements_SCL!$P$16:$P$100, Equipements_SCL!$M$16:$M$100, $G42, Equipements_SCL!$J$16:$J$100, J$37)))) | K42: =IF( $G42="", "", IF( SUMIFS(Analytique!$AD$3:$AD$20, Analytique!$Z$3:$Z$20, $G42, Analytique!$Y$3:$Y$20, "A1")=0, "", SUMIFS(Analytique!$AD$3:$AD$20, Analytique!$Z$3:$Z$20, $G42, Analytique!$Y$3:$Y$20, "A1") ) ) | AD42: =IF($G42="", "", IF(COUNTIFS(Equipements_SCL!$M$16:$M$100, $G42, Equipements_SCL!$J$16:$J$100, AD$37)=0, "", IF(SUMIFS(Equipements_SCL!$AV$16:$AV$100, Equipements_SCL!$M$16:$M$100, $G42, Equipements_SCL!$J$16:$J$100, AD$37)=-1, "", SUMIFS(Equipements_SCL!$P$16:$P$100, Equipements_SCL!$M$16:$M$100, $G42, Equipements_SCL!$J$16:$J$100, AD$37)))) | AE42: =IF($G42="", "", IF(COUNTIFS(Equipements_SCL!$M$16:$M$100, $G42, Equipements_SCL!$J$16:$J$100, AE$37)=0, "", IF(SUMIFS(Equipements_SCL!$AV$16:$AV$100, Equipements_SCL!$M$16:$M$100, $G42, Equipements_SCL!$J$16:$J$100, AE$37)=-1, "", SUMIFS(Equipements_SCL!$P$16:$P$100, Equipements_SCL!$M$16:$M$100, $G42, Equipements_SCL!$J$16:$J$100, AE$37))))
H43: =IF(AND($G43<>"",OR($I43<>"",$J43<>"",$K43<>"")),AVERAGE($I43,$J43,$K43),"") | I43: =IF(AND($G43<>"",OR($AD43<>"",$AE43<>"")),MAX($AD43,$AE43),"") | J43: =IF($G43="", "", IF(COUNTIFS(Equipements_SCL!$M$16:$M$100, $G43, Equipements_SCL!$J$16:$J$100, J$37)=0, "", IF(SUMIFS(Equipements_SCL!$AV$16:$AV$100, Equipements_SCL!$M$16:$M$100, $G43, Equipements_SCL!$J$16:$J$100, J$37)=-1, "", SUMIFS(Equipements_SCL!$P$16:$P$100, Equipements_SCL!$M$16:$M$100, $G43, Equipements_SCL!$J$16:$J$100, J$37)))) | K43: =IF( $G43="", "", IF( SUMIFS(Analytique!$AD$3:$AD$20, Analytique!$Z$3:$Z$20, $G43, Analytique!$Y$3:$Y$20, "A1")=0, "", SUMIFS(Analytique!$AD$3:$AD$20, Analytique!$Z$3:$Z$20, $G43, Analytique!$Y$3:$Y$20, "A1") ) ) | AD43: =IF($G43="", "", IF(COUNTIFS(Equipements_SCL!$M$16:$M$100, $G43, Equipements_SCL!$J$16:$J$100, AD$37)=0, "", IF(SUMIFS(Equipements_SCL!$AV$16:$AV$100, Equipements_SCL!$M$16:$M$100, $G43, Equipements_SCL!$J$16:$J$100, AD$37)=-1, "", SUMIFS(Equipements_SCL!$P$16:$P$100, Equipements_SCL!$M$16:$M$100, $G43, Equipements_SCL!$J$16:$J$100, AD$37)))) | AE43: =IF($G43="", "", IF(COUNTIFS(Equipements_SCL!$M$16:$M$100, $G43, Equipements_SCL!$J$16:$J$100, AE$37)=0, "", IF(SUMIFS(Equipements_SCL!$AV$16:$AV$100, Equipements_SCL!$M$16:$M$100, $G43, Equipements_SCL!$J$16:$J$100, AE$37)=-1, "", SUMIFS(Equipements_SCL!$P$16:$P$100, Equipements_SCL!$M$16:$M$100, $G43, Equipements_SCL!$J$16:$J$100, AE$37))))
H44: =IF(AND($G44<>"",OR($I44<>"",$J44<>"",$K44<>"")),AVERAGE($I44,$J44,$K44),"") | I44: =IF(AND($G44<>"",OR($AD44<>"",$AE44<>"")),MAX($AD44,$AE44),"") | J44: =IF($G44="", "", IF(COUNTIFS(Equipements_SCL!$M$16:$M$100, $G44, Equipements_SCL!$J$16:$J$100, J$37)=0, "", IF(SUMIFS(Equipements_SCL!$AV$16:$AV$100, Equipements_SCL!$M$16:$M$100, $G44, Equipements_SCL!$J$16:$J$100, J$37)=-1, "", SUMIFS(Equipements_SCL!$P$16:$P$100, Equipements_SCL!$M$16:$M$100, $G44, Equipements_SCL!$J$16:$J$100, J$37)))) | K44: =IF( $G44="", "", IF( SUMIFS(Analytique!$AD$3:$AD$20, Analytique!$Z$3:$Z$20, $G44, Analytique!$Y$3:$Y$20, "A1")=0, "", SUMIFS(Analytique!$AD$3:$AD$20, Analytique!$Z$3:$Z$20, $G44, Analytique!$Y$3:$Y$20, "A1") ) ) | AD44: =IF($G44="", "", IF(COUNTIFS(Equipements_SCL!$M$16:$M$100, $G44, Equipements_SCL!$J$16:$J$100, AD$37)=0, "", IF(SUMIFS(Equipements_SCL!$AV$16:$AV$100, Equipements_SCL!$M$16:$M$100, $G44, Equipements_SCL!$J$16:$J$100, AD$37)=-1, "", SUMIFS(Equipements_SCL!$P$16:$P$100, Equipements_SCL!$M$16:$M$100, $G44, Equipements_SCL!$J$16:$J$100, AD$37)))) | AE44: =IF($G44="", "", IF(COUNTIFS(Equipements_SCL!$M$16:$M$100, $G44, Equipements_SCL!$J$16:$J$100, AE$37)=0, "", IF(SUMIFS(Equipements_SCL!$AV$16:$AV$100, Equipements_SCL!$M$16:$M$100, $G44, Equipements_SCL!$J$16:$J$100, AE$37)=-1, "", SUMIFS(Equipements_SCL!$P$16:$P$100, Equipements_SCL!$M$16:$M$100, $G44, Equipements_SCL!$J$16:$J$100, AE$37))))
H45: =IF(AND($G45<>"",OR($I45<>"",$J45<>"",$K45<>"")),AVERAGE($I45,$J45,$K45),"") | I45: =IF(AND($G45<>"",OR($AD45<>"",$AE45<>"")),MAX($AD45,$AE45),"") | J45: =IF($G45="", "", IF(COUNTIFS(Equipements_SCL!$M$16:$M$100, $G45, Equipements_SCL!$J$16:$J$100, J$37)=0, "", IF(SUMIFS(Equipements_SCL!$AV$16:$AV$100, Equipements_SCL!$M$16:$M$100, $G45, Equipements_SCL!$J$16:$J$100, J$37)=-1, "", SUMIFS(Equipements_SCL!$P$16:$P$100, Equipements_SCL!$M$16:$M$100, $G45, Equipements_SCL!$J$16:$J$100, J$37)))) | K45: =IF( $G45="", "", IF( SUMIFS(Analytique!$AD$3:$AD$20, Analytique!$Z$3:$Z$20, $G45, Analytique!$Y$3:$Y$20, "A1")=0, "", SUMIFS(Analytique!$AD$3:$AD$20, Analytique!$Z$3:$Z$20, $G45, Analytique!$Y$3:$Y$20, "A1") ) ) | AD45: =IF($G45="", "", IF(COUNTIFS(Equipements_SCL!$M$16:$M$100, $G45, Equipements_SCL!$J$16:$J$100, AD$37)=0, "", IF(SUMIFS(Equipements_SCL!$AV$16:$AV$100, Equipements_SCL!$M$16:$M$100, $G45, Equipements_SCL!$J$16:$J$100, AD$37)=-1, "", SUMIFS(Equipements_SCL!$P$16:$P$100, Equipements_SCL!$M$16:$M$100, $G45, Equipements_SCL!$J$16:$J$100, AD$37)))) | AE45: =IF($G45="", "", IF(COUNTIFS(Equipements_SCL!$M$16:$M$100, $G45, Equipements_SCL!$J$16:$J$100, AE$37)=0, "", IF(SUMIFS(Equipements_SCL!$AV$16:$AV$100, Equipements_SCL!$M$16:$M$100, $G45, Equipements_SCL!$J$16:$J$100, AE$37)=-1, "", SUMIFS(Equipements_SCL!$P$16:$P$100, Equipements_SCL!$M$16:$M$100, $G45, Equipements_SCL!$J$16:$J$100, AE$37))))
H46: =IF(AND($G46<>"",OR($I46<>"",$J46<>"",$K46<>"")),AVERAGE($I46,$J46,$K46),"") | I46: =IF(AND($G46<>"",OR($AD46<>"",$AE46<>"")),MAX($AD46,$AE46),"") | J46: =IF($G46="", "", IF(COUNTIFS(Equipements_SCL!$M$16:$M$100, $G46, Equipements_SCL!$J$16:$J$100, J$37)=0, "", IF(SUMIFS(Equipements_SCL!$AV$16:$AV$100, Equipements_SCL!$M$16:$M$100, $G46, Equipements_SCL!$J$16:$J$100, J$37)=-1, "", SUMIFS(Equipements_SCL!$P$16:$P$100, Equipements_SCL!$M$16:$M$100, $G46, Equipements_SCL!$J$16:$J$100, J$37)))) | K46: =IF( $G46="", "", IF( SUMIFS(Analytique!$AD$3:$AD$20, Analytique!$Z$3:$Z$20, $G46, Analytique!$Y$3:$Y$20, "A1")=0, "", SUMIFS(Analytique!$AD$3:$AD$20, Analytique!$Z$3:$Z$20, $G46, Analytique!$Y$3:$Y$20, "A1") ) ) | AD46: =IF($G46="", "", IF(COUNTIFS(Equipements_SCL!$M$16:$M$100, $G46, Equipements_SCL!$J$16:$J$100, AD$37)=0, "", IF(SUMIFS(Equipements_SCL!$AV$16:$AV$100, Equipements_SCL!$M$16:$M$100, $G46, Equipements_SCL!$J$16:$J$100, AD$37)=-1, "", SUMIFS(Equipements_SCL!$P$16:$P$100, Equipements_SCL!$M$16:$M$100, $G46, Equipements_SCL!$J$16:$J$100, AD$37)))) | AE46: =IF($G46="", "", IF(COUNTIFS(Equipements_SCL!$M$16:$M$100, $G46, Equipements_SCL!$J$16:$J$100, AE$37)=0, "", IF(SUMIFS(Equipements_SCL!$AV$16:$AV$100, Equipements_SCL!$M$16:$M$100, $G46, Equipements_SCL!$J$16:$J$100, AE$37)=-1, "", SUMIFS(Equipements_SCL!$P$16:$P$100, Equipements_SCL!$M$16:$M$100, $G46, Equipements_SCL!$J$16:$J$100, AE$37))))
H47: =IF(AND($G47<>"",OR($I47<>"",$J47<>"",$K47<>"")),AVERAGE($I47,$J47,$K47),"") | I47: =IF(AND($G47<>"",OR($AD47<>"",$AE47<>"")),MAX($AD47,$AE47),"") | J47: =IF($G47="", "", IF(COUNTIFS(Equipements_SCL!$M$16:$M$100, $G47, Equipements_SCL!$J$16:$J$100, J$37)=0, "", IF(SUMIFS(Equipements_SCL!$AV$16:$AV$100, Equipements_SCL!$M$16:$M$100, $G47, Equipements_SCL!$J$16:$J$100, J$37)=-1, "", SUMIFS(Equipements_SCL!$P$16:$P$100, Equipements_SCL!$M$16:$M$100, $G47, Equipements_SCL!$J$16:$J$100, J$37)))) | K47: =IF( $G47="", "", IF( SUMIFS(Analytique!$AD$3:$AD$20, Analytique!$Z$3:$Z$20, $G47, Analytique!$Y$3:$Y$20, "A1")=0, "", SUMIFS(Analytique!$AD$3:$AD$20, Analytique!$Z$3:$Z$20, $G47, Analytique!$Y$3:$Y$20, "A1") ) ) | AD47: =IF($G47="", "", IF(COUNTIFS(Equipements_SCL!$M$16:$M$100, $G47, Equipements_SCL!$J$16:$J$100, AD$37)=0, "", IF(SUMIFS(Equipements_SCL!$AV$16:$AV$100, Equipements_SCL!$M$16:$M$100, $G47, Equipements_SCL!$J$16:$J$100, AD$37)=-1, "", SUMIFS(Equipements_SCL!$P$16:$P$100, Equipements_SCL!$M$16:$M$100, $G47, Equipements_SCL!$J$16:$J$100, AD$37)))) | AE47: =IF($G47="", "", IF(COUNTIFS(Equipements_SCL!$M$16:$M$100, $G47, Equipements_SCL!$J$16:$J$100, AE$37)=0, "", IF(SUMIFS(Equipements_SCL!$AV$16:$AV$100, Equipements_SCL!$M$16:$M$100, $G47, Equipements_SCL!$J$16:$J$100, AE$37)=-1, "", SUMIFS(Equipements_SCL!$P$16:$P$100, Equipements_SCL!$M$16:$M$100, $G47, Equipements_SCL!$J$16:$J$100, AE$37))))
H48: =IF(AND($G48<>"",OR($I48<>"",$J48<>"",$K48<>"")),AVERAGE($I48,$J48,$K48),"") | I48: =IF(AND($G48<>"",OR($AD48<>"",$AE48<>"")),MAX($AD48,$AE48),"") | J48: =IF($G48="", "", IF(COUNTIFS(Equipements_SCL!$M$16:$M$100, $G48, Equipements_SCL!$J$16:$J$100, J$37)=0, "", IF(SUMIFS(Equipements_SCL!$AV$16:$AV$100, Equipements_SCL!$M$16:$M$100, $G48, Equipements_SCL!$J$16:$J$100, J$37)=-1, "", SUMIFS(Equipements_SCL!$P$16:$P$100, Equipements_SCL!$M$16:$M$100, $G48, Equipements_SCL!$J$16:$J$100, J$37)))) | K48: =IF( $G48="", "", IF( SUMIFS(Analytique!$AD$3:$AD$20, Analytique!$Z$3:$Z$20, $G48, Analytique!$Y$3:$Y$20, "A1")=0, "", SUMIFS(Analytique!$AD$3:$AD$20, Analytique!$Z$3:$Z$20, $G48, Analytique!$Y$3:$Y$20, "A1") ) ) | AD48: =IF($G48="", "", IF(COUNTIFS(Equipements_SCL!$M$16:$M$100, $G48, Equipements_SCL!$J$16:$J$100, AD$37)=0, "", IF(SUMIFS(Equipements_SCL!$AV$16:$AV$100, Equipements_SCL!$M$16:$M$100, $G48, Equipements_SCL!$J$16:$J$100, AD$37)=-1, "", SUMIFS(Equipements_SCL!$P$16:$P$100, Equipements_SCL!$M$16:$M$100, $G48, Equipements_SCL!$J$16:$J$100, AD$37)))) | AE48: =IF($G48="", "", IF(COUNTIFS(Equipements_SCL!$M$16:$M$100, $G48, Equipements_SCL!$J$16:$J$100, AE$37)=0, "", IF(SUMIFS(Equipements_SCL!$AV$16:$AV$100, Equipements_SCL!$M$16:$M$100, $G48, Equipements_SCL!$J$16:$J$100, AE$37)=-1, "", SUMIFS(Equipements_SCL!$P$16:$P$100, Equipements_SCL!$M$16:$M$100, $G48, Equipements_SCL!$J$16:$J$100, AE$37))))
