Workbook
Name Asservissement: PARAM!$A$44:$A$46
Name CODE_SANDRE_3: PARAM!$I$4:$I$19
Name CODE_SANDRE_SCL: PARAM!$F$4:$F$7
Name CODE_SANDRE_STEU: PARAM!$E$4:$E$19
Name conditions_meteo: PARAM!$F$44:$F$46
Name Conformité: PARAM!$B$44:$B$48
Name Eq_h_controle: PARAM!$C$30:$C$32
Name EQUIPEMENT_PREL: PARAM!$B$4:$B$6
Name EQUIPEMENT_Q: PARAM!$A$4:$A$15
Name Frequence: PARAM!$E$44:$E$51
Name LISTE_1: PARAM!$A$21:$A$23
Name LISTE_2: PARAM!$B$21:$B$24
Name LISTE_3: PARAM!$C$21:$C$25
Name LISTE_4: PARAM!$D$21:$D$27
Name LISTE_5: PARAM!$F$21:$F$25
Name LISTE_6: PARAM!$G$21
Name LISTE_7: PARAM!$H$21:$H$23
Name listeDebimetres: INDIRECT("Descriptif!"&ADDRESS(Descriptif!$AD$2,COLUMN(Descriptif!$AF$1))):INDEX(INDIRECT("Descriptif!AF"&Descriptif!$AD$2&":AF101"),COUNTIF(INDIRECT("Descriptif!AF"&Descriptif!$AD$2&":AF101"),"?*"))
Name listePluviometres: INDIRECT("Descriptif!"&ADDRESS(Descriptif!$AD$2,COLUMN(Descriptif!$AJ$1))):INDEX(INDIRECT("Descriptif!AJ"&Descriptif!$AD$2&":AJ101"),COUNTIF(INDIRECT("Descriptif!AJ"&Descriptif!$AD$2&":AJ101"),"?*"))
Name listePreleveurs: INDIRECT("Descriptif!"&ADDRESS(Descriptif!$AD$2,COLUMN(Descriptif!$AD$1))):INDEX(INDIRECT("Descriptif!AD"&Descriptif!$AD$2&":AD101"),COUNTIF(INDIRECT("Descriptif!AD"&Descriptif!$AD$2&":AD101"),"?*"))
Name listeSondeTemp: INDIRECT("Descriptif!"&ADDRESS(Descriptif!$AD$2,COLUMN(Descriptif!$AH$1))):INDEX(INDIRECT("Descriptif!AH"&Descriptif!$AD$2&":AH101"),COUNTIF(INDIRECT("Descriptif!AH"&Descriptif!$AD$2&":AH101"),"?*"))
Name Méthode: PARAM!$A$55:$A$57
Name Montage_sonde: PARAM!$G$44:$G$47
Name PLUVIO_SCL: Descriptif!$E$24:$E$24
Name Print_Area: LimitequantificationSDE!$A$1:$F$21
Name Print_Area: 'SeuilsComparaison-EMT'!$A$1:$K$29
Name Q_en_charge: PARAM!$A$30:$A$33
Name Q_en_charge_boues: PARAM!$E$30
Name Q_Gravitaire: PARAM!$B$30:$B$39
Name Satisfaction: PARAM!$D$44:$D$46
Name Type_capteur: PARAM!$C$44:$C$48
Name Type_equipement: PARAM!$C$4:$C$7
Name Type_reseau: PARAM!$D$30:$D$32
Name TypeDeMesure: PARAM!$B$55:$B$56

Sheet Descriptif
AC1: Ne rien mettre dans cette colonne | AD1: Ne rien mettre dans cette colonne | AE1: Ne rien mettre dans cette colonne | AF1: Ne rien mettre dans cette colonne | AG1: Ne rien mettre dans cette colonne | AH1: Ne rien mettre dans cette colonne | AI1: Ne rien mettre dans cette colonne | AJ1: Ne rien mettre dans cette colonne
C2: CONTRÔLE ANNUEL DES DISPOSITIFS D'AUTOSURVEILLANCE DES SYSTÈMES D'ASSAINISSEMENT COLLECTIF | AC2: début données sys collect | AD2: =ROW(E13)+1 -> 14 | AE2: fin données sys collect | AF2: =ROW(D15)-1 -> 14 | AG2: pluvio SCL | AH2: =ROW(E22)+1 -> 23 | AI2: =ROW(D24)-1 -> 23
C3: NOM DU SYSTÈME D'ASSAINISSEMENT : | I3: NOM DU SYSTÈME DE TRAITEMENT : | N3: NOM DU SYSTÈME DE COLLECTE : | S3: NOM DE L'ORGANISME DE CONTRÔLE : | AC3: début données station | AD3: =ROW(E33)+1 -> 34 | AE3: fin données station | AF3: =ROW(D35)-1 -> 34 | AG3: pluvio STEU | AH3: =ROW(E42)+1 -> 43 | AI3: =ROW(D44)-1 -> 43
C4: CODE SANDRE DE L'AGGLOMÉRATION : | I4: CODE SANDRE DE LA STATION : | N4: CODE SANDRE DU RÉSEAU : | S4: NOM(S) DU(ES) CONTROLEUR(S) :
C5: MAITRE D'OUVRAGE DE LA STATION : | I5: TYPE DE TRAITEMENT : | N5: TYPE DE RÉSEAU : | S5: DATE(S) D'INTERVENTION :
C6: EXPLOITANT DE LA STATION : | I6: CAPACITÉ DE LA STATION : | N6: EXPLOITANT DU RÉSEAU : | S6: CONDITION(S) MÉTÉO :
C8: SYSTÈME DE COLLECTE
D9: Remarques: | E9: Les estimations et les apports par camion ne rentrent pas dans le CDA
D10: Liste des équipements du système de collecte pour chaque point d’autosurveillance
H12: Les informations de codification sont à reprendre du MAS
E13: Actif | F13: Lien vers l'onglet de l'équipement | H13: Point réglementaire | I13: Localisation (cf. MAS) | J13: Code du point (cf MAS) | K13: Libellé de l'équipement | M13: Type d'équipement | O13: Type de matériel | Q13: Pluviométre de référence | S13: Certaines informations d'un équipement ne sont pas modifiables. Au besoin il est préférable de supprimer et de recréer l'équipement. | AC13: Liste préleveurs | AE13: Liste débimètres | AG13: Liste thermo | AI13: Liste pluvio
AB14: =ROW(A14)- $AD$2 +1 -> 1 | AC14: =IF(AND($E14="Oui",$M14="Préleveur"),$F14,"") | AD14: {=IFERROR(INDEX($AC$14:$AC$99,SMALL(IF($AC$14:$AC$99<>"",ROW($AC$14:$AC$99)-ROW(INDIRECT("$AC$14"))+1),ROW(INDIRECT("A" & AB14 ) ))),"")} | AE14: =IF(AND($E14="Oui",LEFT($M14,10) ="Débitmètre"),$F14,"") | AF14: {=IFERROR(INDEX($AE$14:$AE$99,SMALL(IF($AE$14:$AE$99<>"",ROW($AE$14:$AE$99)-ROW(INDIRECT("$AE$14"))+1),ROW(INDIRECT("A" & AB14 ) ))),"")} | AG14: =IF(AND($E14="Oui",LEFT($M14,5) ="Sonde"),$F14,"") | AH14: {=IFERROR(INDEX($AG$14:$AG$99,SMALL(IF($AG$14:$AG$99<>"",ROW($AG$14:$AG$99)-ROW(INDIRECT("$AG$14"))+1),ROW(INDIRECT("A" & AB14 ) ))),"")} | AI14: =IF(AND($E14="Oui", $F14 <> "", $M14 = ""),$F14,"") | AJ14: {=IFERROR(INDEX($AI$14:$AI$99,SMALL(IF($AI$14:$AI$99<>"",ROW($AI$14:$AI$99)-ROW(INDIRECT("$AI$14"))+1),ROW(INDIRECT("A" & AB14 ) ))),"")}
E15: Ajouter un équipement réseau | K15: Si certains points ne sont pas équipés, veuillez les indiquer en commentaire : | AB15: =ROW(A15)- $AD$2 +1 -> 2 | AC15: =IF(AND($E15="Oui",$M15="Préleveur"),$F15,"") | AD15: {=IFERROR(INDEX($AC$14:$AC$99,SMALL(IF($AC$14:$AC$99<>"",ROW($AC$14:$AC$99)-ROW(INDIRECT("$AC$14"))+1),ROW(INDIRECT("A" & AB15 ) ))),"")} | AE15: =IF(AND($E15="Oui",LEFT($M15,10) ="Débitmètre"),$F15,"") | AF15: {=IFERROR(INDEX($AE$14:$AE$99,SMALL(IF($AE$14:$AE$99<>"",ROW($AE$14:$AE$99)-ROW(INDIRECT("$AE$14"))+1),ROW(INDIRECT("A" & AB15 ) ))),"")} | AG15: =IF(AND($E15="Oui",LEFT($M15,5) ="Sonde"),$F15,"") | AH15: {=IFERROR(INDEX($AG$14:$AG$99,SMALL(IF($AG$14:$AG$99<>"",ROW($AG$14:$AG$99)-ROW(INDIRECT("$AG$14"))+1),ROW(INDIRECT("A" & AB15 ) ))),"")} | AI15: =IF(AND($E15="Oui", $F15 <> "", $M15 = ""),$F15,"") | AJ15: {=IFERROR(INDEX($AI$14:$AI$99,SMALL(IF($AI$14:$AI$99<>"",ROW($AI$14:$AI$99)-ROW(INDIRECT("$AI$14"))+1),ROW(INDIRECT("A" & AB15 ) ))),"")}
AB16: =ROW(A16)- $AD$2 +1 -> 3 | AC16: =IF(AND($E16="Oui",$M16="Préleveur"),$F16,"") | AD16: {=IFERROR(INDEX($AC$14:$AC$99,SMALL(IF($AC$14:$AC$99<>"",ROW($AC$14:$AC$99)-ROW(INDIRECT("$AC$14"))+1),ROW(INDIRECT("A" & AB16 ) ))),"")} | AE16: =IF(AND($E16="Oui",LEFT($M16,10) ="Débitmètre"),$F16,"") | AF16: {=IFERROR(INDEX($AE$14:$AE$99,SMALL(IF($AE$14:$AE$99<>"",ROW($AE$14:$AE$99)-ROW(INDIRECT("$AE$14"))+1),ROW(INDIRECT("A" & AB16 ) ))),"")} | AG16: =IF(AND($E16="Oui",LEFT($M16,5) ="Sonde"),$F16,"") | AH16: {=IFERROR(INDEX($AG$14:$AG$99,SMALL(IF($AG$14:$AG$99<>"",ROW($AG$14:$AG$99)-ROW(INDIRECT("$AG$14"))+1),ROW(INDIRECT("A" & AB16 ) ))),"")} | AI16: =IF(AND($E16="Oui", $F16 <> "", $M16 = ""),$F16,"") | AJ16: {=IFERROR(INDEX($AI$14:$AI$99,SMALL(IF($AI$14:$AI$99<>"",ROW($AI$14:$AI$99)-ROW(INDIRECT("$AI$14"))+1),ROW(INDIRECT("A" & AB16 ) ))),"")}
AB17: =ROW(A17)- $AD$2 +1 -> 4 | AC17: =IF(AND($E17="Oui",$M17="Préleveur"),$F17,"") | AD17: {=IFERROR(INDEX($AC$14:$AC$99,SMALL(IF($AC$14:$AC$99<>"",ROW($AC$14:$AC$99)-ROW(INDIRECT("$AC$14"))+1),ROW(INDIRECT("A" & AB17 ) ))),"")} | AE17: =IF(AND($E17="Oui",LEFT($M17,10) ="Débitmètre"),$F17,"") | AF17: {=IFERROR(INDEX($AE$14:$AE$99,SMALL(IF($AE$14:$AE$99<>"",ROW($AE$14:$AE$99)-ROW(INDIRECT("$AE$14"))+1),ROW(INDIRECT("A" & AB17 ) ))),"")} | AG17: =IF(AND($E17="Oui",LEFT($M17,5) ="Sonde"),$F17,"") | AH17: {=IFERROR(INDEX($AG$14:$AG$99,SMALL(IF($AG$14:$AG$99<>"",ROW($AG$14:$AG$99)-ROW(INDIRECT("$AG$14"))+1),ROW(INDIRECT("A" & AB17 ) ))),"")} | AI17: =IF(AND($E17="Oui", $F17 <> "", $M17 = ""),$F17,"") | AJ17: {=IFERROR(INDEX($AI$14:$AI$99,SMALL(IF($AI$14:$AI$99<>"",ROW($AI$14:$AI$99)-ROW(INDIRECT("$AI$14"))+1),ROW(INDIRECT("A" & AB17 ) ))),"")}
AB18: =ROW(A18)- $AD$2 +1 -> 5 | AC18: =IF(AND($E18="Oui",$M18="Préleveur"),$F18,"") | AD18: {=IFERROR(INDEX($AC$14:$AC$99,SMALL(IF($AC$14:$AC$99<>"",ROW($AC$14:$AC$99)-ROW(INDIRECT("$AC$14"))+1),ROW(INDIRECT("A" & AB18 ) ))),"")} | AE18: =IF(AND($E18="Oui",LEFT($M18,10) ="Débitmètre"),$F18,"") | AF18: {=IFERROR(INDEX($AE$14:$AE$99,SMALL(IF($AE$14:$AE$99<>"",ROW($AE$14:$AE$99)-ROW(INDIRECT("$AE$14"))+1),ROW(INDIRECT("A" & AB18 ) ))),"")} | AG18: =IF(AND($E18="Oui",LEFT($M18,5) ="Sonde"),$F18,"") | AH18: {=IFERROR(INDEX($AG$14:$AG$99,SMALL(IF($AG$14:$AG$99<>"",ROW($AG$14:$AG$99)-ROW(INDIRECT("$AG$14"))+1),ROW(INDIRECT("A" & AB18 ) ))),"")} | AI18: =IF(AND($E18="Oui", $F18 <> "", $M18 = ""),$F18,"") | AJ18: {=IFERROR(INDEX($AI$14:$AI$99,SMALL(IF($AI$14:$AI$99<>"",ROW($AI$14:$AI$99)-ROW(INDIRECT("$AI$14"))+1),ROW(INDIRECT("A" & AB18 ) ))),"")}
AB19: =ROW(A19)- $AD$2 +1 -> 6 | AC19: =IF(AND($E19="Oui",$M19="Préleveur"),$F19,"") | AD19: {=IFERROR(INDEX($AC$14:$AC$99,SMALL(IF($AC$14:$AC$99<>"",ROW($AC$14:$AC$99)-ROW(INDIRECT("$AC$14"))+1),ROW(INDIRECT("A" & AB19 ) ))),"")} | AE19: =IF(AND($E19="Oui",LEFT($M19,10) ="Débitmètre"),$F19,"") | AF19: {=IFERROR(INDEX($AE$14:$AE$99,SMALL(IF($AE$14:$AE$99<>"",ROW($AE$14:$AE$99)-ROW(INDIRECT("$AE$14"))+1),ROW(INDIRECT("A" & AB19 ) ))),"")} | AG19: =IF(AND($E19="Oui",LEFT($M19,5) ="Sonde"),$F19,"") | AH19: {=IFERROR(INDEX($AG$14:$AG$99,SMALL(IF($AG$14:$AG$99<>"",ROW($AG$14:$AG$99)-ROW(INDIRECT("$AG$14"))+1),ROW(INDIRECT("A" & AB19 ) ))),"")} | AI19: =IF(AND($E19="Oui", $F19 <> "", $M19 = ""),$F19,"") | AJ19: {=IFERROR(INDEX($AI$14:$AI$99,SMALL(IF($AI$14:$AI$99<>"",ROW($AI$14:$AI$99)-ROW(INDIRECT("$AI$14"))+1),ROW(INDIRECT("A" & AB19 ) ))),"")}
D20: Liste des pluviomètres de référence du réseau | AB20: =ROW(A20)- $AD$2 +1 -> 7 | AC20: =IF(AND($E20="Oui",$M20="Préleveur"),$F20,"") | AD20: {=IFERROR(INDEX($AC$14:$AC$99,SMALL(IF($AC$14:$AC$99<>"",ROW($AC$14:$AC$99)-ROW(INDIRECT("$AC$14"))+1),ROW(INDIRECT("A" & AB20 ) ))),"")} | AE20: =IF(AND($E20="Oui",LEFT($M20,10) ="Débitmètre"),$F20,"") | AF20: {=IFERROR(INDEX($AE$14:$AE$99,SMALL(IF($AE$14:$AE$99<>"",ROW($AE$14:$AE$99)-ROW(INDIRECT("$AE$14"))+1),ROW(INDIRECT("A" & AB20 ) ))),"")} | AG20: =IF(AND($E20="Oui",LEFT($M20,5) ="Sonde"),$F20,"") | AH20: {=IFERROR(INDEX($AG$14:$AG$99,SMALL(IF($AG$14:$AG$99<>"",ROW($AG$14:$AG$99)-ROW(INDIRECT("$AG$14"))+1),ROW(INDIRECT("A" & AB20 ) ))),"")} | AI20: =IF(AND($E20="Oui", $F20 <> "", $M20 = ""),$F20,"") | AJ20: {=IFERROR(INDEX($AI$14:$AI$99,SMALL(IF($AI$14:$AI$99<>"",ROW($AI$14:$AI$99)-ROW(INDIRECT("$AI$14"))+1),ROW(INDIRECT("A" & AB20 ) ))),"")}
AB21: =ROW(A21)- $AD$2 +1 -> 8 | AC21: =IF(AND($E21="Oui",$M21="Préleveur"),$F21,"") | AD21: {=IFERROR(INDEX($AC$14:$AC$99,SMALL(IF($AC$14:$AC$99<>"",ROW($AC$14:$AC$99)-ROW(INDIRECT("$AC$14"))+1),ROW(INDIRECT("A" & AB21 ) ))),"")} | AE21: =IF(AND($E21="Oui",LEFT($M21,10) ="Débitmètre"),$F21,"") | AF21: {=IFERROR(INDEX($AE$14:$AE$99,SMALL(IF($AE$14:$AE$99<>"",ROW($AE$14:$AE$99)-ROW(INDIRECT("$AE$14"))+1),ROW(INDIRECT("A" & AB21 ) ))),"")} | AG21: =IF(AND($E21="Oui",LEFT($M21,5) ="Sonde"),$F21,"") | AH21: {=IFERROR(INDEX($AG$14:$AG$99,SMALL(IF($AG$14:$AG$99<>"",ROW($AG$14:$AG$99)-ROW(INDIRECT("$AG$14"))+1),ROW(INDIRECT("A" & AB21 ) ))),"")} | AI21: =IF(AND($E21="Oui", $F21 <> "", $M21 = ""),$F21,"") | AJ21: {=IFERROR(INDEX($AI$14:$AI$99,SMALL(IF($AI$14:$AI$99<>"",ROW($AI$14:$AI$99)-ROW(INDIRECT("$AI$14"))+1),ROW(INDIRECT("A" & AB21 ) ))),"")}
E22: Actif | F22: Lien vers l'onglet de l'équipement | AB22: =ROW(A22)- $AD$2 +1 -> 9 | AC22: =IF(AND($E22="Oui",$M22="Préleveur"),$F22,"") | AD22: {=IFERROR(INDEX($AC$14:$AC$99,SMALL(IF($AC$14:$AC$99<>"",ROW($AC$14:$AC$99)-ROW(INDIRECT("$AC$14"))+1),ROW(INDIRECT("A" & AB22 ) ))),"")} | AE22: =IF(AND($E22="Oui",LEFT($M22,10) ="Débitmètre"),$F22,"") | AF22: {=IFERROR(INDEX($AE$14:$AE$99,SMALL(IF($AE$14:$AE$99<>"",ROW($AE$14:$AE$99)-ROW(INDIRECT("$AE$14"))+1),ROW(INDIRECT("A" & AB22 ) ))),"")} | AG22: =IF(AND($E22="Oui",LEFT($M22,5) ="Sonde"),$F22,"") | AH22: {=IFERROR(INDEX($AG$14:$AG$99,SMALL(IF($AG$14:$AG$99<>"",ROW($AG$14:$AG$99)-ROW(INDIRECT("$AG$14"))+1),ROW(INDIRECT("A" & AB22 ) ))),"")} | AI22: =IF(AND($E22="Oui", $F22 <> "", $M22 = ""),$F22,"") | AJ22: {=IFERROR(INDEX($AI$14:$AI$99,SMALL(IF($AI$14:$AI$99<>"",ROW($AI$14:$AI$99)-ROW(INDIRECT("$AI$14"))+1),ROW(INDIRECT("A" & AB22 ) ))),"")}
AB23: =ROW(A23)- $AD$2 +1 -> 10 | AC23: =IF(AND($E23="Oui",$M23="Préleveur"),$F23,"") | AD23: {=IFERROR(INDEX($AC$14:$AC$99,SMALL(IF($AC$14:$AC$99<>"",ROW($AC$14:$AC$99)-ROW(INDIRECT("$AC$14"))+1),ROW(INDIRECT("A" & AB23 ) ))),"")} | AE23: =IF(AND($E23="Oui",LEFT($M23,10) ="Débitmètre"),$F23,"") | AF23: {=IFERROR(INDEX($AE$14:$AE$99,SMALL(IF($AE$14:$AE$99<>"",ROW($AE$14:$AE$99)-ROW(INDIRECT("$AE$14"))+1),ROW(INDIRECT("A" & AB23 ) ))),"")} | AG23: =IF(AND($E23="Oui",LEFT($M23,5) ="Sonde"),$F23,"") | AH23: {=IFERROR(INDEX($AG$14:$AG$99,SMALL(IF($AG$14:$AG$99<>"",ROW($AG$14:$AG$99)-ROW(INDIRECT("$AG$14"))+1),ROW(INDIRECT("A" & AB23 ) ))),"")} | AI23: =IF(AND($E23="Oui", $F23 <> "", $M23 = ""),$F23,"") | AJ23: {=IFERROR(INDEX($AI$14:$AI$99,SMALL(IF($AI$14:$AI$99<>"",ROW($AI$14:$AI$99)-ROW(INDIRECT("$AI$14"))+1),ROW(INDIRECT("A" & AB23 ) ))),"")}
E24: Ajouter un pluviomètre réseau | K24: Si pas de pluviomètre, veuillez ajouter en commentaire la provenance des données : | AB24: =ROW(A24)- $AD$2 +1 -> 11 | AC24: =IF(AND($E24="Oui",$M24="Préleveur"),$F24,"") | AD24: {=IFERROR(INDEX($AC$14:$AC$99,SMALL(IF($AC$14:$AC$99<>"",ROW($AC$14:$AC$99)-ROW(INDIRECT("$AC$14"))+1),ROW(INDIRECT("A" & AB24 ) ))),"")} | AE24: =IF(AND($E24="Oui",LEFT($M24,10) ="Débitmètre"),$F24,"") | AF24: {=IFERROR(INDEX($AE$14:$AE$99,SMALL(IF($AE$14:$AE$99<>"",ROW($AE$14:$AE$99)-ROW(INDIRECT("$AE$14"))+1),ROW(INDIRECT("A" & AB24 ) ))),"")} | AG24: =IF(AND($E24="Oui",LEFT($M24,5) ="Sonde"),$F24,"") | AH24: {=IFERROR(INDEX($AG$14:$AG$99,SMALL(IF($AG$14:$AG$99<>"",ROW($AG$14:$AG$99)-ROW(INDIRECT("$AG$14"))+1),ROW(INDIRECT("A" & AB24 ) ))),"")} | AI24: =IF(AND($E24="Oui", $F24 <> "", $M24 = ""),$F24,"") | AJ24: {=IFERROR(INDEX($AI$14:$AI$99,SMALL(IF($AI$14:$AI$99<>"",ROW($AI$14:$AI$99)-ROW(INDIRECT("$AI$14"))+1),ROW(INDIRECT("A" & AB24 ) ))),"")}
AB25: =ROW(A25)- $AD$2 +1 -> 12 | AC25: =IF(AND($E25="Oui",$M25="Préleveur"),$F25,"") | AD25: {=IFERROR(INDEX($AC$14:$AC$99,SMALL(IF($AC$14:$AC$99<>"",ROW($AC$14:$AC$99)-ROW(INDIRECT("$AC$14"))+1),ROW(INDIRECT("A" & AB25 ) ))),"")} | AE25: =IF(AND($E25="Oui",LEFT($M25,10) ="Débitmètre"),$F25,"") | AF25: {=IFERROR(INDEX($AE$14:$AE$99,SMALL(IF($AE$14:$AE$99<>"",ROW($AE$14:$AE$99)-ROW(INDIRECT("$AE$14"))+1),ROW(INDIRECT("A" & AB25 ) ))),"")} | AG25: =IF(AND($E25="Oui",LEFT($M25,5) ="Sonde"),$F25,"") | AH25: {=IFERROR(INDEX($AG$14:$AG$99,SMALL(IF($AG$14:$AG$99<>"",ROW($AG$14:$AG$99)-ROW(INDIRECT("$AG$14"))+1),ROW(INDIRECT("A" & AB25 ) ))),"")} | AI25: =IF(AND($E25="Oui", $F25 <> "", $M25 = ""),$F25,"") | AJ25: {=IFERROR(INDEX($AI$14:$AI$99,SMALL(IF($AI$14:$AI$99<>"",ROW($AI$14:$AI$99)-ROW(INDIRECT("$AI$14"))+1),ROW(INDIRECT("A" & AB25 ) ))),"")}
AB26: =ROW(A26)- $AD$2 +1 -> 13 | AC26: =IF(AND($E26="Oui",$M26="Préleveur"),$F26,"") | AD26: {=IFERROR(INDEX($AC$14:$AC$99,SMALL(IF($AC$14:$AC$99<>"",ROW($AC$14:$AC$99)-ROW(INDIRECT("$AC$14"))+1),ROW(INDIRECT("A" & AB26 ) ))),"")} | AE26: =IF(AND($E26="Oui",LEFT($M26,10) ="Débitmètre"),$F26,"") | AF26: {=IFERROR(INDEX($AE$14:$AE$99,SMALL(IF($AE$14:$AE$99<>"",ROW($AE$14:$AE$99)-ROW(INDIRECT("$AE$14"))+1),ROW(INDIRECT("A" & AB26 ) ))),"")} | AG26: =IF(AND($E26="Oui",LEFT($M26,5) ="Sonde"),$F26,"") | AH26: {=IFERROR(INDEX($AG$14:$AG$99,SMALL(IF($AG$14:$AG$99<>"",ROW($AG$14:$AG$99)-ROW(INDIRECT("$AG$14"))+1),ROW(INDIRECT("A" & AB26 ) ))),"")} | AI26: =IF(AND($E26="Oui", $F26 <> "", $M26 = ""),$F26,"") | AJ26: {=IFERROR(INDEX($AI$14:$AI$99,SMALL(IF($AI$14:$AI$99<>"",ROW($AI$14:$AI$99)-ROW(INDIRECT("$AI$14"))+1),ROW(INDIRECT("A" & AB26 ) ))),"")}
AB27: =ROW(A27)- $AD$2 +1 -> 14 | AC27: =IF(AND($E27="Oui",$M27="Préleveur"),$F27,"") | AD27: {=IFERROR(INDEX($AC$14:$AC$99,SMALL(IF($AC$14:$AC$99<>"",ROW($AC$14:$AC$99)-ROW(INDIRECT("$AC$14"))+1),ROW(INDIRECT("A" & AB27 ) ))),"")} | AE27: =IF(AND($E27="Oui",LEFT($M27,10) ="Débitmètre"),$F27,"") | AF27: {=IFERROR(INDEX($AE$14:$AE$99,SMALL(IF($AE$14:$AE$99<>"",ROW($AE$14:$AE$99)-ROW(INDIRECT("$AE$14"))+1),ROW(INDIRECT("A" & AB27 ) ))),"")} | AG27: =IF(AND($E27="Oui",LEFT($M27,5) ="Sonde"),$F27,"") | AH27: {=IFERROR(INDEX($AG$14:$AG$99,SMALL(IF($AG$14:$AG$99<>"",ROW($AG$14:$AG$99)-ROW(INDIRECT("$AG$14"))+1),ROW(INDIRECT("A" & AB27 ) ))),"")} | AI27: =IF(AND($E27="Oui", $F27 <> "", $M27 = ""),$F27,"") | AJ27: {=IFERROR(INDEX($AI$14:$AI$99,SMALL(IF($AI$14:$AI$99<>"",ROW($AI$14:$AI$99)-ROW(INDIRECT("$AI$14"))+1),ROW(INDIRECT("A" & AB27 ) ))),"")}
AB28: =ROW(A28)- $AD$2 +1 -> 15 | AC28: =IF(AND($E28="Oui",$M28="Préleveur"),$F28,"") | AD28: {=IFERROR(INDEX($AC$14:$AC$99,SMALL(IF($AC$14:$AC$99<>"",ROW($AC$14:$AC$99)-ROW(INDIRECT("$AC$14"))+1),ROW(INDIRECT("A" & AB28 ) ))),"")} | AE28: =IF(AND($E28="Oui",LEFT($M28,10) ="Débitmètre"),$F28,"") | AF28: {=IFERROR(INDEX($AE$14:$AE$99,SMALL(IF($AE$14:$AE$99<>"",ROW($AE$14:$AE$99)-ROW(INDIRECT("$AE$14"))+1),ROW(INDIRECT("A" & AB28 ) ))),"")} | AG28: =IF(AND($E28="Oui",LEFT($M28,5) ="Sonde"),$F28,"") | AH28: {=IFERROR(INDEX($AG$14:$AG$99,SMALL(IF($AG$14:$AG$99<>"",ROW($AG$14:$AG$99)-ROW(INDIRECT("$AG$14"))+1),ROW(INDIRECT("A" & AB28 ) ))),"")} | AI28: =IF(AND($E28="Oui", $F28 <> "", $M28 = ""),$F28,"") | AJ28: {=IFERROR(INDEX($AI$14:$AI$99,SMALL(IF($AI$14:$AI$99<>"",ROW($AI$14:$AI$99)-ROW(INDIRECT("$AI$14"))+1),ROW(INDIRECT("A" & AB28 ) ))),"")}
C29: SYSTÈME DE TRAITEMENT | AB29: =ROW(A29)- $AD$2 +1 -> 16 | AC29: =IF(AND($E29="Oui",$M29="Préleveur"),$F29,"") | AD29: {=IFERROR(INDEX($AC$14:$AC$99,SMALL(IF($AC$14:$AC$99<>"",ROW($AC$14:$AC$99)-ROW(INDIRECT("$AC$14"))+1),ROW(INDIRECT("A" & AB29 ) ))),"")} | AE29: =IF(AND($E29="Oui",LEFT($M29,10) ="Débitmètre"),$F29,"") | AF29: {=IFERROR(INDEX($AE$14:$AE$99,SMALL(IF($AE$14:$AE$99<>"",ROW($AE$14:$AE$99)-ROW(INDIRECT("$AE$14"))+1),ROW(INDIRECT("A" & AB29 ) ))),"")} | AG29: =IF(AND($E29="Oui",LEFT($M29,5) ="Sonde"),$F29,"") | AH29: {=IFERROR(INDEX($AG$14:$AG$99,SMALL(IF($AG$14:$AG$99<>"",ROW($AG$14:$AG$99)-ROW(INDIRECT("$AG$14"))+1),ROW(INDIRECT("A" & AB29 ) ))),"")} | AI29: =IF(AND($E29="Oui", $F29 <> "", $M29 = ""),$F29,"") | AJ29: {=IFERROR(INDEX($AI$14:$AI$99,SMALL(IF($AI$14:$AI$99<>"",ROW($AI$14:$AI$99)-ROW(INDIRECT("$AI$14"))+1),ROW(INDIRECT("A" & AB29 ) ))),"")}
D30: Remarques: | E30: Les estimations et les apports par camion ne rentrent pas dans le CDA | AB30: =ROW(A30)- $AD$2 +1 -> 17 | AC30: =IF(AND($E30="Oui",$M30="Préleveur"),$F30,"") | AD30: {=IFERROR(INDEX($AC$14:$AC$99,SMALL(IF($AC$14:$AC$99<>"",ROW($AC$14:$AC$99)-ROW(INDIRECT("$AC$14"))+1),ROW(INDIRECT("A" & AB30 ) ))),"")} | AE30: =IF(AND($E30="Oui",LEFT($M30,10) ="Débitmètre"),$F30,"") | AF30: {=IFERROR(INDEX($AE$14:$AE$99,SMALL(IF($AE$14:$AE$99<>"",ROW($AE$14:$AE$99)-ROW(INDIRECT("$AE$14"))+1),ROW(INDIRECT("A" & AB30 ) ))),"")} | AG30: =IF(AND($E30="Oui",LEFT($M30,5) ="Sonde"),$F30,"") | AH30: {=IFERROR(INDEX($AG$14:$AG$99,SMALL(IF($AG$14:$AG$99<>"",ROW($AG$14:$AG$99)-ROW(INDIRECT("$AG$14"))+1),ROW(INDIRECT("A" & AB30 ) ))),"")} | AI30: =IF(AND($E30="Oui", $F30 <> "", $M30 = ""),$F30,"") | AJ30: {=IFERROR(INDEX($AI$14:$AI$99,SMALL(IF($AI$14:$AI$99<>"",ROW($AI$14:$AI$99)-ROW(INDIRECT("$AI$14"))+1),ROW(INDIRECT("A" & AB30 ) ))),"")}
D31: Liste des équipements du système de traitement pour chaque point d’autosurveillance | AB31: =ROW(A31)- $AD$2 +1 -> 18 | AC31: =IF(AND($E31="Oui",$M31="Préleveur"),$F31,"") | AD31: {=IFERROR(INDEX($AC$14:$AC$99,SMALL(IF($AC$14:$AC$99<>"",ROW($AC$14:$AC$99)-ROW(INDIRECT("$AC$14"))+1),ROW(INDIRECT("A" & AB31 ) ))),"")} | AE31: =IF(AND($E31="Oui",LEFT($M31,10) ="Débitmètre"),$F31,"") | AF31: {=IFERROR(INDEX($AE$14:$AE$99,SMALL(IF($AE$14:$AE$99<>"",ROW($AE$14:$AE$99)-ROW(INDIRECT("$AE$14"))+1),ROW(INDIRECT("A" & AB31 ) ))),"")} | AG31: =IF(AND($E31="Oui",LEFT($M31,5) ="Sonde"),$F31,"") | AH31: {=IFERROR(INDEX($AG$14:$AG$99,SMALL(IF($AG$14:$AG$99<>"",ROW($AG$14:$AG$99)-ROW(INDIRECT("$AG$14"))+1),ROW(INDIRECT("A" & AB31 ) ))),"")} | AI31: =IF(AND($E31="Oui", $F31 <> "", $M31 = ""),$F31,"") | AJ31: {=IFERROR(INDEX($AI$14:$AI$99,SMALL(IF($AI$14:$AI$99<>"",ROW($AI$14:$AI$99)-ROW(INDIRECT("$AI$14"))+1),ROW(INDIRECT("A" & AB31 ) ))),"")}
AB32: =ROW(A32)- $AD$2 +1 -> 19 | AC32: =IF(AND($E32="Oui",$M32="Préleveur"),$F32,"") | AD32: {=IFERROR(INDEX($AC$14:$AC$99,SMALL(IF($AC$14:$AC$99<>"",ROW($AC$14:$AC$99)-ROW(INDIRECT("$AC$14"))+1),ROW(INDIRECT("A" & AB32 ) ))),"")} | AE32: =IF(AND($E32="Oui",LEFT($M32,10) ="Débitmètre"),$F32,"") | AF32: {=IFERROR(INDEX($AE$14:$AE$99,SMALL(IF($AE$14:$AE$99<>"",ROW($AE$14:$AE$99)-ROW(INDIRECT("$AE$14"))+1),ROW(INDIRECT("A" & AB32 ) ))),"")} | AG32: =IF(AND($E32="Oui",LEFT($M32,5) ="Sonde"),$F32,"") | AH32: {=IFERROR(INDEX($AG$14:$AG$99,SMALL(IF($AG$14:$AG$99<>"",ROW($AG$14:$AG$99)-ROW(INDIRECT("$AG$14"))+1),ROW(INDIRECT("A" & AB32 ) ))),"")} | AI32: =IF(AND($E32="Oui", $F32 <> "", $M32 = ""),$F32,"") | AJ32: {=IFERROR(INDEX($AI$14:$AI$99,SMALL(IF($AI$14:$AI$99<>"",ROW($AI$14:$AI$99)-ROW(INDIRECT("$AI$14"))+1),ROW(INDIRECT("A" & AB32 ) ))),"")}
E33: Actif | F33: Lien vers l'onglet de l'équipement | H33: Point réglementaire | I33: Localisation (cf. MAS) | J33: Code du point (cf MAS) | K33: Libellé de l'équipement | M33: Type d'équipement | O33: Type de matériel | R33: Certaines informations d'un équipement ne sont pas modifiables. Au besoin il est préférable de supprimer et de recréer l'équipement. | AB33: =ROW(A33)- $AD$2 +1 -> 20 | AC33: =IF(AND($E33="Oui",$M33="Préleveur"),$F33,"") | AD33: {=IFERROR(INDEX($AC$14:$AC$99,SMALL(IF($AC$14:$AC$99<>"",ROW($AC$14:$AC$99)-ROW(INDIRECT("$AC$14"))+1),ROW(INDIRECT("A" & AB33 ) ))),"")} | AE33: =IF(AND($E33="Oui",LEFT($M33,10) ="Débitmètre"),$F33,"") | AF33: {=IFERROR(INDEX($AE$14:$AE$99,SMALL(IF($AE$14:$AE$99<>"",ROW($AE$14:$AE$99)-ROW(INDIRECT("$AE$14"))+1),ROW(INDIRECT("A" & AB33 ) ))),"")} | AG33: =IF(AND($E33="Oui",LEFT($M33,5) ="Sonde"),$F33,"") | AH33: {=IFERROR(INDEX($AG$14:$AG$99,SMALL(IF($AG$14:$AG$99<>"",ROW($AG$14:$AG$99)-ROW(INDIRECT("$AG$14"))+1),ROW(INDIRECT("A" & AB33 ) ))),"")} | AI33: =IF(AND($E33="Oui", $F33 <> "", $M33 = ""),$F33,"") | AJ33: {=IFERROR(INDEX($AI$14:$AI$99,SMALL(IF($AI$14:$AI$99<>"",ROW($AI$14:$AI$99)-ROW(INDIRECT("$AI$14"))+1),ROW(INDIRECT("A" & AB33 ) ))),"")}
AB34: =ROW(A34)- $AD$2 +1 -> 21 | AC34: =IF(AND($E34="Oui",$M34="Préleveur"),$F34,"") | AD34: {=IFERROR(INDEX($AC$14:$AC$99,SMALL(IF($AC$14:$AC$99<>"",ROW($AC$14:$AC$99)-ROW(INDIRECT("$AC$14"))+1),ROW(INDIRECT("A" & AB34 ) ))),"")} | AE34: =IF(AND($E34="Oui",LEFT($M34,10) ="Débitmètre"),$F34,"") | AF34: {=IFERROR(INDEX($AE$14:$AE$99,SMALL(IF($AE$14:$AE$99<>"",ROW($AE$14:$AE$99)-ROW(INDIRECT("$AE$14"))+1),ROW(INDIRECT("A" & AB34 ) ))),"")} | AG34: =IF(AND($E34="Oui",LEFT($M34,5) ="Sonde"),$F34,"") | AH34: {=IFERROR(INDEX($AG$14:$AG$99,SMALL(IF($AG$14:$AG$99<>"",ROW($AG$14:$AG$99)-ROW(INDIRECT("$AG$14"))+1),ROW(INDIRECT("A" & AB34 ) ))),"")} | AI34: =IF(AND($E34="Oui", $F34 <> "", $M34 = ""),$F34,"") | AJ34: {=IFERROR(INDEX($AI$14:$AI$99,SMALL(IF($AI$14:$AI$99<>"",ROW($AI$14:$AI$99)-ROW(INDIRECT("$AI$14"))+1),ROW(INDIRECT("A" & AB34 ) ))),"")}
E35: Ajouter un équipement station | K35: Si certains points ne sont pas équipés, veuillez les indiquer en commentaire : | AB35: =ROW(A35)- $AD$2 +1 -> 22 | AC35: =IF(AND($E35="Oui",$M35="Préleveur"),$F35,"") | AD35: {=IFERROR(INDEX($AC$14:$AC$99,SMALL(IF($AC$14:$AC$99<>"",ROW($AC$14:$AC$99)-ROW(INDIRECT("$AC$14"))+1),ROW(INDIRECT("A" & AB35 ) ))),"")} | AE35: =IF(AND($E35="Oui",LEFT($M35,10) ="Débitmètre"),$F35,"") | AF35: {=IFERROR(INDEX($AE$14:$AE$99,SMALL(IF($AE$14:$AE$99<>"",ROW($AE$14:$AE$99)-ROW(INDIRECT("$AE$14"))+1),ROW(INDIRECT("A" & AB35 ) ))),"")} | AG35: =IF(AND($E35="Oui",LEFT($M35,5) ="Sonde"),$F35,"") | AH35: {=IFERROR(INDEX($AG$14:$AG$99,SMALL(IF($AG$14:$AG$99<>"",ROW($AG$14:$AG$99)-ROW(INDIRECT("$AG$14"))+1),ROW(INDIRECT("A" & AB35 ) ))),"")} | AI35: =IF(AND($E35="Oui", $F35 <> "", $M35 = ""),$F35,"") | AJ35: {=IFERROR(INDEX($AI$14:$AI$99,SMALL(IF($AI$14:$AI$99<>"",ROW($AI$14:$AI$99)-ROW(INDIRECT("$AI$14"))+1),ROW(INDIRECT("A" & AB35 ) ))),"")}
AB36: =ROW(A36)- $AD$2 +1 -> 23 | AC36: =IF(AND($E36="Oui",$M36="Préleveur"),$F36,"") | AD36: {=IFERROR(INDEX($AC$14:$AC$99,SMALL(IF($AC$14:$AC$99<>"",ROW($AC$14:$AC$99)-ROW(INDIRECT("$AC$14"))+1),ROW(INDIRECT("A" & AB36 ) ))),"")} | AE36: =IF(AND($E36="Oui",LEFT($M36,10) ="Débitmètre"),$F36,"") | AF36: {=IFERROR(INDEX($AE$14:$AE$99,SMALL(IF($AE$14:$AE$99<>"",ROW($AE$14:$AE$99)-ROW(INDIRECT("$AE$14"))+1),ROW(INDIRECT("A" & AB36 ) ))),"")} | AG36: =IF(AND($E36="Oui",LEFT($M36,5) ="Sonde"),$F36,"") | AH36: {=IFERROR(INDEX($AG$14:$AG$99,SMALL(IF($AG$14:$AG$99<>"",ROW($AG$14:$AG$99)-ROW(INDIRECT("$AG$14"))+1),ROW(INDIRECT("A" & AB36 ) ))),"")} | AI36: =IF(AND($E36="Oui", $F36 <> "", $M36 = ""),$F36,"") | AJ36: {=IFERROR(INDEX($AI$14:$AI$99,SMALL(IF($AI$14:$AI$99<>"",ROW($AI$14:$AI$99)-ROW(INDIRECT("$AI$14"))+1),ROW(INDIRECT("A" & AB36 ) ))),"")}
AB37: =ROW(A37)- $AD$2 +1 -> 24 | AC37: =IF(AND($E37="Oui",$M37="Préleveur"),$F37,"") | AD37: {=IFERROR(INDEX($AC$14:$AC$99,SMALL(IF($AC$14:$AC$99<>"",ROW($AC$14:$AC$99)-ROW(INDIRECT("$AC$14"))+1),ROW(INDIRECT("A" & AB37 ) ))),"")} | AE37: =IF(AND($E37="Oui",LEFT($M37,10) ="Débitmètre"),$F37,"") | AF37: {=IFERROR(INDEX($AE$14:$AE$99,SMALL(IF($AE$14:$AE$99<>"",ROW($AE$14:$AE$99)-ROW(INDIRECT("$AE$14"))+1),ROW(INDIRECT("A" & AB37 ) ))),"")} | AG37: =IF(AND($E37="Oui",LEFT($M37,5) ="Sonde"),$F37,"") | AH37: {=IFERROR(INDEX($AG$14:$AG$99,SMALL(IF($AG$14:$AG$99<>"",ROW($AG$14:$AG$99)-ROW(INDIRECT("$AG$14"))+1),ROW(INDIRECT("A" & AB37 ) ))),"")} | AI37: =IF(AND($E37="Oui", $F37 <> "", $M37 = ""),$F37,"") | AJ37: {=IFERROR(INDEX($AI$14:$AI$99,SMALL(IF($AI$14:$AI$99<>"",ROW($AI$14:$AI$99)-ROW(INDIRECT("$AI$14"))+1),ROW(INDIRECT("A" & AB37 ) ))),"")}
AB38: =ROW(A38)- $AD$2 +1 -> 25 | AC38: =IF(AND($E38="Oui",$M38="Préleveur"),$F38,"") | AD38: {=IFERROR(INDEX($AC$14:$AC$99,SMALL(IF($AC$14:$AC$99<>"",ROW($AC$14:$AC$99)-ROW(INDIRECT("$AC$14"))+1),ROW(INDIRECT("A" & AB38 ) ))),"")} | AE38: =IF(AND($E38="Oui",LEFT($M38,10) ="Débitmètre"),$F38,"") | AF38: {=IFERROR(INDEX($AE$14:$AE$99,SMALL(IF($AE$14:$AE$99<>"",ROW($AE$14:$AE$99)-ROW(INDIRECT("$AE$14"))+1),ROW(INDIRECT("A" & AB38 ) ))),"")} | AG38: =IF(AND($E38="Oui",LEFT($M38,5) ="Sonde"),$F38,"") | AH38: {=IFERROR(INDEX($AG$14:$AG$99,SMALL(IF($AG$14:$AG$99<>"",ROW($AG$14:$AG$99)-ROW(INDIRECT("$AG$14"))+1),ROW(INDIRECT("A" & AB38 ) ))),"")} | AI38: =IF(AND($E38="Oui", $F38 <> "", $M38 = ""),$F38,"") | AJ38: {=IFERROR(INDEX($AI$14:$AI$99,SMALL(IF($AI$14:$AI$99<>"",ROW($AI$14:$AI$99)-ROW(INDIRECT("$AI$14"))+1),ROW(INDIRECT("A" & AB38 ) ))),"")}
AB39: =ROW(A39)- $AD$2 +1 -> 26 | AC39: =IF(AND($E39="Oui",$M39="Préleveur"),$F39,"") | AD39: {=IFERROR(INDEX($AC$14:$AC$99,SMALL(IF($AC$14:$AC$99<>"",ROW($AC$14:$AC$99)-ROW(INDIRECT("$AC$14"))+1),ROW(INDIRECT("A" & AB39 ) ))),"")} | AE39: =IF(AND($E39="Oui",LEFT($M39,10) ="Débitmètre"),$F39,"") | AF39: {=IFERROR(INDEX($AE$14:$AE$99,SMALL(IF($AE$14:$AE$99<>"",ROW($AE$14:$AE$99)-ROW(INDIRECT("$AE$14"))+1),ROW(INDIRECT("A" & AB39 ) ))),"")} | AG39: =IF(AND($E39="Oui",LEFT($M39,5) ="Sonde"),$F39,"") | AH39: {=IFERROR(INDEX($AG$14:$AG$99,SMALL(IF($AG$14:$AG$99<>"",ROW($AG$14:$AG$99)-ROW(INDIRECT("$AG$14"))+1),ROW(INDIRECT("A" & AB39 ) ))),"")} | AI39: =IF(AND($E39="Oui", $F39 <> "", $M39 = ""),$F39,"") | AJ39: {=IFERROR(INDEX($AI$14:$AI$99,SMALL(IF($AI$14:$AI$99<>"",ROW($AI$14:$AI$99)-ROW(INDIRECT("$AI$14"))+1),ROW(INDIRECT("A" & AB39 ) ))),"")}
D40: Liste des pluviomètres de référence de la station | AB40: =ROW(A40)- $AD$2 +1 -> 27 | AC40: =IF(AND($E40="Oui",$M40="Préleveur"),$F40,"") | AD40: {=IFERROR(INDEX($AC$14:$AC$99,SMALL(IF($AC$14:$AC$99<>"",ROW($AC$14:$AC$99)-ROW(INDIRECT("$AC$14"))+1),ROW(INDIRECT("A" & AB40 ) ))),"")} | AE40: =IF(AND($E40="Oui",LEFT($M40,10) ="Débitmètre"),$F40,"") | AF40: {=IFERROR(INDEX($AE$14:$AE$99,SMALL(IF($AE$14:$AE$99<>"",ROW($AE$14:$AE$99)-ROW(INDIRECT("$AE$14"))+1),ROW(INDIRECT("A" & AB40 ) ))),"")} | AG40: =IF(AND($E40="Oui",LEFT($M40,5) ="Sonde"),$F40,"") | AH40: {=IFERROR(INDEX($AG$14:$AG$99,SMALL(IF($AG$14:$AG$99<>"",ROW($AG$14:$AG$99)-ROW(INDIRECT("$AG$14"))+1),ROW(INDIRECT("A" & AB40 ) ))),"")} | AI40: =IF(AND($E40="Oui", $F40 <> "", $M40 = ""),$F40,"") | AJ40: {=IFERROR(INDEX($AI$14:$AI$99,SMALL(IF($AI$14:$AI$99<>"",ROW($AI$14:$AI$99)-ROW(INDIRECT("$AI$14"))+1),ROW(INDIRECT("A" & AB40 ) ))),"")}
AB41: =ROW(A41)- $AD$2 +1 -> 28 | AC41: =IF(AND($E41="Oui",$M41="Préleveur"),$F41,"") | AD41: {=IFERROR(INDEX($AC$14:$AC$99,SMALL(IF($AC$14:$AC$99<>"",ROW($AC$14:$AC$99)-ROW(INDIRECT("$AC$14"))+1),ROW(INDIRECT("A" & AB41 ) ))),"")} | AE41: =IF(AND($E41="Oui",LEFT($M41,10) ="Débitmètre"),$F41,"") | AF41: {=IFERROR(INDEX($AE$14:$AE$99,SMALL(IF($AE$14:$AE$99<>"",ROW($AE$14:$AE$99)-ROW(INDIRECT("$AE$14"))+1),ROW(INDIRECT("A" & AB41 ) ))),"")} | AG41: =IF(AND($E41="Oui",LEFT($M41,5) ="Sonde"),$F41,"") | AH41: {=IFERROR(INDEX($AG$14:$AG$99,SMALL(IF($AG$14:$AG$99<>"",ROW($AG$14:$AG$99)-ROW(INDIRECT("$AG$14"))+1),ROW(INDIRECT("A" & AB41 ) ))),"")} | AI41: =IF(AND($E41="Oui", $F41 <> "", $M41 = ""),$F41,"") | AJ41: {=IFERROR(INDEX($AI$14:$AI$99,SMALL(IF($AI$14:$AI$99<>"",ROW($AI$14:$AI$99)-ROW(INDIRECT("$AI$14"))+1),ROW(INDIRECT("A" & AB41 ) ))),"")}
E42: Actif | F42: Lien vers l'onglet de l'équipement | AB42: =ROW(A42)- $AD$2 +1 -> 29 | AC42: =IF(AND($E42="Oui",$M42="Préleveur"),$F42,"") | AD42: {=IFERROR(INDEX($AC$14:$AC$99,SMALL(IF($AC$14:$AC$99<>"",ROW($AC$14:$AC$99)-ROW(INDIRECT("$AC$14"))+1),ROW(INDIRECT("A" & AB42 ) ))),"")} | AE42: =IF(AND($E42="Oui",LEFT($M42,10) ="Débitmètre"),$F42,"") | AF42: {=IFERROR(INDEX($AE$14:$AE$99,SMALL(IF($AE$14:$AE$99<>"",ROW($AE$14:$AE$99)-ROW(INDIRECT("$AE$14"))+1),ROW(INDIRECT("A" & AB42 ) ))),"")} | AG42: =IF(AND($E42="Oui",LEFT($M42,5) ="Sonde"),$F42,"") | AH42: {=IFERROR(INDEX($AG$14:$AG$99,SMALL(IF($AG$14:$AG$99<>"",ROW($AG$14:$AG$99)-ROW(INDIRECT("$AG$14"))+1),ROW(INDIRECT("A" & AB42 ) ))),"")} | AI42: =IF(AND($E42="Oui", $F42 <> "", $M42 = ""),$F42,"") | AJ42: {=IFERROR(INDEX($AI$14:$AI$99,SMALL(IF($AI$14:$AI$99<>"",ROW($AI$14:$AI$99)-ROW(INDIRECT("$AI$14"))+1),ROW(INDIRECT("A" & AB42 ) ))),"")}
...

Sheet SYNTHESE_SCL
C2: CONTRÔLE ANNUEL DES DISPOSITIFS D'AUTOSURVEILLANCE DES SYSTÈMES D'ASSAINISSEMENT COLLECTIF | Y2: Exporter en Word
C3: NOM DU SYSTÈME D'ASSAINISSEMENT : | G3: =IF(ISBLANK(Descriptif!F3),"",Descriptif!F3) | J3: NOM DU SYSTÈME DE TRAITEMENT : | M3: =IF(ISBLANK(Descriptif!L3),"",Descriptif!L3) | P3: NOM DU SYSTÈME DE COLLECTE : | S3: =IF(ISBLANK(Descriptif!Q3),"",Descriptif!Q3) | V3: NOM DE L'ORGANISME DE CONTRÔLE : | Y3: =IF(ISBLANK(Descriptif!U3),"",Descriptif!U3)
C4: CODE SANDRE DE L'AGGLOMÉRATION : | G4: =IF(ISBLANK(Descriptif!F4),"",Descriptif!F4) | J4: CODE SANDRE DE LA STATION : | M4: =IF(ISBLANK(Descriptif!L4),"",Descriptif!L4) | P4: CODE SANDRE DU RÉSEAU : | S4: =IF(ISBLANK(Descriptif!Q4),"",Descriptif!Q4) | V4: NOM(S) DU(ES) CONTROLEUR(S) : | Y4: =IF(ISBLANK(Descriptif!U4),"",Descriptif!U4)
C5: MAITRE D'OUVRAGE DE LA STATION : | G5: =IF(ISBLANK(Descriptif!F5),"",Descriptif!F5) | J5: TYPE DE TRAITEMENT : | M5: =IF(ISBLANK(Descriptif!L5),"",Descriptif!L5) | P5: TYPE DE RÉSEAU : | S5: =IF(ISBLANK(Descriptif!Q5),"",Descriptif!Q5) | V5: DATE(S) D'INTERVENTION : | Y5: =IF(ISBLANK(Descriptif!U5),"",Descriptif!U5)
C6: EXPLOITANT DE LA STATION : | G6: =IF(ISBLANK(Descriptif!F6),"",Descriptif!F6) | J6: CAPACITÉ DE LA STATION : | M6: =IF(ISBLANK(Descriptif!L6),"",Descriptif!L6) | P6: EXPLOITANT DU RÉSEAU : | S6: =IF(ISBLANK(Descriptif!Q6),"",Descriptif!Q6) | V6: CONDITION(S) MÉTÉO : | Y6: =IF(ISBLANK(Descriptif!U6),"",Descriptif!U6)
C8: SYNTHÈSE DES CONTRÔLES RÉALISÉS SUR LES DISPOSITIFS AUTOSURVEILLANCE
D11: Évaluation des pratiques de fractionnement et de transport des échantillons
K12: Penalité | N12: Commentaires sur l'évaluation :
G13: SDE | I13: Aquaref | K13: =IF(Analytique!N11<>"",Analytique!N11,"") | N13: =IF(Analytique!D17<>"",Analytique!D17,"")
G14: Eaux résiduaires | I14: Fractionnement | K14: =IF(Analytique!N12<>"",Analytique!N12,"")
I15: Température | K15: =IF(Analytique!N13<>"",Analytique!N13,"")
I16: Transport | K16: =IF(Analytique!N14<>"",Analytique!N14,"")
D19: Autres évaluations
K20: Score | N20: Commentaires sur l'évaluation :
G21: Sonde température | I21: {=IFERROR(INDEX(Equipements_SCL!$L$16:$L$72,SMALL(IF(Equipements_SCL!$J$16:$J$72="Sonde de température",ROW(Equipements_SCL!$J$16:$J$72)-ROW(Equipements_SCL!$J$16)+1),ROW(1:1))),"")} | K21: {=IFERROR(INDEX(Equipements_SCL!$P$16:$P$72,SMALL(IF(Equipements_SCL!$J$16:$J$72="Sonde de température",ROW(Equipements_SCL!$J$16:$J$72)-ROW(Equipements_SCL!$J$16)+1),ROW(1:1))),"")} | N21: {=IFERROR(INDEX(Equipements_SCL!$T$16:$T$72,SMALL(IF(Equipements_SCL!$J$16:$J$72="Sonde de température",ROW(Equipements_SCL!$J$16:$J$72)-ROW(Equipements_SCL!$J$16)+1),ROW(1:1))),"")}
I22: {=IFERROR(INDEX(Equipements_SCL!$L$16:$L$72,SMALL(IF(Equipements_SCL!$J$16:$J$72="Sonde de température",ROW(Equipements_SCL!$J$16:$J$72)-ROW(Equipements_SCL!$J$16)+1),ROW(2:2))),"")} | K22: {=IFERROR(INDEX(Equipements_SCL!$R$16:$R$72,SMALL(IF(Equipements_SCL!$J$16:$J$72="Sonde de température",ROW(Equipements_SCL!$J$16:$J$72)-ROW(Equipements_SCL!$J$16)+1),ROW(2:2))),"")} | N22: {=IFERROR(INDEX(Equipements_SCL!$T$16:$T$72,SMALL(IF(Equipements_SCL!$J$16:$J$72="Sonde de température",ROW(Equipements_SCL!$J$16:$J$72)-ROW(Equipements_SCL!$J$16)+1),ROW(2:2))),"")}
I23: {=IFERROR(INDEX(Equipements_SCL!$L$16:$L$72,SMALL(IF(Equipements_SCL!$J$16:$J$72="Sonde de température",ROW(Equipements_SCL!$J$16:$J$72)-ROW(Equipements_SCL!$J$16)+1),ROW(3:3))),"")} | K23: {=IFERROR(INDEX(Equipements_SCL!$R$16:$R$72,SMALL(IF(Equipements_SCL!$J$16:$J$72="Sonde de température",ROW(Equipements_SCL!$J$16:$J$72)-ROW(Equipements_SCL!$J$16)+1),ROW(3:3))),"")} | N23: {=IFERROR(INDEX(Equipements_SCL!$T$16:$T$72,SMALL(IF(Equipements_SCL!$J$16:$J$72="Sonde de température",ROW(Equipements_SCL!$J$16:$J$72)-ROW(Equipements_SCL!$J$16)+1),ROW(3:3))),"")}
K25: Score | N25: Commentaires sur l'évaluation :
G26: Pluviomètre | I26: {=IFERROR(INDEX(Equipements_SCL!$L$16:$L$72,SMALL(IF(Equipements_SCL!$J$16:$J$72="Pluviomètre",ROW(Equipements_SCL!$J$16:$J$72)-ROW(Equipements_SCL!$J$16)+1),ROW(1:1))),"")} | K26: {=IFERROR(INDEX(Equipements_SCL!$P$16:$P$72,SMALL(IF(Equipements_SCL!$J$16:$J$72="Pluviomètre",ROW(Equipements_SCL!$J$16:$J$72)-ROW(Equipements_SCL!$J$16)+1),ROW(1:1))),"")} | N26: {=IFERROR(INDEX(Equipements_SCL!$T$16:$T$72,SMALL(IF(Equipements_SCL!$J$16:$J$72="Pluviomètre",ROW(Equipements_SCL!$J$16:$J$72)-ROW(Equipements_SCL!$J$16)+1),ROW(1:1))),"")}
I27: {=IFERROR(INDEX(Equipements_SCL!$L$16:$L$72,SMALL(IF(Equipements_SCL!$J$16:$J$72="Pluviomètre",ROW(Equipements_SCL!$J$16:$J$72)-ROW(Equipements_SCL!$J$16)+1),ROW(2:2))),"")} | K27: {=IFERROR(INDEX(Equipements_SCL!$P$16:$P$72,SMALL(IF(Equipements_SCL!$J$16:$J$72="Pluviomètre",ROW(Equipements_SCL!$J$16:$J$72)-ROW(Equipements_SCL!$J$16)+1),ROW(2:2))),"")} | N27: {=IFERROR(INDEX(Equipements_SCL!$T$16:$T$72,SMALL(IF(Equipements_SCL!$J$16:$J$72="Pluviomètre",ROW(Equipements_SCL!$J$16:$J$72)-ROW(Equipements_SCL!$J$16)+1),ROW(2:2))),"")}
I28: {=IFERROR(INDEX(Equipements_SCL!$L$16:$L$72,SMALL(IF(Equipements_SCL!$J$16:$J$72="Pluviomètre",ROW(Equipements_SCL!$J$16:$J$72)-ROW(Equipements_SCL!$J$16)+1),ROW(3:3))),"")} | K28: {=IFERROR(INDEX(Equipements_SCL!$P$16:$P$72,SMALL(IF(Equipements_SCL!$J$16:$J$72="Pluviomètre",ROW(Equipements_SCL!$J$16:$J$72)-ROW(Equipements_SCL!$J$16)+1),ROW(3:3))),"")} | N28: {=IFERROR(INDEX(Equipements_SCL!$T$16:$T$72,SMALL(IF(Equipements_SCL!$J$16:$J$72="Pluviomètre",ROW(Equipements_SCL!$J$16:$J$72)-ROW(Equipements_SCL!$J$16)+1),ROW(3:3))),"")}
D31: Évaluation des points règlementaires du réseau
G32: Point | H32: Score | I32: Débitmètre | J32: Débitmètre gravitaire | K32: Débitmètre en charge | L32: Préleveur | M32: Analytique
G33: {=_xlfn._xlws.SORT(_xlfn.UNIQUE(_xlfn._xlws.FILTER(Equipements_SCL!$M$16:M100, Equipements_SCL!$M$16:M100<>"", "")))} | H33: =IF(AND($G33<>"",OR($I33<>"",$L33<>"",$M33<>"")),AVERAGE($I33,$L33,$M33),"") | I33: =IF(AND($G33<>"",OR($J33<>"",$K33<>"")),MAX($J33,$K33),"") | J33: =IF($G33="", "", IF(SUMIFS(Equipements_SCL!$P$16:$P$100, Equipements_SCL!$M$16:$M$100, $G33, Equipements_SCL!$J$16:$J$100, J$32)=0, "", SUMIFS(Equipements_SCL!$P$16:$P$100, Equipements_SCL!$M$16:$M$100, $G33, Equipements_SCL!$J$16:$J$100, J$32))) | K33: =IF($G33="", "", IF(SUMIFS(Equipements_SCL!$P$16:$P$100, Equipements_SCL!$M$16:$M$100, $G33, Equipements_SCL!$J$16:$J$100, K$32)=0, "", SUMIFS(Equipements_SCL!$P$16:$P$100, Equipements_SCL!$M$16:$M$100, $G33, Equipements_SCL!$J$16:$J$100, K$32))) | L33: =IF($G33="", "", IF(SUMIFS(Equipements_SCL!$P$16:$P$100, Equipements_SCL!$M$16:$M$100, $G33, Equipements_SCL!$J$16:$J$100, L$32)=0, "", SUMIFS(Equipements_SCL!$P$16:$P$100, Equipements_SCL!$M$16:$M$100, $G33, Equipements_SCL!$J$16:$J$100, L$32))) | M33: =IF( $G33="", "", IF( SUMIFS(Analytique!$AD$3:$AD$20, Analytique!$Z$3:$Z$20, $G33, Analytique!$Y$3:$Y$20, "A1")=0, "", SUMIFS(Analytique!$AD$3:$AD$20, Analytique!$Z$3:$Z$20, $G33, Analytique!$Y$3:$Y$20, "A1") ) )
G34: {=_xlfn._xlws.SORT(_xlfn.UNIQUE(_xlfn._xlws.FILTER(Equipements_SCL!$M$16:M101, Equipements_SCL!$M$16:M101<>"", "")))} | H34: =IF(AND($G34<>"",OR($I34<>"",$L34<>"",$M34<>"")),AVERAGE($I34,$L34,$M34),"") | I34: =IF(AND($G34<>"",OR($J34<>"",$K34<>"")),MAX($J34,$K34),"") | J34: =IF($G34="", "", IF(SUMIFS(Equipements_SCL!$P$16:$P$100, Equipements_SCL!$M$16:$M$100, $G34, Equipements_SCL!$J$16:$J$100, J$32)=0, "", SUMIFS(Equipements_SCL!$P$16:$P$100, Equipements_SCL!$M$16:$M$100, $G34, Equipements_SCL!$J$16:$J$100, J$32))) | K34: =IF($G34="", "", IF(SUMIFS(Equipements_SCL!$P$16:$P$100, Equipements_SCL!$M$16:$M$100, $G34, Equipements_SCL!$J$16:$J$100, K$32)=0, "", SUMIFS(Equipements_SCL!$P$16:$P$100, Equipements_SCL!$M$16:$M$100, $G34, Equipements_SCL!$J$16:$J$100, K$32))) | L34: =IF($G34="", "", IF(SUMIFS(Equipements_SCL!$P$16:$P$100, Equipements_SCL!$M$16:$M$100, $G34, Equipements_SCL!$J$16:$J$100, L$32)=0, "", SUMIFS(Equipements_SCL!$P$16:$P$100, Equipements_SCL!$M$16:$M$100, $G34, Equipements_SCL!$J$16:$J$100, L$32))) | M34: =IF( $G34="", "", IF( SUMIFS(Analytique!$AD$3:$AD$20, Analytique!$Z$3:$Z$20, $G34, Analytique!$Y$3:$Y$20, "A1")=0, "", SUMIFS(Analytique!$AD$3:$AD$20, Analytique!$Z$3:$Z$20, $G34, Analytique!$Y$3:$Y$20, "A1") ) )
G35: {=_xlfn._xlws.SORT(_xlfn.UNIQUE(_xlfn._xlws.FILTER(Equipements_SCL!$M$16:M102, Equipements_SCL!$M$16:M102<>"", "")))} | H35: =IF(AND($G35<>"",OR($I35<>"",$L35<>"",$M35<>"")),AVERAGE($I35,$L35,$M35),"") | I35: =IF(AND($G35<>"",OR($J35<>"",$K35<>"")),MAX($J35,$K35),"") | J35: =IF($G35="", "", IF(SUMIFS(Equipements_SCL!$P$16:$P$100, Equipements_SCL!$M$16:$M$100, $G35, Equipements_SCL!$J$16:$J$100, J$32)=0, "", SUMIFS(Equipements_SCL!$P$16:$P$100, Equipements_SCL!$M$16:$M$100, $G35, Equipements_SCL!$J$16:$J$100, J$32))) | K35: =IF($G35="", "", IF(SUMIFS(Equipements_SCL!$P$16:$P$100, Equipements_SCL!$M$16:$M$100, $G35, Equipements_SCL!$J$16:$J$100, K$32)=0, "", SUMIFS(Equipements_SCL!$P$16:$P$100, Equipements_SCL!$M$16:$M$100, $G35, Equipements_SCL!$J$16:$J$100, K$32))) | L35: =IF($G35="", "", IF(SUMIFS(Equipements_SCL!$P$16:$P$100, Equipements_SCL!$M$16:$M$100, $G35, Equipements_SCL!$J$16:$J$100, L$32)=0, "", SUMIFS(Equipements_SCL!$P$16:$P$100, Equipements_SCL!$M$16:$M$100, $G35, Equipements_SCL!$J$16:$J$100, L$32))) | M35: =IF( $G35="", "", IF( SUMIFS(Analytique!$AD$3:$AD$20, Analytique!$Z$3:$Z$20, $G35, Analytique!$Y$3:$Y$20, "A1")=0, "", SUMIFS(Analytique!$AD$3:$AD$20, Analytique!$Z$3:$Z$20, $G35, Analytique!$Y$3:$Y$20, "A1") ) )
G36: {=_xlfn._xlws.SORT(_xlfn.UNIQUE(_xlfn._xlws.FILTER(Equipements_SCL!$M$16:M103, Equipements_SCL!$M$16:M103<>"", "")))} | H36: =IF(AND($G36<>"",OR($I36<>"",$L36<>"",$M36<>"")),AVERAGE($I36,$L36,$M36),"") | I36: =IF(AND($G36<>"",OR($J36<>"",$K36<>"")),MAX($J36,$K36),"") | J36: =IF($G36="", "", IF(SUMIFS(Equipements_SCL!$P$16:$P$100, Equipements_SCL!$M$16:$M$100, $G36, Equipements_SCL!$J$16:$J$100, J$32)=0, "", SUMIFS(Equipements_SCL!$P$16:$P$100, Equipements_SCL!$M$16:$M$100, $G36, Equipements_SCL!$J$16:$J$100, J$32))) | K36: =IF($G36="", "", IF(SUMIFS(Equipements_SCL!$P$16:$P$100, Equipements_SCL!$M$16:$M$100, $G36, Equipements_SCL!$J$16:$J$100, K$32)=0, "", SUMIFS(Equipements_SCL!$P$16:$P$100, Equipements_SCL!$M$16:$M$100, $G36, Equipements_SCL!$J$16:$J$100, K$32))) | L36: =IF($G36="", "", IF(SUMIFS(Equipements_SCL!$P$16:$P$100, Equipements_SCL!$M$16:$M$100, $G36, Equipements_SCL!$J$16:$J$100, L$32)=0, "", SUMIFS(Equipements_SCL!$P$16:$P$100, Equipements_SCL!$M$16:$M$100, $G36, Equipements_SCL!$J$16:$J$100, L$32))) | M36: =IF( $G36="", "", IF( SUMIFS(Analytique!$AD$3:$AD$20, Analytique!$Z$3:$Z$20, $G36, Analytique!$Y$3:$Y$20, "A1")=0, "", SUMIFS(Analytique!$AD$3:$AD$20, Analytique!$Z$3:$Z$20, $G36, Analytique!$Y$3:$Y$20, "A1") ) )
G37: {=_xlfn._xlws.SORT(_xlfn.UNIQUE(_xlfn._xlws.FILTER(Equipements_SCL!$M$16:M104, Equipements_SCL!$M$16:M104<>"", "")))} | H37: =IF(AND($G37<>"",OR($I37<>"",$L37<>"",$M37<>"")),AVERAGE($I37,$L37,$M37),"") | I37: =IF(AND($G37<>"",OR($J37<>"",$K37<>"")),MAX($J37,$K37),"") | J37: =IF($G37="", "", IF(SUMIFS(Equipements_SCL!$P$16:$P$100, Equipements_SCL!$M$16:$M$100, $G37, Equipements_SCL!$J$16:$J$100, J$32)=0, "", SUMIFS(Equipements_SCL!$P$16:$P$100, Equipements_SCL!$M$16:$M$100, $G37, Equipements_SCL!$J$16:$J$100, J$32))) | K37: =IF($G37="", "", IF(SUMIFS(Equipements_SCL!$P$16:$P$100, Equipements_SCL!$M$16:$M$100, $G37, Equipements_SCL!$J$16:$J$100, K$32)=0, "", SUMIFS(Equipements_SCL!$P$16:$P$100, Equipements_SCL!$M$16:$M$100, $G37, Equipements_SCL!$J$16:$J$100, K$32))) | L37: =IF($G37="", "", IF(SUMIFS(Equipements_SCL!$P$16:$P$100, Equipements_SCL!$M$16:$M$100, $G37, Equipements_SCL!$J$16:$J$100, L$32)=0, "", SUMIFS(Equipements_SCL!$P$16:$P$100, Equipements_SCL!$M$16:$M$100, $G37, Equipements_SCL!$J$16:$J$100, L$32))) | M37: =IF( $G37="", "", IF( SUMIFS(Analytique!$AD$3:$AD$20, Analytique!$Z$3:$Z$20, $G37, Analytique!$Y$3:$Y$20, "A1")=0, "", SUMIFS(Analytique!$AD$3:$AD$20, Analytique!$Z$3:$Z$20, $G37, Analytique!$Y$3:$Y$20, "A1") ) )
G38: {=_xlfn._xlws.SORT(_xlfn.UNIQUE(_xlfn._xlws.FILTER(Equipements_SCL!$M$16:M105, Equipements_SCL!$M$16:M105<>"", "")))} | H38: =IF(AND($G38<>"",OR($I38<>"",$L38<>"",$M38<>"")),AVERAGE($I38,$L38,$M38),"") | I38: =IF(AND($G38<>"",OR($J38<>"",$K38<>"")),MAX($J38,$K38),"") | J38: =IF($G38="", "", IF(SUMIFS(Equipements_SCL!$P$16:$P$100, Equipements_SCL!$M$16:$M$100, $G38, Equipements_SCL!$J$16:$J$100, J$32)=0, "", SUMIFS(Equipements_SCL!$P$16:$P$100, Equipements_SCL!$M$16:$M$100, $G38, Equipements_SCL!$J$16:$J$100, J$32))) | K38: =IF($G38="", "", IF(SUMIFS(Equipements_SCL!$P$16:$P$100, Equipements_SCL!$M$16:$M$100, $G38, Equipements_SCL!$J$16:$J$100, K$32)=0, "", SUMIFS(Equipements_SCL!$P$16:$P$100, Equipements_SCL!$M$16:$M$100, $G38, Equipements_SCL!$J$16:$J$100, K$32))) | L38: =IF($G38="", "", IF(SUMIFS(Equipements_SCL!$P$16:$P$100, Equipements_SCL!$M$16:$M$100, $G38, Equipements_SCL!$J$16:$J$100, L$32)=0, "", SUMIFS(Equipements_SCL!$P$16:$P$100, Equipements_SCL!$M$16:$M$100, $G38, Equipements_SCL!$J$16:$J$100, L$32))) | M38: =IF( $G38="", "", IF( SUMIFS(Analytique!$AD$3:$AD$20, Analytique!$Z$3:$Z$20, $G38, Analytique!$Y$3:$Y$20, "A1")=0, "", SUMIFS(Analytique!$AD$3:$AD$20, Analytique!$Z$3:$Z$20, $G38, Analytique!$Y$3:$Y$20, "A1") ) )
G39: {=_xlfn._xlws.SORT(_xlfn.UNIQUE(_xlfn._xlws.FILTER(Equipements_SCL!$M$16:M106, Equipements_SCL!$M$16:M106<>"", "")))} | H39: =IF(AND($G39<>"",OR($I39<>"",$L39<>"",$M39<>"")),AVERAGE($I39,$L39,$M39),"") | I39: =IF(AND($G39<>"",OR($J39<>"",$K39<>"")),MAX($J39,$K39),"") | J39: =IF($G39="", "", IF(SUMIFS(Equipements_SCL!$P$16:$P$100, Equipements_SCL!$M$16:$M$100, $G39, Equipements_SCL!$J$16:$J$100, J$32)=0, "", SUMIFS(Equipements_SCL!$P$16:$P$100, Equipements_SCL!$M$16:$M$100, $G39, Equipements_SCL!$J$16:$J$100, J$32))) | K39: =IF($G39="", "", IF(SUMIFS(Equipements_SCL!$P$16:$P$100, Equipements_SCL!$M$16:$M$100, $G39, Equipements_SCL!$J$16:$J$100, K$32)=0, "", SUMIFS(Equipements_SCL!$P$16:$P$100, Equipements_SCL!$M$16:$M$100, $G39, Equipements_SCL!$J$16:$J$100, K$32))) | L39: =IF($G39="", "", IF(SUMIFS(Equipements_SCL!$P$16:$P$100, Equipements_SCL!$M$16:$M$100, $G39, Equipements_SCL!$J$16:$J$100, L$32)=0, "", SUMIFS(Equipements_SCL!$P$16:$P$100, Equipements_SCL!$M$16:$M$100, $G39, Equipements_SCL!$J$16:$J$100, L$32))) | M39: =IF( $G39="", "", IF( SUMIFS(Analytique!$AD$3:$AD$20, Analytique!$Z$3:$Z$20, $G39, Analytique!$Y$3:$Y$20, "A1")=0, "", SUMIFS(Analytique!$AD$3:$AD$20, Analytique!$Z$3:$Z$20, $G39, Analytique!$Y$3:$Y$20, "A1") ) )
G40: {=_xlfn._xlws.SORT(_xlfn.UNIQUE(_xlfn._xlws.FILTER(Equipements_SCL!$M$16:M107, Equipements_SCL!$M$16:M107<>"", "")))} | H40: =IF(AND($G40<>"",OR($I40<>"",$L40<>"",$M40<>"")),AVERAGE($I40,$L40,$M40),"") | I40: =IF(AND($G40<>"",OR($J40<>"",$K40<>"")),MAX($J40,$K40),"") | J40: =IF($G40="", "", IF(SUMIFS(Equipements_SCL!$P$16:$P$100, Equipements_SCL!$M$16:$M$100, $G40, Equipements_SCL!$J$16:$J$100, J$32)=0, "", SUMIFS(Equipements_SCL!$P$16:$P$100, Equipements_SCL!$M$16:$M$100, $G40, Equipements_SCL!$J$16:$J$100, J$32))) | K40: =IF($G40="", "", IF(SUMIFS(Equipements_SCL!$P$16:$P$100, Equipements_SCL!$M$16:$M$100, $G40, Equipements_SCL!$J$16:$J$100, K$32)=0, "", SUMIFS(Equipements_SCL!$P$16:$P$100, Equipements_SCL!$M$16:$M$100, $G40, Equipements_SCL!$J$16:$J$100, K$32))) | L40: =IF($G40="", "", IF(SUMIFS(Equipements_SCL!$P$16:$P$100, Equipements_SCL!$M$16:$M$100, $G40, Equipements_SCL!$J$16:$J$100, L$32)=0, "", SUMIFS(Equipements_SCL!$P$16:$P$100, Equipements_SCL!$M$16:$M$100, $G40, Equipements_SCL!$J$16:$J$100, L$32))) | M40: =IF( $G40="", "", IF( SUMIFS(Analytique!$AD$3:$AD$20, Analytique!$Z$3:$Z$20, $G40, Analytique!$Y$3:$Y$20, "A1")=0, "", SUMIFS(Analytique!$AD$3:$AD$20, Analytique!$Z$3:$Z$20, $G40, Analytique!$Y$3:$Y$20, "A1") ) )
G41: {=_xlfn._xlws.SORT(_xlfn.UNIQUE(_xlfn._xlws.FILTER(Equipements_SCL!$M$16:M108, Equipements_SCL!$M$16:M108<>"", "")))} | H41: =IF(AND($G41<>"",OR($I41<>"",$L41<>"",$M41<>"")),AVERAGE($I41,$L41,$M41),"") | I41: =IF(AND($G41<>"",OR($J41<>"",$K41<>"")),MAX($J41,$K41),"") | J41: =IF($G41="", "", IF(SUMIFS(Equipements_SCL!$P$16:$P$100, Equipements_SCL!$M$16:$M$100, $G41, Equipements_SCL!$J$16:$J$100, J$32)=0, "", SUMIFS(Equipements_SCL!$P$16:$P$100, Equipements_SCL!$M$16:$M$100, $G41, Equipements_SCL!$J$16:$J$100, J$32))) | K41: =IF($G41="", "", IF(SUMIFS(Equipements_SCL!$P$16:$P$100, Equipements_SCL!$M$16:$M$100, $G41, Equipements_SCL!$J$16:$J$100, K$32)=0, "", SUMIFS(Equipements_SCL!$P$16:$P$100, Equipements_SCL!$M$16:$M$100, $G41, Equipements_SCL!$J$16:$J$100, K$32))) | L41: =IF($G41="", "", IF(SUMIFS(Equipements_SCL!$P$16:$P$100, Equipements_SCL!$M$16:$M$100, $G41, Equipements_SCL!$J$16:$J$100, L$32)=0, "", SUMIFS(Equipements_SCL!$P$16:$P$100, Equipements_SCL!$M$16:$M$100, $G41, Equipements_SCL!$J$16:$J$100, L$32))) | M41: =IF( $G41="", "", IF( SUMIFS(Analytique!$AD$3:$AD$20, Analytique!$Z$3:$Z$20, $G41, Analytique!$Y$3:$Y$20, "A1")=0, "", SUMIFS(Analytique!$AD$3:$AD$20, Analytique!$Z$3:$Z$20, $G41, Analytique!$Y$3:$Y$20, "A1") ) )
G42: {=_xlfn._xlws.SORT(_xlfn.UNIQUE(_xlfn._xlws.FILTER(Equipements_SCL!$M$16:M109, Equipements_SCL!$M$16:M109<>"", "")))} | H42: =IF(AND($G42<>"",OR($I42<>"",$L42<>"",$M42<>"")),AVERAGE($I42,$L42,$M42),"") | I42: =IF(AND($G42<>"",OR($J42<>"",$K42<>"")),MAX($J42,$K42),"") | J42: =IF($G42="", "", IF(SUMIFS(Equipements_SCL!$P$16:$P$100, Equipements_SCL!$M$16:$M$100, $G42, Equipements_SCL!$J$16:$J$100, J$32)=0, "", SUMIFS(Equipements_SCL!$P$16:$P$100, Equipements_SCL!$M$16:$M$100, $G42, Equipements_SCL!$J$16:$J$100, J$32))) | K42: =IF($G42="", "", IF(SUMIFS(Equipements_SCL!$P$16:$P$100, Equipements_SCL!$M$16:$M$100, $G42, Equipements_SCL!$J$16:$J$100, K$32)=0, "", SUMIFS(Equipements_SCL!$P$16:$P$100, Equipements_SCL!$M$16:$M$100, $G42, Equipements_SCL!$J$16:$J$100, K$32))) | L42: =IF($G42="", "", IF(SUMIFS(Equipements_SCL!$P$16:$P$100, Equipements_SCL!$M$16:$M$100, $G42, Equipements_SCL!$J$16:$J$100, L$32)=0, "", SUMIFS(Equipements_SCL!$P$16:$P$100, Equipements_SCL!$M$16:$M$100, $G42, Equipements_SCL!$J$16:$J$100, L$32))) | M42: =IF( $G42="", "", IF( SUMIFS(Analytique!$AD$3:$AD$20, Analytique!$Z$3:$Z$20, $G42, Analytique!$Y$3:$Y$20, "A1")=0, "", SUMIFS(Analytique!$AD$3:$AD$20, Analytique!$Z$3:$Z$20, $G42, Analytique!$Y$3:$Y$20, "A1") ) )
G43: {=_xlfn._xlws.SORT(_xlfn.UNIQUE(_xlfn._xlws.FILTER(Equipements_SCL!$M$16:M110, Equipements_SCL!$M$16:M110<>"", "")))} | H43: =IF(AND($G43<>"",OR($I43<>"",$L43<>"",$M43<>"")),AVERAGE($I43,$L43,$M43),"") | I43: =IF(AND($G43<>"",OR($J43<>"",$K43<>"")),MAX($J43,$K43),"") | J43: =IF($G43="", "", IF(SUMIFS(Equipements_SCL!$P$16:$P$100, Equipements_SCL!$M$16:$M$100, $G43, Equipements_SCL!$J$16:$J$100, J$32)=0, "", SUMIFS(Equipements_SCL!$P$16:$P$100, Equipements_SCL!$M$16:$M$100, $G43, Equipements_SCL!$J$16:$J$100, J$32))) | K43: =IF($G43="", "", IF(SUMIFS(Equipements_SCL!$P$16:$P$100, Equipements_SCL!$M$16:$M$100, $G43, Equipements_SCL!$J$16:$J$100, K$32)=0, "", SUMIFS(Equipements_SCL!$P$16:$P$100, Equipements_SCL!$M$16:$M$100, $G43, Equipements_SCL!$J$16:$J$100, K$32))) | L43: =IF($G43="", "", IF(SUMIFS(Equipements_SCL!$P$16:$P$100, Equipements_SCL!$M$16:$M$100, $G43, Equipements_SCL!$J$16:$J$100, L$32)=0, "", SUMIFS(Equipements_SCL!$P$16:$P$100, Equipements_SCL!$M$16:$M$100, $G43, Equipements_SCL!$J$16:$J$100, L$32))) | M43: =IF( $G43="", "", IF( SUMIFS(Analytique!$AD$3:$AD$20, Analytique!$Z$3:$Z$20, $G43, Analytique!$Y$3:$Y$20, "A1")=0, "", SUMIFS(Analytique!$AD$3:$AD$20, Analytique!$Z$3:$Z$20, $G43, Analytique!$Y$3:$Y$20, "A1") ) )
G44: {=_xlfn._xlws.SORT(_xlfn.UNIQUE(_xlfn._xlws.FILTER(Equipements_SCL!$M$16:M111, Equipements_SCL!$M$16:M111<>"", "")))} | H44: =IF(AND($G44<>"",OR($I44<>"",$L44<>"",$M44<>"")),AVERAGE($I44,$L44,$M44),"") | I44: =IF(AND($G44<>"",OR($J44<>"",$K44<>"")),MAX($J44,$K44),"") | J44: =IF($G44="", "", IF(SUMIFS(Equipements_SCL!$P$16:$P$100, Equipements_SCL!$M$16:$M$100, $G44, Equipements_SCL!$J$16:$J$100, J$32)=0, "", SUMIFS(Equipements_SCL!$P$16:$P$100, Equipements_SCL!$M$16:$M$100, $G44, Equipements_SCL!$J$16:$J$100, J$32))) | K44: =IF($G44="", "", IF(SUMIFS(Equipements_SCL!$P$16:$P$100, Equipements_SCL!$M$16:$M$100, $G44, Equipements_SCL!$J$16:$J$100, K$32)=0, "", SUMIFS(Equipements_SCL!$P$16:$P$100, Equipements_SCL!$M$16:$M$100, $G44, Equipements_SCL!$J$16:$J$100, K$32))) | L44: =IF($G44="", "", IF(SUMIFS(Equipements_SCL!$P$16:$P$100, Equipements_SCL!$M$16:$M$100, $G44, Equipements_SCL!$J$16:$J$100, L$32)=0, "", SUMIFS(Equipements_SCL!$P$16:$P$100, Equipements_SCL!$M$16:$M$100, $G44, Equipements_SCL!$J$16:$J$100, L$32))) | M44: =IF( $G44="", "", IF( SUMIFS(Analytique!$AD$3:$AD$20, Analytique!$Z$3:$Z$20, $G44, Analytique!$Y$3:$Y$20, "A1")=0, "", SUMIFS(Analytique!$AD$3:$AD$20, Analytique!$Z$3:$Z$20, $G44, Analytique!$Y$3:$Y$20, "A1") ) )
... G57: {=_xlfn._xlws.SORT(_xlfn.UNIQUE(_xlfn._xlws.FILTER(Equipements_SCL!$M$16:M124, Equipements_SCL!$M$16:M124<>"", "")))} | H57: =IF(AND($G57<>"",OR($I57<>"",$L57<>"",$M57<>"")),AVERAGE($I57,$L57,$M57),"") | I57: =IF(AND($G57<>"",OR($J57<>"",$K57<>"")),MAX($J57,$K57),"") | J57: =IF($G57="", "", IF(SUMIFS(Equipements_SCL!$P$16:$P$100, Equipements_SCL!$M$16:$M$100, $G57, Equipements_SCL!$J$16:$J$100, J$32)=0, "", SUMIFS(Equipements_SCL!$P$16:$P$100, Equipements_SCL!$M$16:$M$100, $G57, Equipements_SCL!$J$16:$J$100, J$32))) | K57: =IF($G57="", "", IF(SUMIFS(Equipements_SCL!$P$16:$P$100, Equipements_SCL!$M$16:$M$100, $G57, Equipements_SCL!$J$16:$J$100, K$32)=0, "", SUMIFS(Equipements_SCL!$P$16:$P$100, Equipements_SCL!$M$16:$M$100, $G57, Equipements_SCL!$J$16:$J$100, K$32))) | L57: =IF($G57="", "", IF(SUMIFS(Equipements_SCL!$P$16:$P$100, Equipements_SCL!$M$16:$M$100, $G57, Equipements_SCL!$J$16:$J$100, L$32)=0, "", SUMIFS(Equipements_SCL!$P$16:$P$100, Equipements_SCL!$M$16:$M$100, $G57, Equipements_SCL!$J$16:$J$100, L$32))) | M57: =IF( $G57="", "", IF( SUMIFS(Analytique!$AD$3:$AD$20, Analytique!$Z$3:$Z$20, $G57, Analytique!$Y$3:$Y$20, "A1")=0, "", SUMIFS(Analytique!$AD$3:$AD$20, Analytique!$Z$3:$Z$20, $G57, Analytique!$Y$3:$Y$20, "A1") ) )
G58: Veuillez étendre le tableau si tous vos points réseau n'apparaissent pas
D62: Commentaire général
C68: DÉTAIL DES CONTRÔLES RÉALISÉS PAR ÉQUIPEMENT D'AUTOSURVEILLANCE
D70: Détails des équipements contrôlés | N70: Score sur 100 | O70: Critères d'évaluation
...

Sheet SYNTHESE_STEU
C2: CONTRÔLE ANNUEL DES DISPOSITIFS D'AUTOSURVEILLANCE DES SYSTÈMES D'ASSAINISSEMENT COLLECTIF | Y2: Exporter en Word
C3: NOM DU SYSTÈME D'ASSAINISSEMENT : | G3: =IF(ISBLANK(Descriptif!F3),"",Descriptif!F3) | J3: NOM DU SYSTÈME DE TRAITEMENT : | M3: =IF(ISBLANK(Descriptif!L3),"",Descriptif!L3) | P3: NOM DU SYSTÈME DE COLLECTE : | S3: =IF(ISBLANK(Descriptif!Q3),"",Descriptif!Q3) | V3: NOM DE L'ORGANISME DE CONTRÔLE : | Y3: =IF(ISBLANK(Descriptif!U3),"",Descriptif!U3)
C4: CODE SANDRE DE L'AGGLOMÉRATION : | G4: =IF(ISBLANK(Descriptif!F4),"",Descriptif!F4) | J4: CODE SANDRE DE LA STATION : | M4: =IF(ISBLANK(Descriptif!L4),"",Descriptif!L4) | P4: CODE SANDRE DU RÉSEAU : | S4: =IF(ISBLANK(Descriptif!Q4),"",Descriptif!Q4) | V4: NOM(S) DU(ES) CONTROLEUR(S) : | Y4: =IF(ISBLANK(Descriptif!U4),"",Descriptif!U4)
C5: MAITRE D'OUVRAGE DE LA STATION : | G5: =IF(ISBLANK(Descriptif!F5),"",Descriptif!F5) | J5: TYPE DE TRAITEMENT : | M5: =IF(ISBLANK(Descriptif!L5),"",Descriptif!L5) | P5: TYPE DE RÉSEAU : | S5: =IF(ISBLANK(Descriptif!Q5),"",Descriptif!Q5) | V5: DATE(S) D'INTERVENTION : | Y5: =IF(ISBLANK(Descriptif!U5),"",Descriptif!U5)
C6: EXPLOITANT DE LA STATION : | G6: =IF(ISBLANK(Descriptif!F6),"",Descriptif!F6) | J6: CAPACITÉ DE LA STATION : | M6: =IF(ISBLANK(Descriptif!L6),"",Descriptif!L6) | P6: EXPLOITANT DU RÉSEAU : | S6: =IF(ISBLANK(Descriptif!Q6),"",Descriptif!Q6) | V6: CONDITION(S) MÉTÉO : | Y6: =IF(ISBLANK(Descriptif!U6),"",Descriptif!U6)
C8: SYNTHÈSE DES CONTRÔLES RÉALISÉS SUR LES DISPOSITIFS AUTOSURVEILLANCE
D10: Évaluation des points règlementaires
G11: ENTRÉE et SORTIE | J11: Score | L11: DTS ET BY-PASS | O11: Score | Q11: BOUES ET APPORTS EXTÉRIEURS | T11: Score | V11: RÉUTILISATION DES EAUX TRAITÉES | Y11: Score
G12: Point A3 | J12: =Recap_equipements!E63 | L12: Point A2 | O12: =Recap_equipements!E75 | Q12: Point A6 | T12: =Recap_equipements!E87 | V12: Point A8 | Y12: =Recap_equipements!E105
G13: Débitmètre | J13: =IF(Recap_equipements!F65<>"",Recap_equipements!F65,"") | L13: Débitmètre | O13: =IF(Recap_equipements!F77<>"",Recap_equipements!F77,"") | Q13: Débitmètre | T13: =IF(Recap_equipements!F89<>"",Recap_equipements!F89,"") | V13: Débitmètre | Y13: =IF(Recap_equipements!F107<>"",Recap_equipements!F107,"")
G14: Préleveur | J14: =IF(Recap_equipements!F66<>"",Recap_equipements!F66,"") | L14: Préleveur | O14: =IF(Recap_equipements!F78<>"",Recap_equipements!F78,"") | Q14: Préleveur | T14: =IF(Recap_equipements!F90<>"",Recap_equipements!F90,"") | V14: Préleveur | Y14: =IF(Recap_equipements!F108<>"",Recap_equipements!F108,"")
G15: Analytique | J15: =IF(Recap_equipements!F67<>"",Recap_equipements!F67,"") | L15: Analytique | O15: =IF(Recap_equipements!F79<>"",Recap_equipements!F79,"") | Q15: Analytique | T15: =IF(Recap_equipements!F91<>"",Recap_equipements!F91,"") | V15: Analytique | Y15: =IF(Recap_equipements!F109<>"",Recap_equipements!F109,"")
G16: Point A4 | J16: =Recap_equipements!E69 | L16: Point A5 | O16: =Recap_equipements!E81 | Q16: Point A7 | T16: =Recap_equipements!E93
G17: Débitmètre | J17: =IF(Recap_equipements!F71<>"",Recap_equipements!F71,"") | L17: Débitmètre | O17: =IF(Recap_equipements!F83<>"",Recap_equipements!F83,"") | Q17: Débitmètre | T17: =IF(Recap_equipements!F95<>"",Recap_equipements!F95,"") | V17: Validé
G18: Préleveur | J18: =IF(Recap_equipements!F72<>"",Recap_equipements!F72,"") | L18: Préleveur | O18: =IF(Recap_equipements!F84<>"",Recap_equipements!F84,"") | Q18: Préleveur | T18: =IF(Recap_equipements!F96<>"",Recap_equipements!F96,"") | V18: Réserve
G19: Analytique | J19: =IF(Recap_equipements!F73<>"",Recap_equipements!F73,"") | L19: Analytique | O19: =IF(Recap_equipements!F85<>"",Recap_equipements!F85,"") | Q19: Analytique | T19: =IF(Recap_equipements!F97<>"",Recap_equipements!F97,"") | V19: Non validé
D22: Évaluation documentaire
M23: Coefficient Qualité | N23: Commentaires sur l'évaluation :
G24: Manuel autosurveillance à jour, validé ou en cours d'expertise ? | L24: =IF(Qualité!L10<>"",Qualité!L10,"Non contrôlé") -> Non contrôlé | N24: =IF(Qualité!M10<>"",Qualité!M10,"")
G25: Existe-t-il un système Qualité performant ? | L25: =IF(Qualité!L29<>"",Qualité!L29,"Non contrôlé") -> Non contrôlé | M25: =IF(Qualité!L29="Oui",1,0.9) -> 0.9 | N25: =IF(Qualité!D32<>"",Qualité!D32,"")
D28: Évaluation des pratiques de fractionnement et de transport des échantillons
K29: Penalité | N29: Commentaires sur l'évaluation :
G30: SDE | I30: Aquaref | K30: =IF(Analytique!N11<>"",Analytique!N11,"") | N30: =IF(Analytique!D17<>"",Analytique!D17,"")
G31: Eaux résiduaires | I31: Fractionnement | K31: =IF(Analytique!N12<>"",Analytique!N12,"")
I32: Température | K32: =IF(Analytique!N13<>"",Analytique!N13,"")
I33: Transport | K33: =IF(Analytique!N14<>"",Analytique!N14,"")
D36: Autres évaluations
K37: Score | N37: Commentaires sur l'évaluation :
G38: Sonde température | I38: {=IFERROR(INDEX(Equipements_STEU!$L$16:$L$72,SMALL(IF(Equipements_STEU!$J$16:$J$72="Sonde de température",ROW(Equipements_STEU!$J$16:$J$72)-ROW(Equipements_STEU!$J$16)+1),ROW(1:1))),"")} | K38: {=IFERROR(INDEX(Equipements_STEU!$P$16:$P$72,SMALL(IF(Equipements_STEU!$J$16:$J$72="Sonde de température",ROW(Equipements_STEU!$J$16:$J$72)-ROW(Equipements_STEU!$J$16)+1),ROW(1:1))),"")} | N38: {=IFERROR(INDEX(Equipements_STEU!$T$16:$T$72,SMALL(IF(Equipements_STEU!$J$16:$J$72="Sonde de température",ROW(Equipements_STEU!$J$16:$J$72)-ROW(Equipements_STEU!$J$16)+1),ROW(1:1))),"")}
I39: {=IFERROR(INDEX(Equipements_STEU!$L$16:$L$72,SMALL(IF(Equipements_STEU!$J$16:$J$72="Sonde de température",ROW(Equipements_STEU!$J$16:$J$72)-ROW(Equipements_STEU!$J$16)+1),ROW(2:2))),"")} | K39: {=IFERROR(INDEX(Equipements_STEU!$R$16:$R$72,SMALL(IF(Equipements_STEU!$J$16:$J$72="Sonde de température",ROW(Equipements_STEU!$J$16:$J$72)-ROW(Equipements_STEU!$J$16)+1),ROW(2:2))),"")} | N39: {=IFERROR(INDEX(Equipements_STEU!$T$16:$T$72,SMALL(IF(Equipements_STEU!$J$16:$J$72="Sonde de température",ROW(Equipements_STEU!$J$16:$J$72)-ROW(Equipements_STEU!$J$16)+1),ROW(2:2))),"")}
I40: {=IFERROR(INDEX(Equipements_STEU!$L$16:$L$72,SMALL(IF(Equipements_STEU!$J$16:$J$72="Sonde de température",ROW(Equipements_STEU!$J$16:$J$72)-ROW(Equipements_STEU!$J$16)+1),ROW(3:3))),"")} | K40: {=IFERROR(INDEX(Equipements_STEU!$R$16:$R$72,SMALL(IF(Equipements_STEU!$J$16:$J$72="Sonde de température",ROW(Equipements_STEU!$J$16:$J$72)-ROW(Equipements_STEU!$J$16)+1),ROW(3:3))),"")} | N40: {=IFERROR(INDEX(Equipements_STEU!$T$16:$T$72,SMALL(IF(Equipements_STEU!$J$16:$J$72="Sonde de température",ROW(Equipements_STEU!$J$16:$J$72)-ROW(Equipements_STEU!$J$16)+1),ROW(3:3))),"")}
K42: Score | N42: Commentaires sur l'évaluation :
G43: Pluviomètre | I43: {=IFERROR(INDEX(Equipements_STEU!$L$16:$L$72,SMALL(IF(Equipements_STEU!$J$16:$J$72="Pluviomètre",ROW(Equipements_STEU!$J$16:$J$72)-ROW(Equipements_STEU!$J$16)+1),ROW(1:1))),"")} | K43: {=IFERROR(INDEX(Equipements_STEU!$P$16:$P$72,SMALL(IF(Equipements_STEU!$J$16:$J$72="Pluviomètre",ROW(Equipements_STEU!$J$16:$J$72)-ROW(Equipements_STEU!$J$16)+1),ROW(1:1))),"")} | N43: {=IFERROR(INDEX(Equipements_STEU!$T$16:$T$72,SMALL(IF(Equipements_STEU!$J$16:$J$72="Pluviomètre",ROW(Equipements_STEU!$J$16:$J$72)-ROW(Equipements_STEU!$J$16)+1),ROW(1:1))),"")}
