Workbook
Name Asservissement: PARAM!$A$44:$A$46
Name CODE_SANDRE_3: PARAM!$I$4:$I$19
Name CODE_SANDRE_SCL: PARAM!$F$4:$F$7
Name CODE_SANDRE_STEU: PARAM!$E$4:$E$19
Name conditions_meteo: PARAM!$F$44:$F$46
Name Conformité: PARAM!$B$44:$B$48
Name Eq_h_controle: PARAM!$C$30:$C$32
Name EQUIPEMENT_PREL: PARAM!$B$4:$B$6
Name EQUIPEMENT_Q: PARAM!$A$4:$A$15
Name Frequence: PARAM!$E$44:$E$51
Name LISTE_1: PARAM!$A$21:$A$22
Name LISTE_1_a: #REF!
Name LISTE_2: PARAM!$B$21:$B$23
Name LISTE_3: PARAM!$C$21:$C$24
Name LISTE_4: PARAM!$D$21:$D$26
Name LISTE_5: PARAM!$F$21:$F$24
Name LISTE_6: PARAM!$G$21:$G$23
Name LISTE_7: PARAM!$H$21:$H$23
Name listeDebimetres: INDIRECT("Descriptif!"&ADDRESS(Descriptif!$AD$2,COLUMN(Descriptif!$AF$1))):INDEX(INDIRECT("Descriptif!AF"&Descriptif!$AD$2&":AF101"),COUNTIF(INDIRECT("Descriptif!AF"&Descriptif!$AD$2&":AF101"),"?*"))
Name listePluviometres: INDIRECT("Descriptif!"&ADDRESS(Descriptif!$AD$2,COLUMN(Descriptif!$AJ$1))):INDEX(INDIRECT("Descriptif!AJ"&Descriptif!$AD$2&":AJ101"),COUNTIF(INDIRECT("Descriptif!AJ"&Descriptif!$AD$2&":AJ101"),"?*"))
Name listePreleveurs: INDIRECT("Descriptif!"&ADDRESS(Descriptif!$AD$2,COLUMN(Descriptif!$AD$1))):INDEX(INDIRECT("Descriptif!AD"&Descriptif!$AD$2&":AD101"),COUNTIF(INDIRECT("Descriptif!AD"&Descriptif!$AD$2&":AD101"),"?*"))
Name listeSondeTemp: INDIRECT("Descriptif!"&ADDRESS(Descriptif!$AD$2,COLUMN(Descriptif!$AH$1))):INDEX(INDIRECT("Descriptif!AH"&Descriptif!$AD$2&":AH101"),COUNTIF(INDIRECT("Descriptif!AH"&Descriptif!$AD$2&":AH101"),"?*"))
Name Méthode: PARAM!$A$55:$A$57
Name Montage_sonde: PARAM!$G$44:$G$47
Name PLUVIO_SCL: Descriptif!$E$24:$E$24
Name Print_Area: LimitequantificationSDE!$A$1:$F$21
Name Print_Area: 'SeuilsComparaison-EMT'!$A$1:$K$29
Name Q_en_charge: PARAM!$A$30:$A$36
Name Q_Gravitaire: PARAM!$B$30:$B$39
Name Satisfaction: PARAM!$D$44:$D$46
Name Type_capteur: PARAM!$C$44:$C$48
Name Type_equipement: PARAM!$C$4:$C$7
Name Type_reseau: PARAM!$D$30:$D$32
Name TypeDeMesure: PARAM!$B$55:$B$56

Sheet Descriptif
AC1: Ne rien mettre dans cette colonne | AD1: Ne rien mettre dans cette colonne | AE1: Ne rien mettre dans cette colonne | AF1: Ne rien mettre dans cette colonne | AG1: Ne rien mettre dans cette colonne | AH1: Ne rien mettre dans cette colonne | AI1: Ne rien mettre dans cette colonne | AJ1: Ne rien mettre dans cette colonne
C2: CONTRÔLE ANNUEL DES DISPOSITIFS D'AUTOSURVEILLANCE DES SYSTÈMES D'ASSAINISSEMENT COLLECTIF | AC2: début données sys collect | AD2: =ROW(E13)+1 -> 14 | AE2: fin données sys collect | AF2: =ROW(D15)-1 -> 14 | AG2: pluvio SCL | AH2: =ROW(E22)+1 -> 23 | AI2: =ROW(D24)-1 -> 23
C3: NOM DU SYSTÈME D'ASSAINISSEMENT : | F3: BARJAC (30) | I3: NOM SYSTÈME DE TRAITEMENT : | L3: BARJAC (30) | N3: NOM SYSTÈME DE COLLECTE : | Q3: sys | S3: ORGANISME DE CONTRÔLE : | U3: CEREG Ingénierie | AC3: début données station | AD3: =ROW(E33)+1 -> 34 | AE3: fin données station | AF3: =ROW(D35)-1 -> 34 | AG3: pluvio STEU | AH3: =ROW(E42)+1 -> 43 | AI3: =ROW(D44)-1 -> 43
C4: CODE SANDRE DE L'AGGLOMERATION : | F4: eee | I4: CODE SANDRE DE LA STATION : | L4: 060930290002 | N4: CODE SANDRE DU RESEAU : | Q4: yyy | S4: NOM(S) CONTROLEUR(S) : | U4: control
C5: NOM DU MAITRE D'OUVRAGE : | F5: Commune de Barjac | I5: TYPE DE TRAITEMENT : | L5: Boues activée faible charge | N5: TYPE DE RESEAU | Q5: Mixte | S5: DATE(S) D'INTERVENTION : | U5: 46006
C6: EXPLOITANT DE LA STATION : | F6: Regie | I6: CAPACITE DE LA STATION : | L6: 5 000 EH | N6: EXPLOITANT DU RESEAU : | Q6: exp r | S6: CONDITION(S) METEO : | U6: pluie
C8: SYSTÈME DE COLLECTE
D10: Liste des équipements du système de collecte pour chaque point d’autosurveillance
H12: Les informations de codification sont à reprendre du MAS
E13: Actif | F13: Lien vers l'onglet de l'équipement | H13: Point réglementaire | I13: Localisation (cf. MAS) | J13: Code du point (cf MAS) | K13: Libellé de l'équipement | M13: Type d'équipement | O13: Type de matériel | Q13: Pluviométre de référence* | S13: Certaines informations d'un équipement ne sont pas modifiables. Au besoin il est préférable de supprimer et de recréer l'équipement. | AC13: Liste préleveurs | AE13: Liste débimètres | AG13: Liste thermo | AI13: Liste pluvio
AB14: =ROW(A14)- $AD$2 +1 -> 1 | AC14: =IF(AND($E14="Oui",$M14="Préleveur"),$F14,"") | AD14: {=IFERROR(INDEX($AC$14:$AC$102,SMALL(IF($AC$14:$AC$102<>"",ROW($AC$14:$AC$102)-ROW(INDIRECT("$AC$14"))+1),ROW(INDIRECT("A" & AB14 ) ))),"")} | AE14: =IF(AND($E14="Oui",LEFT($M14,10) ="Débitmètre"),$F14,"") | AF14: {=IFERROR(INDEX($AE$14:$AE$102,SMALL(IF($AE$14:$AE$102<>"",ROW($AE$14:$AE$102)-ROW(INDIRECT("$AE$14"))+1),ROW(INDIRECT("A" & AB14 ) ))),"")} | AG14: =IF(AND($E14="Oui",LEFT($M14,5) ="Sonde"),$F14,"") | AH14: {=IFERROR(INDEX($AG$14:$AG$102,SMALL(IF($AG$14:$AG$102<>"",ROW($AG$14:$AG$102)-ROW(INDIRECT("$AG$14"))+1),ROW(INDIRECT("A" & AB14 ) ))),"")} | AI14: =IF(AND($E14="Oui", $F14 <> "", $M14 = ""),$F14,"") | AJ14: {=IFERROR(INDEX($AI$14:$AI$102,SMALL(IF($AI$14:$AI$102<>"",ROW($AI$14:$AI$102)-ROW(INDIRECT("$AI$14"))+1),ROW(INDIRECT("A" & AB14 ) ))),"")}
E15: Ajouter un équipement réseau | K15: Si certains points A1 sont non équipés, veuillez les indiquer en commentaire | AB15: =ROW(A15)- $AD$2 +1 -> 2 | AC15: =IF(AND($E15="Oui",$M15="Préleveur"),$F15,"") | AD15: {=IFERROR(INDEX($AC$14:$AC$102,SMALL(IF($AC$14:$AC$102<>"",ROW($AC$14:$AC$102)-ROW(INDIRECT("$AC$14"))+1),ROW(INDIRECT("A" & AB15 ) ))),"")} | AE15: =IF(AND($E15="Oui",LEFT($M15,10) ="Débitmètre"),$F15,"") | AF15: {=IFERROR(INDEX($AE$14:$AE$102,SMALL(IF($AE$14:$AE$102<>"",ROW($AE$14:$AE$102)-ROW(INDIRECT("$AE$14"))+1),ROW(INDIRECT("A" & AB15 ) ))),"")} | AG15: =IF(AND($E15="Oui",LEFT($M15,5) ="Sonde"),$F15,"") | AH15: {=IFERROR(INDEX($AG$14:$AG$102,SMALL(IF($AG$14:$AG$102<>"",ROW($AG$14:$AG$102)-ROW(INDIRECT("$AG$14"))+1),ROW(INDIRECT("A" & AB15 ) ))),"")} | AI15: =IF(AND($E15="Oui", $F15 <> "", $M15 = ""),$F15,"") | AJ15: {=IFERROR(INDEX($AI$14:$AI$102,SMALL(IF($AI$14:$AI$102<>"",ROW($AI$14:$AI$102)-ROW(INDIRECT("$AI$14"))+1),ROW(INDIRECT("A" & AB15 ) ))),"")}
AB16: =ROW(A16)- $AD$2 +1 -> 3 | AC16: =IF(AND($E16="Oui",$M16="Préleveur"),$F16,"") | AD16: {=IFERROR(INDEX($AC$14:$AC$102,SMALL(IF($AC$14:$AC$102<>"",ROW($AC$14:$AC$102)-ROW(INDIRECT("$AC$14"))+1),ROW(INDIRECT("A" & AB16 ) ))),"")} | AE16: =IF(AND($E16="Oui",LEFT($M16,10) ="Débitmètre"),$F16,"") | AF16: {=IFERROR(INDEX($AE$14:$AE$102,SMALL(IF($AE$14:$AE$102<>"",ROW($AE$14:$AE$102)-ROW(INDIRECT("$AE$14"))+1),ROW(INDIRECT("A" & AB16 ) ))),"")} | AG16: =IF(AND($E16="Oui",LEFT($M16,5) ="Sonde"),$F16,"") | AH16: {=IFERROR(INDEX($AG$14:$AG$102,SMALL(IF($AG$14:$AG$102<>"",ROW($AG$14:$AG$102)-ROW(INDIRECT("$AG$14"))+1),ROW(INDIRECT("A" & AB16 ) ))),"")} | AI16: =IF(AND($E16="Oui", $F16 <> "", $M16 = ""),$F16,"") | AJ16: {=IFERROR(INDEX($AI$14:$AI$102,SMALL(IF($AI$14:$AI$102<>"",ROW($AI$14:$AI$102)-ROW(INDIRECT("$AI$14"))+1),ROW(INDIRECT("A" & AB16 ) ))),"")}
AB17: =ROW(A17)- $AD$2 +1 -> 4 | AC17: =IF(AND($E17="Oui",$M17="Préleveur"),$F17,"") | AD17: {=IFERROR(INDEX($AC$14:$AC$102,SMALL(IF($AC$14:$AC$102<>"",ROW($AC$14:$AC$102)-ROW(INDIRECT("$AC$14"))+1),ROW(INDIRECT("A" & AB17 ) ))),"")} | AE17: =IF(AND($E17="Oui",LEFT($M17,10) ="Débitmètre"),$F17,"") | AF17: {=IFERROR(INDEX($AE$14:$AE$102,SMALL(IF($AE$14:$AE$102<>"",ROW($AE$14:$AE$102)-ROW(INDIRECT("$AE$14"))+1),ROW(INDIRECT("A" & AB17 ) ))),"")} | AG17: =IF(AND($E17="Oui",LEFT($M17,5) ="Sonde"),$F17,"") | AH17: {=IFERROR(INDEX($AG$14:$AG$102,SMALL(IF($AG$14:$AG$102<>"",ROW($AG$14:$AG$102)-ROW(INDIRECT("$AG$14"))+1),ROW(INDIRECT("A" & AB17 ) ))),"")} | AI17: =IF(AND($E17="Oui", $F17 <> "", $M17 = ""),$F17,"") | AJ17: {=IFERROR(INDEX($AI$14:$AI$102,SMALL(IF($AI$14:$AI$102<>"",ROW($AI$14:$AI$102)-ROW(INDIRECT("$AI$14"))+1),ROW(INDIRECT("A" & AB17 ) ))),"")}
AB18: =ROW(A18)- $AD$2 +1 -> 5 | AC18: =IF(AND($E18="Oui",$M18="Préleveur"),$F18,"") | AD18: {=IFERROR(INDEX($AC$14:$AC$102,SMALL(IF($AC$14:$AC$102<>"",ROW($AC$14:$AC$102)-ROW(INDIRECT("$AC$14"))+1),ROW(INDIRECT("A" & AB18 ) ))),"")} | AE18: =IF(AND($E18="Oui",LEFT($M18,10) ="Débitmètre"),$F18,"") | AF18: {=IFERROR(INDEX($AE$14:$AE$102,SMALL(IF($AE$14:$AE$102<>"",ROW($AE$14:$AE$102)-ROW(INDIRECT("$AE$14"))+1),ROW(INDIRECT("A" & AB18 ) ))),"")} | AG18: =IF(AND($E18="Oui",LEFT($M18,5) ="Sonde"),$F18,"") | AH18: {=IFERROR(INDEX($AG$14:$AG$102,SMALL(IF($AG$14:$AG$102<>"",ROW($AG$14:$AG$102)-ROW(INDIRECT("$AG$14"))+1),ROW(INDIRECT("A" & AB18 ) ))),"")} | AI18: =IF(AND($E18="Oui", $F18 <> "", $M18 = ""),$F18,"") | AJ18: {=IFERROR(INDEX($AI$14:$AI$102,SMALL(IF($AI$14:$AI$102<>"",ROW($AI$14:$AI$102)-ROW(INDIRECT("$AI$14"))+1),ROW(INDIRECT("A" & AB18 ) ))),"")}
AB19: =ROW(A19)- $AD$2 +1 -> 6 | AC19: =IF(AND($E19="Oui",$M19="Préleveur"),$F19,"") | AD19: {=IFERROR(INDEX($AC$14:$AC$102,SMALL(IF($AC$14:$AC$102<>"",ROW($AC$14:$AC$102)-ROW(INDIRECT("$AC$14"))+1),ROW(INDIRECT("A" & AB19 ) ))),"")} | AE19: =IF(AND($E19="Oui",LEFT($M19,10) ="Débitmètre"),$F19,"") | AF19: {=IFERROR(INDEX($AE$14:$AE$102,SMALL(IF($AE$14:$AE$102<>"",ROW($AE$14:$AE$102)-ROW(INDIRECT("$AE$14"))+1),ROW(INDIRECT("A" & AB19 ) ))),"")} | AG19: =IF(AND($E19="Oui",LEFT($M19,5) ="Sonde"),$F19,"") | AH19: {=IFERROR(INDEX($AG$14:$AG$102,SMALL(IF($AG$14:$AG$102<>"",ROW($AG$14:$AG$102)-ROW(INDIRECT("$AG$14"))+1),ROW(INDIRECT("A" & AB19 ) ))),"")} | AI19: =IF(AND($E19="Oui", $F19 <> "", $M19 = ""),$F19,"") | AJ19: {=IFERROR(INDEX($AI$14:$AI$102,SMALL(IF($AI$14:$AI$102<>"",ROW($AI$14:$AI$102)-ROW(INDIRECT("$AI$14"))+1),ROW(INDIRECT("A" & AB19 ) ))),"")}
D20: Liste des pluviomètres de référence du réseau | AB20: =ROW(A20)- $AD$2 +1 -> 7 | AC20: =IF(AND($E20="Oui",$M20="Préleveur"),$F20,"") | AD20: {=IFERROR(INDEX($AC$14:$AC$102,SMALL(IF($AC$14:$AC$102<>"",ROW($AC$14:$AC$102)-ROW(INDIRECT("$AC$14"))+1),ROW(INDIRECT("A" & AB20 ) ))),"")} | AE20: =IF(AND($E20="Oui",LEFT($M20,10) ="Débitmètre"),$F20,"") | AF20: {=IFERROR(INDEX($AE$14:$AE$102,SMALL(IF($AE$14:$AE$102<>"",ROW($AE$14:$AE$102)-ROW(INDIRECT("$AE$14"))+1),ROW(INDIRECT("A" & AB20 ) ))),"")} | AG20: =IF(AND($E20="Oui",LEFT($M20,5) ="Sonde"),$F20,"") | AH20: {=IFERROR(INDEX($AG$14:$AG$102,SMALL(IF($AG$14:$AG$102<>"",ROW($AG$14:$AG$102)-ROW(INDIRECT("$AG$14"))+1),ROW(INDIRECT("A" & AB20 ) ))),"")} | AI20: =IF(AND($E20="Oui", $F20 <> "", $M20 = ""),$F20,"") | AJ20: {=IFERROR(INDEX($AI$14:$AI$102,SMALL(IF($AI$14:$AI$102<>"",ROW($AI$14:$AI$102)-ROW(INDIRECT("$AI$14"))+1),ROW(INDIRECT("A" & AB20 ) ))),"")}
AB21: =ROW(A21)- $AD$2 +1 -> 8 | AC21: =IF(AND($E21="Oui",$M21="Préleveur"),$F21,"") | AD21: {=IFERROR(INDEX($AC$14:$AC$102,SMALL(IF($AC$14:$AC$102<>"",ROW($AC$14:$AC$102)-ROW(INDIRECT("$AC$14"))+1),ROW(INDIRECT("A" & AB21 ) ))),"")} | AE21: =IF(AND($E21="Oui",LEFT($M21,10) ="Débitmètre"),$F21,"") | AF21: {=IFERROR(INDEX($AE$14:$AE$102,SMALL(IF($AE$14:$AE$102<>"",ROW($AE$14:$AE$102)-ROW(INDIRECT("$AE$14"))+1),ROW(INDIRECT("A" & AB21 ) ))),"")} | AG21: =IF(AND($E21="Oui",LEFT($M21,5) ="Sonde"),$F21,"") | AH21: {=IFERROR(INDEX($AG$14:$AG$102,SMALL(IF($AG$14:$AG$102<>"",ROW($AG$14:$AG$102)-ROW(INDIRECT("$AG$14"))+1),ROW(INDIRECT("A" & AB21 ) ))),"")} | AI21: =IF(AND($E21="Oui", $F21 <> "", $M21 = ""),$F21,"") | AJ21: {=IFERROR(INDEX($AI$14:$AI$102,SMALL(IF($AI$14:$AI$102<>"",ROW($AI$14:$AI$102)-ROW(INDIRECT("$AI$14"))+1),ROW(INDIRECT("A" & AB21 ) ))),"")}
E22: Actif | F22: Lien vers l'onglet de l'équipement | AB22: =ROW(A22)- $AD$2 +1 -> 9 | AC22: =IF(AND($E22="Oui",$M22="Préleveur"),$F22,"") | AD22: {=IFERROR(INDEX($AC$14:$AC$102,SMALL(IF($AC$14:$AC$102<>"",ROW($AC$14:$AC$102)-ROW(INDIRECT("$AC$14"))+1),ROW(INDIRECT("A" & AB22 ) ))),"")} | AE22: =IF(AND($E22="Oui",LEFT($M22,10) ="Débitmètre"),$F22,"") | AF22: {=IFERROR(INDEX($AE$14:$AE$102,SMALL(IF($AE$14:$AE$102<>"",ROW($AE$14:$AE$102)-ROW(INDIRECT("$AE$14"))+1),ROW(INDIRECT("A" & AB22 ) ))),"")} | AG22: =IF(AND($E22="Oui",LEFT($M22,5) ="Sonde"),$F22,"") | AH22: {=IFERROR(INDEX($AG$14:$AG$102,SMALL(IF($AG$14:$AG$102<>"",ROW($AG$14:$AG$102)-ROW(INDIRECT("$AG$14"))+1),ROW(INDIRECT("A" & AB22 ) ))),"")} | AI22: =IF(AND($E22="Oui", $F22 <> "", $M22 = ""),$F22,"") | AJ22: {=IFERROR(INDEX($AI$14:$AI$102,SMALL(IF($AI$14:$AI$102<>"",ROW($AI$14:$AI$102)-ROW(INDIRECT("$AI$14"))+1),ROW(INDIRECT("A" & AB22 ) ))),"")}
AB23: =ROW(A23)- $AD$2 +1 -> 10 | AC23: =IF(AND($E23="Oui",$M23="Préleveur"),$F23,"") | AD23: {=IFERROR(INDEX($AC$14:$AC$102,SMALL(IF($AC$14:$AC$102<>"",ROW($AC$14:$AC$102)-ROW(INDIRECT("$AC$14"))+1),ROW(INDIRECT("A" & AB23 ) ))),"")} | AE23: =IF(AND($E23="Oui",LEFT($M23,10) ="Débitmètre"),$F23,"") | AF23: {=IFERROR(INDEX($AE$14:$AE$102,SMALL(IF($AE$14:$AE$102<>"",ROW($AE$14:$AE$102)-ROW(INDIRECT("$AE$14"))+1),ROW(INDIRECT("A" & AB23 ) ))),"")} | AG23: =IF(AND($E23="Oui",LEFT($M23,5) ="Sonde"),$F23,"") | AH23: {=IFERROR(INDEX($AG$14:$AG$102,SMALL(IF($AG$14:$AG$102<>"",ROW($AG$14:$AG$102)-ROW(INDIRECT("$AG$14"))+1),ROW(INDIRECT("A" & AB23 ) ))),"")} | AI23: =IF(AND($E23="Oui", $F23 <> "", $M23 = ""),$F23,"") | AJ23: {=IFERROR(INDEX($AI$14:$AI$102,SMALL(IF($AI$14:$AI$102<>"",ROW($AI$14:$AI$102)-ROW(INDIRECT("$AI$14"))+1),ROW(INDIRECT("A" & AB23 ) ))),"")}
E24: Ajouter un pluviomètre réseau | K24: Si pas de pluviomètre, veuillez ajouter en commentaire la provenance des données : | AB24: =ROW(A24)- $AD$2 +1 -> 11 | AC24: =IF(AND($E24="Oui",$M24="Préleveur"),$F24,"") | AD24: {=IFERROR(INDEX($AC$14:$AC$102,SMALL(IF($AC$14:$AC$102<>"",ROW($AC$14:$AC$102)-ROW(INDIRECT("$AC$14"))+1),ROW(INDIRECT("A" & AB24 ) ))),"")} | AE24: =IF(AND($E24="Oui",LEFT($M24,10) ="Débitmètre"),$F24,"") | AF24: {=IFERROR(INDEX($AE$14:$AE$102,SMALL(IF($AE$14:$AE$102<>"",ROW($AE$14:$AE$102)-ROW(INDIRECT("$AE$14"))+1),ROW(INDIRECT("A" & AB24 ) ))),"")} | AG24: =IF(AND($E24="Oui",LEFT($M24,5) ="Sonde"),$F24,"") | AH24: {=IFERROR(INDEX($AG$14:$AG$102,SMALL(IF($AG$14:$AG$102<>"",ROW($AG$14:$AG$102)-ROW(INDIRECT("$AG$14"))+1),ROW(INDIRECT("A" & AB24 ) ))),"")} | AI24: =IF(AND($E24="Oui", $F24 <> "", $M24 = ""),$F24,"") | AJ24: {=IFERROR(INDEX($AI$14:$AI$102,SMALL(IF($AI$14:$AI$102<>"",ROW($AI$14:$AI$102)-ROW(INDIRECT("$AI$14"))+1),ROW(INDIRECT("A" & AB24 ) ))),"")}
AB25: =ROW(A25)- $AD$2 +1 -> 12 | AC25: =IF(AND($E25="Oui",$M25="Préleveur"),$F25,"") | AD25: {=IFERROR(INDEX($AC$14:$AC$102,SMALL(IF($AC$14:$AC$102<>"",ROW($AC$14:$AC$102)-ROW(INDIRECT("$AC$14"))+1),ROW(INDIRECT("A" & AB25 ) ))),"")} | AE25: =IF(AND($E25="Oui",LEFT($M25,10) ="Débitmètre"),$F25,"") | AF25: {=IFERROR(INDEX($AE$14:$AE$102,SMALL(IF($AE$14:$AE$102<>"",ROW($AE$14:$AE$102)-ROW(INDIRECT("$AE$14"))+1),ROW(INDIRECT("A" & AB25 ) ))),"")} | AG25: =IF(AND($E25="Oui",LEFT($M25,5) ="Sonde"),$F25,"") | AH25: {=IFERROR(INDEX($AG$14:$AG$102,SMALL(IF($AG$14:$AG$102<>"",ROW($AG$14:$AG$102)-ROW(INDIRECT("$AG$14"))+1),ROW(INDIRECT("A" & AB25 ) ))),"")} | AI25: =IF(AND($E25="Oui", $F25 <> "", $M25 = ""),$F25,"") | AJ25: {=IFERROR(INDEX($AI$14:$AI$102,SMALL(IF($AI$14:$AI$102<>"",ROW($AI$14:$AI$102)-ROW(INDIRECT("$AI$14"))+1),ROW(INDIRECT("A" & AB25 ) ))),"")}
AB26: =ROW(A26)- $AD$2 +1 -> 13 | AC26: =IF(AND($E26="Oui",$M26="Préleveur"),$F26,"") | AD26: {=IFERROR(INDEX($AC$14:$AC$102,SMALL(IF($AC$14:$AC$102<>"",ROW($AC$14:$AC$102)-ROW(INDIRECT("$AC$14"))+1),ROW(INDIRECT("A" & AB26 ) ))),"")} | AE26: =IF(AND($E26="Oui",LEFT($M26,10) ="Débitmètre"),$F26,"") | AF26: {=IFERROR(INDEX($AE$14:$AE$102,SMALL(IF($AE$14:$AE$102<>"",ROW($AE$14:$AE$102)-ROW(INDIRECT("$AE$14"))+1),ROW(INDIRECT("A" & AB26 ) ))),"")} | AG26: =IF(AND($E26="Oui",LEFT($M26,5) ="Sonde"),$F26,"") | AH26: {=IFERROR(INDEX($AG$14:$AG$102,SMALL(IF($AG$14:$AG$102<>"",ROW($AG$14:$AG$102)-ROW(INDIRECT("$AG$14"))+1),ROW(INDIRECT("A" & AB26 ) ))),"")} | AI26: =IF(AND($E26="Oui", $F26 <> "", $M26 = ""),$F26,"") | AJ26: {=IFERROR(INDEX($AI$14:$AI$102,SMALL(IF($AI$14:$AI$102<>"",ROW($AI$14:$AI$102)-ROW(INDIRECT("$AI$14"))+1),ROW(INDIRECT("A" & AB26 ) ))),"")}
AB27: =ROW(A27)- $AD$2 +1 -> 14 | AC27: =IF(AND($E27="Oui",$M27="Préleveur"),$F27,"") | AD27: {=IFERROR(INDEX($AC$14:$AC$102,SMALL(IF($AC$14:$AC$102<>"",ROW($AC$14:$AC$102)-ROW(INDIRECT("$AC$14"))+1),ROW(INDIRECT("A" & AB27 ) ))),"")} | AE27: =IF(AND($E27="Oui",LEFT($M27,10) ="Débitmètre"),$F27,"") | AF27: {=IFERROR(INDEX($AE$14:$AE$102,SMALL(IF($AE$14:$AE$102<>"",ROW($AE$14:$AE$102)-ROW(INDIRECT("$AE$14"))+1),ROW(INDIRECT("A" & AB27 ) ))),"")} | AG27: =IF(AND($E27="Oui",LEFT($M27,5) ="Sonde"),$F27,"") | AH27: {=IFERROR(INDEX($AG$14:$AG$102,SMALL(IF($AG$14:$AG$102<>"",ROW($AG$14:$AG$102)-ROW(INDIRECT("$AG$14"))+1),ROW(INDIRECT("A" & AB27 ) ))),"")} | AI27: =IF(AND($E27="Oui", $F27 <> "", $M27 = ""),$F27,"") | AJ27: {=IFERROR(INDEX($AI$14:$AI$102,SMALL(IF($AI$14:$AI$102<>"",ROW($AI$14:$AI$102)-ROW(INDIRECT("$AI$14"))+1),ROW(INDIRECT("A" & AB27 ) ))),"")}
AB28: =ROW(A28)- $AD$2 +1 -> 15 | AC28: =IF(AND($E28="Oui",$M28="Préleveur"),$F28,"") | AD28: {=IFERROR(INDEX($AC$14:$AC$102,SMALL(IF($AC$14:$AC$102<>"",ROW($AC$14:$AC$102)-ROW(INDIRECT("$AC$14"))+1),ROW(INDIRECT("A" & AB28 ) ))),"")} | AE28: =IF(AND($E28="Oui",LEFT($M28,10) ="Débitmètre"),$F28,"") | AF28: {=IFERROR(INDEX($AE$14:$AE$102,SMALL(IF($AE$14:$AE$102<>"",ROW($AE$14:$AE$102)-ROW(INDIRECT("$AE$14"))+1),ROW(INDIRECT("A" & AB28 ) ))),"")} | AG28: =IF(AND($E28="Oui",LEFT($M28,5) ="Sonde"),$F28,"") | AH28: {=IFERROR(INDEX($AG$14:$AG$102,SMALL(IF($AG$14:$AG$102<>"",ROW($AG$14:$AG$102)-ROW(INDIRECT("$AG$14"))+1),ROW(INDIRECT("A" & AB28 ) ))),"")} | AI28: =IF(AND($E28="Oui", $F28 <> "", $M28 = ""),$F28,"") | AJ28: {=IFERROR(INDEX($AI$14:$AI$102,SMALL(IF($AI$14:$AI$102<>"",ROW($AI$14:$AI$102)-ROW(INDIRECT("$AI$14"))+1),ROW(INDIRECT("A" & AB28 ) ))),"")}
C29: SYSTÈME DE TRAITEMENT | AB29: =ROW(A29)- $AD$2 +1 -> 16 | AC29: =IF(AND($E29="Oui",$M29="Préleveur"),$F29,"") | AD29: {=IFERROR(INDEX($AC$14:$AC$102,SMALL(IF($AC$14:$AC$102<>"",ROW($AC$14:$AC$102)-ROW(INDIRECT("$AC$14"))+1),ROW(INDIRECT("A" & AB29 ) ))),"")} | AE29: =IF(AND($E29="Oui",LEFT($M29,10) ="Débitmètre"),$F29,"") | AF29: {=IFERROR(INDEX($AE$14:$AE$102,SMALL(IF($AE$14:$AE$102<>"",ROW($AE$14:$AE$102)-ROW(INDIRECT("$AE$14"))+1),ROW(INDIRECT("A" & AB29 ) ))),"")} | AG29: =IF(AND($E29="Oui",LEFT($M29,5) ="Sonde"),$F29,"") | AH29: {=IFERROR(INDEX($AG$14:$AG$102,SMALL(IF($AG$14:$AG$102<>"",ROW($AG$14:$AG$102)-ROW(INDIRECT("$AG$14"))+1),ROW(INDIRECT("A" & AB29 ) ))),"")} | AI29: =IF(AND($E29="Oui", $F29 <> "", $M29 = ""),$F29,"") | AJ29: {=IFERROR(INDEX($AI$14:$AI$102,SMALL(IF($AI$14:$AI$102<>"",ROW($AI$14:$AI$102)-ROW(INDIRECT("$AI$14"))+1),ROW(INDIRECT("A" & AB29 ) ))),"")}
AB30: =ROW(A30)- $AD$2 +1 -> 17 | AC30: =IF(AND($E30="Oui",$M30="Préleveur"),$F30,"") | AD30: {=IFERROR(INDEX($AC$14:$AC$102,SMALL(IF($AC$14:$AC$102<>"",ROW($AC$14:$AC$102)-ROW(INDIRECT("$AC$14"))+1),ROW(INDIRECT("A" & AB30 ) ))),"")} | AE30: =IF(AND($E30="Oui",LEFT($M30,10) ="Débitmètre"),$F30,"") | AF30: {=IFERROR(INDEX($AE$14:$AE$102,SMALL(IF($AE$14:$AE$102<>"",ROW($AE$14:$AE$102)-ROW(INDIRECT("$AE$14"))+1),ROW(INDIRECT("A" & AB30 ) ))),"")} | AG30: =IF(AND($E30="Oui",LEFT($M30,5) ="Sonde"),$F30,"") | AH30: {=IFERROR(INDEX($AG$14:$AG$102,SMALL(IF($AG$14:$AG$102<>"",ROW($AG$14:$AG$102)-ROW(INDIRECT("$AG$14"))+1),ROW(INDIRECT("A" & AB30 ) ))),"")} | AI30: =IF(AND($E30="Oui", $F30 <> "", $M30 = ""),$F30,"") | AJ30: {=IFERROR(INDEX($AI$14:$AI$102,SMALL(IF($AI$14:$AI$102<>"",ROW($AI$14:$AI$102)-ROW(INDIRECT("$AI$14"))+1),ROW(INDIRECT("A" & AB30 ) ))),"")}
D31: Liste des équipements du système de traitement pour chaque point d’autosurveillance | AB31: =ROW(A31)- $AD$2 +1 -> 18 | AC31: =IF(AND($E31="Oui",$M31="Préleveur"),$F31,"") | AD31: {=IFERROR(INDEX($AC$14:$AC$102,SMALL(IF($AC$14:$AC$102<>"",ROW($AC$14:$AC$102)-ROW(INDIRECT("$AC$14"))+1),ROW(INDIRECT("A" & AB31 ) ))),"")} | AE31: =IF(AND($E31="Oui",LEFT($M31,10) ="Débitmètre"),$F31,"") | AF31: {=IFERROR(INDEX($AE$14:$AE$102,SMALL(IF($AE$14:$AE$102<>"",ROW($AE$14:$AE$102)-ROW(INDIRECT("$AE$14"))+1),ROW(INDIRECT("A" & AB31 ) ))),"")} | AG31: =IF(AND($E31="Oui",LEFT($M31,5) ="Sonde"),$F31,"") | AH31: {=IFERROR(INDEX($AG$14:$AG$102,SMALL(IF($AG$14:$AG$102<>"",ROW($AG$14:$AG$102)-ROW(INDIRECT("$AG$14"))+1),ROW(INDIRECT("A" & AB31 ) ))),"")} | AI31: =IF(AND($E31="Oui", $F31 <> "", $M31 = ""),$F31,"") | AJ31: {=IFERROR(INDEX($AI$14:$AI$102,SMALL(IF($AI$14:$AI$102<>"",ROW($AI$14:$AI$102)-ROW(INDIRECT("$AI$14"))+1),ROW(INDIRECT("A" & AB31 ) ))),"")}
AB32: =ROW(A32)- $AD$2 +1 -> 19 | AC32: =IF(AND($E32="Oui",$M32="Préleveur"),$F32,"") | AD32: {=IFERROR(INDEX($AC$14:$AC$102,SMALL(IF($AC$14:$AC$102<>"",ROW($AC$14:$AC$102)-ROW(INDIRECT("$AC$14"))+1),ROW(INDIRECT("A" & AB32 ) ))),"")} | AE32: =IF(AND($E32="Oui",LEFT($M32,10) ="Débitmètre"),$F32,"") | AF32: {=IFERROR(INDEX($AE$14:$AE$102,SMALL(IF($AE$14:$AE$102<>"",ROW($AE$14:$AE$102)-ROW(INDIRECT("$AE$14"))+1),ROW(INDIRECT("A" & AB32 ) ))),"")} | AG32: =IF(AND($E32="Oui",LEFT($M32,5) ="Sonde"),$F32,"") | AH32: {=IFERROR(INDEX($AG$14:$AG$102,SMALL(IF($AG$14:$AG$102<>"",ROW($AG$14:$AG$102)-ROW(INDIRECT("$AG$14"))+1),ROW(INDIRECT("A" & AB32 ) ))),"")} | AI32: =IF(AND($E32="Oui", $F32 <> "", $M32 = ""),$F32,"") | AJ32: {=IFERROR(INDEX($AI$14:$AI$102,SMALL(IF($AI$14:$AI$102<>"",ROW($AI$14:$AI$102)-ROW(INDIRECT("$AI$14"))+1),ROW(INDIRECT("A" & AB32 ) ))),"")}
E33: Actif | F33: Lien vers l'onglet de l'équipement | H33: Point réglementaire | I33: Localisation (cf. MAS) | J33: Code du point (cf MAS) | K33: Libellé de l'équipement | M33: Type d'équipement | O33: Type de matériel | R33: Certaines informations d'un équipement ne sont pas modifiables. Au besoin il est préférable de supprimer et de recréer l'équipement. | AB33: =ROW(A33)- $AD$2 +1 -> 20 | AC33: =IF(AND($E33="Oui",$M33="Préleveur"),$F33,"") | AD33: {=IFERROR(INDEX($AC$14:$AC$102,SMALL(IF($AC$14:$AC$102<>"",ROW($AC$14:$AC$102)-ROW(INDIRECT("$AC$14"))+1),ROW(INDIRECT("A" & AB33 ) ))),"")} | AE33: =IF(AND($E33="Oui",LEFT($M33,10) ="Débitmètre"),$F33,"") | AF33: {=IFERROR(INDEX($AE$14:$AE$102,SMALL(IF($AE$14:$AE$102<>"",ROW($AE$14:$AE$102)-ROW(INDIRECT("$AE$14"))+1),ROW(INDIRECT("A" & AB33 ) ))),"")} | AG33: =IF(AND($E33="Oui",LEFT($M33,5) ="Sonde"),$F33,"") | AH33: {=IFERROR(INDEX($AG$14:$AG$102,SMALL(IF($AG$14:$AG$102<>"",ROW($AG$14:$AG$102)-ROW(INDIRECT("$AG$14"))+1),ROW(INDIRECT("A" & AB33 ) ))),"")} | AI33: =IF(AND($E33="Oui", $F33 <> "", $M33 = ""),$F33,"") | AJ33: {=IFERROR(INDEX($AI$14:$AI$102,SMALL(IF($AI$14:$AI$102<>"",ROW($AI$14:$AI$102)-ROW(INDIRECT("$AI$14"))+1),ROW(INDIRECT("A" & AB33 ) ))),"")}
AB34: =ROW(A34)- $AD$2 +1 -> 21 | AC34: =IF(AND($E34="Oui",$M34="Préleveur"),$F34,"") | AD34: {=IFERROR(INDEX($AC$14:$AC$102,SMALL(IF($AC$14:$AC$102<>"",ROW($AC$14:$AC$102)-ROW(INDIRECT("$AC$14"))+1),ROW(INDIRECT("A" & AB34 ) ))),"")} | AE34: =IF(AND($E34="Oui",LEFT($M34,10) ="Débitmètre"),$F34,"") | AF34: {=IFERROR(INDEX($AE$14:$AE$102,SMALL(IF($AE$14:$AE$102<>"",ROW($AE$14:$AE$102)-ROW(INDIRECT("$AE$14"))+1),ROW(INDIRECT("A" & AB34 ) ))),"")} | AG34: =IF(AND($E34="Oui",LEFT($M34,5) ="Sonde"),$F34,"") | AH34: {=IFERROR(INDEX($AG$14:$AG$102,SMALL(IF($AG$14:$AG$102<>"",ROW($AG$14:$AG$102)-ROW(INDIRECT("$AG$14"))+1),ROW(INDIRECT("A" & AB34 ) ))),"")} | AI34: =IF(AND($E34="Oui", $F34 <> "", $M34 = ""),$F34,"") | AJ34: {=IFERROR(INDEX($AI$14:$AI$102,SMALL(IF($AI$14:$AI$102<>"",ROW($AI$14:$AI$102)-ROW(INDIRECT("$AI$14"))+1),ROW(INDIRECT("A" & AB34 ) ))),"")}
E35: Ajouter un équipement station | K35: Si certains points A1 sont non équipés, veuillez les indiquer en commentaire | AB35: =ROW(A35)- $AD$2 +1 -> 22 | AC35: =IF(AND($E35="Oui",$M35="Préleveur"),$F35,"") | AD35: {=IFERROR(INDEX($AC$14:$AC$102,SMALL(IF($AC$14:$AC$102<>"",ROW($AC$14:$AC$102)-ROW(INDIRECT("$AC$14"))+1),ROW(INDIRECT("A" & AB35 ) ))),"")} | AE35: =IF(AND($E35="Oui",LEFT($M35,10) ="Débitmètre"),$F35,"") | AF35: {=IFERROR(INDEX($AE$14:$AE$102,SMALL(IF($AE$14:$AE$102<>"",ROW($AE$14:$AE$102)-ROW(INDIRECT("$AE$14"))+1),ROW(INDIRECT("A" & AB35 ) ))),"")} | AG35: =IF(AND($E35="Oui",LEFT($M35,5) ="Sonde"),$F35,"") | AH35: {=IFERROR(INDEX($AG$14:$AG$102,SMALL(IF($AG$14:$AG$102<>"",ROW($AG$14:$AG$102)-ROW(INDIRECT("$AG$14"))+1),ROW(INDIRECT("A" & AB35 ) ))),"")} | AI35: =IF(AND($E35="Oui", $F35 <> "", $M35 = ""),$F35,"") | AJ35: {=IFERROR(INDEX($AI$14:$AI$102,SMALL(IF($AI$14:$AI$102<>"",ROW($AI$14:$AI$102)-ROW(INDIRECT("$AI$14"))+1),ROW(INDIRECT("A" & AB35 ) ))),"")}
AB36: =ROW(A36)- $AD$2 +1 -> 23 | AC36: =IF(AND($E36="Oui",$M36="Préleveur"),$F36,"") | AD36: {=IFERROR(INDEX($AC$14:$AC$102,SMALL(IF($AC$14:$AC$102<>"",ROW($AC$14:$AC$102)-ROW(INDIRECT("$AC$14"))+1),ROW(INDIRECT("A" & AB36 ) ))),"")} | AE36: =IF(AND($E36="Oui",LEFT($M36,10) ="Débitmètre"),$F36,"") | AF36: {=IFERROR(INDEX($AE$14:$AE$102,SMALL(IF($AE$14:$AE$102<>"",ROW($AE$14:$AE$102)-ROW(INDIRECT("$AE$14"))+1),ROW(INDIRECT("A" & AB36 ) ))),"")} | AG36: =IF(AND($E36="Oui",LEFT($M36,5) ="Sonde"),$F36,"") | AH36: {=IFERROR(INDEX($AG$14:$AG$102,SMALL(IF($AG$14:$AG$102<>"",ROW($AG$14:$AG$102)-ROW(INDIRECT("$AG$14"))+1),ROW(INDIRECT("A" & AB36 ) ))),"")} | AI36: =IF(AND($E36="Oui", $F36 <> "", $M36 = ""),$F36,"") | AJ36: {=IFERROR(INDEX($AI$14:$AI$102,SMALL(IF($AI$14:$AI$102<>"",ROW($AI$14:$AI$102)-ROW(INDIRECT("$AI$14"))+1),ROW(INDIRECT("A" & AB36 ) ))),"")}
AB37: =ROW(A37)- $AD$2 +1 -> 24 | AC37: =IF(AND($E37="Oui",$M37="Préleveur"),$F37,"") | AD37: {=IFERROR(INDEX($AC$14:$AC$102,SMALL(IF($AC$14:$AC$102<>"",ROW($AC$14:$AC$102)-ROW(INDIRECT("$AC$14"))+1),ROW(INDIRECT("A" & AB37 ) ))),"")} | AE37: =IF(AND($E37="Oui",LEFT($M37,10) ="Débitmètre"),$F37,"") | AF37: {=IFERROR(INDEX($AE$14:$AE$102,SMALL(IF($AE$14:$AE$102<>"",ROW($AE$14:$AE$102)-ROW(INDIRECT("$AE$14"))+1),ROW(INDIRECT("A" & AB37 ) ))),"")} | AG37: =IF(AND($E37="Oui",LEFT($M37,5) ="Sonde"),$F37,"") | AH37: {=IFERROR(INDEX($AG$14:$AG$102,SMALL(IF($AG$14:$AG$102<>"",ROW($AG$14:$AG$102)-ROW(INDIRECT("$AG$14"))+1),ROW(INDIRECT("A" & AB37 ) ))),"")} | AI37: =IF(AND($E37="Oui", $F37 <> "", $M37 = ""),$F37,"") | AJ37: {=IFERROR(INDEX($AI$14:$AI$102,SMALL(IF($AI$14:$AI$102<>"",ROW($AI$14:$AI$102)-ROW(INDIRECT("$AI$14"))+1),ROW(INDIRECT("A" & AB37 ) ))),"")}
AB38: =ROW(A38)- $AD$2 +1 -> 25 | AC38: =IF(AND($E38="Oui",$M38="Préleveur"),$F38,"") | AD38: {=IFERROR(INDEX($AC$14:$AC$102,SMALL(IF($AC$14:$AC$102<>"",ROW($AC$14:$AC$102)-ROW(INDIRECT("$AC$14"))+1),ROW(INDIRECT("A" & AB38 ) ))),"")} | AE38: =IF(AND($E38="Oui",LEFT($M38,10) ="Débitmètre"),$F38,"") | AF38: {=IFERROR(INDEX($AE$14:$AE$102,SMALL(IF($AE$14:$AE$102<>"",ROW($AE$14:$AE$102)-ROW(INDIRECT("$AE$14"))+1),ROW(INDIRECT("A" & AB38 ) ))),"")} | AG38: =IF(AND($E38="Oui",LEFT($M38,5) ="Sonde"),$F38,"") | AH38: {=IFERROR(INDEX($AG$14:$AG$102,SMALL(IF($AG$14:$AG$102<>"",ROW($AG$14:$AG$102)-ROW(INDIRECT("$AG$14"))+1),ROW(INDIRECT("A" & AB38 ) ))),"")} | AI38: =IF(AND($E38="Oui", $F38 <> "", $M38 = ""),$F38,"") | AJ38: {=IFERROR(INDEX($AI$14:$AI$102,SMALL(IF($AI$14:$AI$102<>"",ROW($AI$14:$AI$102)-ROW(INDIRECT("$AI$14"))+1),ROW(INDIRECT("A" & AB38 ) ))),"")}
AB39: =ROW(A39)- $AD$2 +1 -> 26 | AC39: =IF(AND($E39="Oui",$M39="Préleveur"),$F39,"") | AD39: {=IFERROR(INDEX($AC$14:$AC$102,SMALL(IF($AC$14:$AC$102<>"",ROW($AC$14:$AC$102)-ROW(INDIRECT("$AC$14"))+1),ROW(INDIRECT("A" & AB39 ) ))),"")} | AE39: =IF(AND($E39="Oui",LEFT($M39,10) ="Débitmètre"),$F39,"") | AF39: {=IFERROR(INDEX($AE$14:$AE$102,SMALL(IF($AE$14:$AE$102<>"",ROW($AE$14:$AE$102)-ROW(INDIRECT("$AE$14"))+1),ROW(INDIRECT("A" & AB39 ) ))),"")} | AG39: =IF(AND($E39="Oui",LEFT($M39,5) ="Sonde"),$F39,"") | AH39: {=IFERROR(INDEX($AG$14:$AG$102,SMALL(IF($AG$14:$AG$102<>"",ROW($AG$14:$AG$102)-ROW(INDIRECT("$AG$14"))+1),ROW(INDIRECT("A" & AB39 ) ))),"")} | AI39: =IF(AND($E39="Oui", $F39 <> "", $M39 = ""),$F39,"") | AJ39: {=IFERROR(INDEX($AI$14:$AI$102,SMALL(IF($AI$14:$AI$102<>"",ROW($AI$14:$AI$102)-ROW(INDIRECT("$AI$14"))+1),ROW(INDIRECT("A" & AB39 ) ))),"")}
D40: Liste des pluviomètres de référence de la station | AB40: =ROW(A40)- $AD$2 +1 -> 27 | AC40: =IF(AND($E40="Oui",$M40="Préleveur"),$F40,"") | AD40: {=IFERROR(INDEX($AC$14:$AC$102,SMALL(IF($AC$14:$AC$102<>"",ROW($AC$14:$AC$102)-ROW(INDIRECT("$AC$14"))+1),ROW(INDIRECT("A" & AB40 ) ))),"")} | AE40: =IF(AND($E40="Oui",LEFT($M40,10) ="Débitmètre"),$F40,"") | AF40: {=IFERROR(INDEX($AE$14:$AE$102,SMALL(IF($AE$14:$AE$102<>"",ROW($AE$14:$AE$102)-ROW(INDIRECT("$AE$14"))+1),ROW(INDIRECT("A" & AB40 ) ))),"")} | AG40: =IF(AND($E40="Oui",LEFT($M40,5) ="Sonde"),$F40,"") | AH40: {=IFERROR(INDEX($AG$14:$AG$102,SMALL(IF($AG$14:$AG$102<>"",ROW($AG$14:$AG$102)-ROW(INDIRECT("$AG$14"))+1),ROW(INDIRECT("A" & AB40 ) ))),"")} | AI40: =IF(AND($E40="Oui", $F40 <> "", $M40 = ""),$F40,"") | AJ40: {=IFERROR(INDEX($AI$14:$AI$102,SMALL(IF($AI$14:$AI$102<>"",ROW($AI$14:$AI$102)-ROW(INDIRECT("$AI$14"))+1),ROW(INDIRECT("A" & AB40 ) ))),"")}
AB41: =ROW(A41)- $AD$2 +1 -> 28 | AC41: =IF(AND($E41="Oui",$M41="Préleveur"),$F41,"") | AD41: {=IFERROR(INDEX($AC$14:$AC$102,SMALL(IF($AC$14:$AC$102<>"",ROW($AC$14:$AC$102)-ROW(INDIRECT("$AC$14"))+1),ROW(INDIRECT("A" & AB41 ) ))),"")} | AE41: =IF(AND($E41="Oui",LEFT($M41,10) ="Débitmètre"),$F41,"") | AF41: {=IFERROR(INDEX($AE$14:$AE$102,SMALL(IF($AE$14:$AE$102<>"",ROW($AE$14:$AE$102)-ROW(INDIRECT("$AE$14"))+1),ROW(INDIRECT("A" & AB41 ) ))),"")} | AG41: =IF(AND($E41="Oui",LEFT($M41,5) ="Sonde"),$F41,"") | AH41: {=IFERROR(INDEX($AG$14:$AG$102,SMALL(IF($AG$14:$AG$102<>"",ROW($AG$14:$AG$102)-ROW(INDIRECT("$AG$14"))+1),ROW(INDIRECT("A" & AB41 ) ))),"")} | AI41: =IF(AND($E41="Oui", $F41 <> "", $M41 = ""),$F41,"") | AJ41: {=IFERROR(INDEX($AI$14:$AI$102,SMALL(IF($AI$14:$AI$102<>"",ROW($AI$14:$AI$102)-ROW(INDIRECT("$AI$14"))+1),ROW(INDIRECT("A" & AB41 ) ))),"")}
E42: Actif | F42: Lien vers l'onglet de l'équipement | AB42: =ROW(A42)- $AD$2 +1 -> 29 | AC42: =IF(AND($E42="Oui",$M42="Préleveur"),$F42,"") | AD42: {=IFERROR(INDEX($AC$14:$AC$102,SMALL(IF($AC$14:$AC$102<>"",ROW($AC$14:$AC$102)-ROW(INDIRECT("$AC$14"))+1),ROW(INDIRECT("A" & AB42 ) ))),"")} | AE42: =IF(AND($E42="Oui",LEFT($M42,10) ="Débitmètre"),$F42,"") | AF42: {=IFERROR(INDEX($AE$14:$AE$102,SMALL(IF($AE$14:$AE$102<>"",ROW($AE$14:$AE$102)-ROW(INDIRECT("$AE$14"))+1),ROW(INDIRECT("A" & AB42 ) ))),"")} | AG42: =IF(AND($E42="Oui",LEFT($M42,5) ="Sonde"),$F42,"") | AH42: {=IFERROR(INDEX($AG$14:$AG$102,SMALL(IF($AG$14:$AG$102<>"",ROW($AG$14:$AG$102)-ROW(INDIRECT("$AG$14"))+1),ROW(INDIRECT("A" & AB42 ) ))),"")} | AI42: =IF(AND($E42="Oui", $F42 <> "", $M42 = ""),$F42,"") | AJ42: {=IFERROR(INDEX($AI$14:$AI$102,SMALL(IF($AI$14:$AI$102<>"",ROW($AI$14:$AI$102)-ROW(INDIRECT("$AI$14"))+1),ROW(INDIRECT("A" & AB42 ) ))),"")}
AB43: =ROW(A43)- $AD$2 +1 -> 30 | AC43: =IF(AND($E43="Oui",$M43="Préleveur"),$F43,"") | AD43: {=IFERROR(INDEX($AC$14:$AC$102,SMALL(IF($AC$14:$AC$102<>"",ROW($AC$14:$AC$102)-ROW(INDIRECT("$AC$14"))+1),ROW(INDIRECT("A" & AB43 ) ))),"")} | AE43: =IF(AND($E43="Oui",LEFT($M43,10) ="Débitmètre"),$F43,"") | AF43: {=IFERROR(INDEX($AE$14:$AE$102,SMALL(IF($AE$14:$AE$102<>"",ROW($AE$14:$AE$102)-ROW(INDIRECT("$AE$14"))+1),ROW(INDIRECT("A" & AB43 ) ))),"")} | AG43: =IF(AND($E43="Oui",LEFT($M43,5) ="Sonde"),$F43,"") | AH43: {=IFERROR(INDEX($AG$14:$AG$102,SMALL(IF($AG$14:$AG$102<>"",ROW($AG$14:$AG$102)-ROW(INDIRECT("$AG$14"))+1),ROW(INDIRECT("A" & AB43 ) ))),"")} | AI43: =IF(AND($E43="Oui", $F43 <> "", $M43 = ""),$F43,"") | AJ43: {=IFERROR(INDEX($AI$14:$AI$102,SMALL(IF($AI$14:$AI$102<>"",ROW($AI$14:$AI$102)-ROW(INDIRECT("$AI$14"))+1),ROW(INDIRECT("A" & AB43 ) ))),"")}
...

Sheet SYNTHESE
C2: CONTRÔLE ANNUEL DES DISPOSITIFS D'AUTOSURVEILLANCE DES SYSTÈMES D'ASSAINISSEMENT COLLECTIF
C3: NOM DU SYSTÈME D'ASSAINISSEMENT : | F3: =IF(ISBLANK(Descriptif!F3),"",Descriptif!F3) -> BARJAC (30) | I3: NOM SYSTÈME DE TRAITEMENT : | K3: =IF(ISBLANK(Descriptif!L3),"",Descriptif!L3) -> BARJAC (30) | M3: NOM SYSTÈME DE COLLECTE : | Q3: =IF(ISBLANK(Descriptif!Q3),"",Descriptif!Q3) -> sys | V3: ORGANISME DE CONTRÔLE : | Y3: =IF(ISBLANK(Descriptif!U3),"",Descriptif!U3) -> CEREG Ingénierie
C4: CODE SANDRE DE L'AGGLOMERATION : | F4: =IF(ISBLANK(Descriptif!F4),"",Descriptif!F4) -> eee | I4: CODE SANDRE DE LA STATION : | K4: =IF(ISBLANK(Descriptif!L4),"",Descriptif!L4) -> 060930290002 | M4: CODE SANDRE DU RESEAU : | Q4: =IF(ISBLANK(Descriptif!Q4),"",Descriptif!Q4) -> yyy | V4: NOM(S) CONTROLEUR(S) : | Y4: =IF(ISBLANK(Descriptif!U4),"",Descriptif!U4) -> control
C5: NOM DU MAITRE D'OUVRAGE : | F5: =IF(ISBLANK(Descriptif!F5),"",Descriptif!F5) -> Commune de Barjac | I5: TYPE DE TRAITEMENT : | K5: =IF(ISBLANK(Descriptif!L5),"",Descriptif!L5) -> Boues activée faible charge | M5: TYPE DE RESEAU | Q5: =IF(ISBLANK(Descriptif!Q5),"",Descriptif!Q5) -> Mixte | V5: DATE(S) D'INTERVENTION : | Y5: =IF(ISBLANK(Descriptif!U5),"",Descriptif!U5) -> 46006
C6: EXPLOITANT DE LA STATION : | F6: =IF(ISBLANK(Descriptif!F6),"",Descriptif!F6) -> Regie | I6: CAPACITE DE LA STATION : | K6: =IF(ISBLANK(Descriptif!L6),"",Descriptif!L6) -> 5 000 EH | M6: EXPLOITANT DU RESEAU : | Q6: =IF(ISBLANK(Descriptif!Q6),"",Descriptif!Q6) -> exp r | V6: CONDITION(S) METEO : | Y6: =IF(ISBLANK(Descriptif!U6),"",Descriptif!U6) -> pluie
C8: EVALUATIONS
D10: Evaluation des points règlementaires
G11: ENTREE et SORTIE | J11: Score | L11: DEVERSEMENT STATION | P11: Score | T11: BOUE et Apports extérieurs | Y11: Score
G12: Point A3 | J12: =Recap_equipements!E62 | L12: Point A2 | P12: =Recap_equipements!E74 | T12: Point A6 | Y12: =Recap_equipements!E86
G13: Débitmètre | J13: =IF(Recap_equipements!F64<>"",Recap_equipements!F64,"") | L13: Débitmètre | P13: =Recap_equipements!F76 | T13: Débitmètre | Y13: =Recap_equipements!F88
G14: Préleveur | J14: =IF(Recap_equipements!F65<>"",Recap_equipements!F65,"") | L14: Préleveur | P14: =Recap_equipements!F77 | T14: Préleveur | Y14: =Recap_equipements!F89
G15: Analytique | J15: =IF(Recap_equipements!F66<>"",Recap_equipements!F66,"") | L15: Analytique | P15: =Recap_equipements!F78 | T15: Analytique | Y15: =Recap_equipements!F90
G16: Point A4 | J16: =Recap_equipements!E68 | L16: Point A5 | P16: =Recap_equipements!E80 | T16: Point A7 | Y16: =Recap_equipements!E92
G17: Débitmètre | J17: =IF(Recap_equipements!F70<>"",Recap_equipements!F70,"") | L17: Débitmètre | P17: =Recap_equipements!F82 | T17: Débitmètre | Y17: =Recap_equipements!F94
G18: Préleveur | J18: =IF(Recap_equipements!F71<>"",Recap_equipements!F71,"") | L18: Préleveur | P18: =Recap_equipements!F83 | T18: Préleveur | Y18: =Recap_equipements!F95
G19: Analytique | J19: =IF(Recap_equipements!F72<>"",Recap_equipements!F72,"") | L19: Analytique | P19: =Recap_equipements!F84 | T19: Analytique | Y19: =Recap_equipements!F96
H21: Validé | K21: Validé avec réserve | O21: Non validé
D23: Evaluation documentaire | O23: Commentaire évaluation :
G24: Manuel d'autosurveillance à jour ou en cours d'expertise ? | K24: =IF(Qualité!L10<>"",Qualité!L10,"Non contrôlé") -> Oui | L24: Coef Qualité | O24: =IF(Qualité!M10<>"",Qualité!M10,"")
G25: Existe-t-il un système Qualité performant ? | K25: =IF(Qualité!L29<>"",Qualité!L29,"Non contrôlé") -> Non | L25: =IF(Qualité!L29="Non",0.9,1) -> 0.9 | O25: =IF(Qualité!D32<>"",Qualité!D32,"") -> Le système Qualité mis en œuvre est performant.
D28: Evaluation des pratiques analytiques
K29: Score/Penalité | O29: Commentaire évaluation :
G30: SDE | I30: Aquaref | K30: =IF(Analytique!N11<>"",Analytique!N11,"") -> 0 | O30: =IF(Analytique!D17<>"",Analytique!D17,"")
G31: EAU | I31: Fractionnement | K31: =IF(Analytique!N12<>"",Analytique!N12,"") -> 0
I32: Température | K32: =IF(Analytique!N13<>"",Analytique!N13,"") -> 0
I33: Transport | K33: =IF(Analytique!N14<>"",Analytique!N14,"") -> 0
I34: Score analytique | K34: =IF(Analytique!Q28<>"",Analytique!Q28,"") -> 0 | O34: =IF(Analytique!D34<>"",Analytique!D34,"")
G35: Score total de la chaine analytique | K35: =IF(Analytique!J31<>"",Analytique!J31,"") -> 0
D39: Autres évaluations
K40: Score | M40: Commentaire :
G41: Sonde température | I41: {=IFERROR(INDEX(Equipements!$L$16:$L$72,SMALL(IF(Equipements!$J$16:$J$72="Sonde de température",ROW(Equipements!$J$16:$J$72)-ROW(Equipements!$J$16)+1),ROW(1:1))),"")} | K41: {=IFERROR(INDEX(Equipements!$P$16:$P$72,SMALL(IF(Equipements!$J$16:$J$72="Sonde de température",ROW(Equipements!$J$16:$J$72)-ROW(Equipements!$J$16)+1),ROW(1:1))),"")} | M41: {=IFERROR(INDEX(Equipements!$V$16:$V$72,SMALL(IF(Equipements!$J$16:$J$72="Sonde de température",ROW(Equipements!$J$16:$J$72)-ROW(Equipements!$J$16)+1),ROW(1:1))),"")}
I42: {=IFERROR(INDEX(Equipements!$L$16:$L$72,SMALL(IF(Equipements!$J$16:$J$72="Sonde de température",ROW(Equipements!$J$16:$J$72)-ROW(Equipements!$J$16)+1),ROW(2:2))),"")} | K42: {=IFERROR(INDEX(Equipements!$R$16:$R$72,SMALL(IF(Equipements!$J$16:$J$72="Sonde de température",ROW(Equipements!$J$16:$J$72)-ROW(Equipements!$J$16)+1),ROW(2:2))),"")} | M42: {=IFERROR(INDEX(Equipements!$V$16:$V$72,SMALL(IF(Equipements!$J$16:$J$72="Sonde de température",ROW(Equipements!$J$16:$J$72)-ROW(Equipements!$J$16)+1),ROW(2:2))),"")}
I43: {=IFERROR(INDEX(Equipements!$L$16:$L$72,SMALL(IF(Equipements!$J$16:$J$72="Sonde de température",ROW(Equipements!$J$16:$J$72)-ROW(Equipements!$J$16)+1),ROW(3:3))),"")} | K43: {=IFERROR(INDEX(Equipements!$R$16:$R$72,SMALL(IF(Equipements!$J$16:$J$72="Sonde de température",ROW(Equipements!$J$16:$J$72)-ROW(Equipements!$J$16)+1),ROW(3:3))),"")} | M43: {=IFERROR(INDEX(Equipements!$V$16:$V$72,SMALL(IF(Equipements!$J$16:$J$72="Sonde de température",ROW(Equipements!$J$16:$J$72)-ROW(Equipements!$J$16)+1),ROW(3:3))),"")}
K45: Score | M45: Commentaire :
G46: Pluviomètre | I46: {=IFERROR(INDEX(Equipements!$L$16:$L$72,SMALL(IF(Equipements!$J$16:$J$72="Pluviomètre",ROW(Equipements!$J$16:$J$72)-ROW(Equipements!$J$16)+1),ROW(1:1))),"")} | K46: {=IFERROR(INDEX(Equipements!$P$16:$P$72,SMALL(IF(Equipements!$J$16:$J$72="Pluviomètre",ROW(Equipements!$J$16:$J$72)-ROW(Equipements!$J$16)+1),ROW(1:1))),"")} | M46: {=IFERROR(INDEX(Equipements!$V$16:$V$72,SMALL(IF(Equipements!$J$16:$J$72="Pluviomètre",ROW(Equipements!$J$16:$J$72)-ROW(Equipements!$J$16)+1),ROW(1:1))),"")}
I47: {=IFERROR(INDEX(Equipements!$L$16:$L$72,SMALL(IF(Equipements!$J$16:$J$72="Pluviomètre",ROW(Equipements!$J$16:$J$72)-ROW(Equipements!$J$16)+1),ROW(2:2))),"")} | K47: {=IFERROR(INDEX(Equipements!$P$16:$P$72,SMALL(IF(Equipements!$J$16:$J$72="Pluviomètre",ROW(Equipements!$J$16:$J$72)-ROW(Equipements!$J$16)+1),ROW(2:2))),"")} | M47: {=IFERROR(INDEX(Equipements!$V$16:$V$72,SMALL(IF(Equipements!$J$16:$J$72="Pluviomètre",ROW(Equipements!$J$16:$J$72)-ROW(Equipements!$J$16)+1),ROW(2:2))),"")}
I48: {=IFERROR(INDEX(Equipements!$L$16:$L$72,SMALL(IF(Equipements!$J$16:$J$72="Pluviomètre",ROW(Equipements!$J$16:$J$72)-ROW(Equipements!$J$16)+1),ROW(3:3))),"")} | K48: {=IFERROR(INDEX(Equipements!$P$16:$P$72,SMALL(IF(Equipements!$J$16:$J$72="Pluviomètre",ROW(Equipements!$J$16:$J$72)-ROW(Equipements!$J$16)+1),ROW(3:3))),"")} | M48: {=IFERROR(INDEX(Equipements!$V$16:$V$72,SMALL(IF(Equipements!$J$16:$J$72="Pluviomètre",ROW(Equipements!$J$16:$J$72)-ROW(Equipements!$J$16)+1),ROW(3:3))),"")}
D51: Commentaire général
C57: SYNTHESE DISPOSITIFS AUTOSURVEILLANCE DE LA STATION D'ÉPURATION
D59: Détails des équipements contrôlés | K59: Score sur 100 | L59: Critères d'évaluation
...

Sheet Qualité
C2: CONTRÔLE ANNUEL DES DISPOSITIFS D'AUTOSURVEILLANCE DES SYSTÈMES D'ASSAINISSEMENT COLLECTIF
C3: NOM DU SYSTÈME D'ASSAINISSEMENT : | G3: =IF(ISBLANK(Descriptif!F3),"",Descriptif!F3) -> BARJAC (30) | K3: NOM DU SYSTÈME DE COLLECTE : | O3: =IF(ISBLANK(Descriptif!Q3),"",Descriptif!Q3) -> sys
C4: CODE SANDRE DE L'AGGLOMERATION : | G4: =IF(ISBLANK(Descriptif!F4),"",Descriptif!F4) -> eee | K4: CODE SANDRE DU RESEAU : | O4: =IF(ISBLANK(Descriptif!Q4),"",Descriptif!Q4) -> yyy
C5: NOM DU MAITRE D'OUVRAGE : | G5: =IF(ISBLANK(Descriptif!F5),"",Descriptif!F5) -> Commune de Barjac | K5: NOM DE L'EXPLOITANT RESEAU : | O5: =IF(ISBLANK(Descriptif!Q6),"",Descriptif!Q6) -> exp r
C6: NOM DE L'EXPLOITANT STATION : | G6: =IF(ISBLANK(Descriptif!F6),"",Descriptif!F6) -> Regie | K6: ORGANISME DE CONTRÔLE : | O6: =IF(ISBLANK(Descriptif!U3),"",Descriptif!U3) -> CEREG Ingénierie
C8: MANUEL D'AUTOSURVEILLANCE
D10: 1 | E10: Est-ce que le manuel est à jour, validé ou en cours d'expertise? | L10: Oui
D12: COMMENTAIRES :
D13: La fiche descriptive du débitmètre "sortiestation" devra être actualisée afin de tenir compte du renouvellement du dispositif de mesure en mars 2025
D15: Le manuel d’autosurveillance n’est pas à jour si : * date du MAS ≤ 2015 ; * changement du maitre d’ouvrage ou de l’exploitant ; * construction d’une nouvelle STEU ou la réhabilitation d’une STEU ; * modification des points du système de collecte et des points de déversement au milieu ; * modification du référentiel et du schéma SANDRE (ajout ou suppression d’un point d’autosurveillance ou toute autre modification impactant le calcul du rendement) ; * évolutions techniques ou travaux importants sur le système d'assainissement impactant les points d'autosurveillance ; * modifications réglementaires telles que l’adoption d’un nouvel arrêté si impact sur le référentiel, le schéma SANDRE et le matériel d’autosurveillance ; * modifications significatives du suivi métrologique des dispositifs d'autosurveillance ; *modifications significatives concernant la réalisation des analyses d'autosurveillance.
C19: PROCEDURE DE CONTROLES INTERNES DES MATERIELS D'AUTOSURVEILLANCE
D21: 2 | E21: Est-ce que le contrôle des débimètres est réalisé selon les procédures décrites dans le manuel d'autosurveillance ? | L21: Oui
D22: 3 | E22: Est-ce que le contrôle des échantillonneurs est réalisé selon les procédures décrites dans le manuel d'autosurveillance ? | L22: Oui
D23: 4 | E23: Est-ce que le contrôle des thermomètres est réalisé selon les procédures décrites dans le manuel d'autosurveillance ? | L23: Oui
D24: 5 | E24: Est-ce que le contrôle des pluviomètres est réalisé selon les procédures décrites dans le manuel d'autosurveillance ? | L24: Oui
D25: 6 | E25: Est-ce que le contrôle des balances est réalisé selon les procédures décrites dans le manuel d'autosurveillance ? | L25: Oui
D26: 7 | E26: Est-ce que le contrôle des chronomètres est réalisé selon les procédures décrites dans le manuel d'autosurveillance ? | L26: Oui
D27: 8 | E27: Les contrôles internes sont-ils tous tracés, formalisés et suivis (fiches de vie, cartes de contrôle...) ? | L27: Oui
D28: 9 | E28: Des fiches de non-conformité et d'action d'amélioration ont-elles été produites ? | L28: Non
D29: 10 | E29: Existe-il un système qualité performant ? | L29: =IF(COUNTIF(L21:L28,"Non")>0,"Non","Oui") -> Non
D31: COMMENTAIRES :
D32: Le système Qualité mis en œuvre est performant.

Sheet Analytique
U1: Ne rien mettre dans cette colonne | V1: Ne rien mettre dans cette colonne | W1: Ne rien mettre dans cette colonne | X1: Ne rien mettre dans cette colonne | Y1: Ne rien mettre dans cette colonne | Z1: Ne rien mettre dans cette colonne
C2: CONTRÔLE ANNUEL DES DISPOSITIFS D'AUTOSURVEILLANCE DES SYSTÈMES D'ASSAINISSEMENT COLLECTIF | X2: Code PREL | Y2: NB ANALYSE | Z2: NB CONFORME | AA2: Coef | AB2: Coef corrigé | AC2: Score | AD2: Evaluation
C3: NOM DU SYSTÈME D'ASSAINISSEMENT : | G3: =IF(ISBLANK(Descriptif!F3), "", Descriptif!F3) -> BARJAC (30) | K3: NOM DU LABORATOIRE : | O3: Labo | X3: {=IFERROR(INDEX($T$37:$T$1003,SMALL(IF($T$37:$T$1003<>"",ROW($T$37:$T$1003)-ROW($T$37)+1),ROW(1:1))),"")} | Y3: {=IFERROR(INDEX($U$37:$U$1003,SMALL(IF($T$37:$T$1003<>"",ROW($T$37:$T$1003)-ROW($T$37)+1),ROW(1:1))),"")} | Z3: {=IFERROR(INDEX($V$37:$V$1003,SMALL(IF($T$37:$T$1003<>"",ROW($T$37:$T$1003)-ROW($T$37)+1),ROW(1:1))),"")} | AA3: {=IFERROR(INDEX($W$37:$W$1003,SMALL(IF($T$37:$T$1003<>"",ROW($T$37:$T$1003)-ROW($T$37)+1),ROW(1:1))),"")} | AB3: =IF(X3<>"",IF($J$28="Oui",100,AA3),"") | AC3: =IF(X3<>"",(AB3/100 * (1-$P$15)*100),"") | AD3: =IF(X3<>"",IF(AC3<>"",IF(AC3>80,"Validé",IF(AC3<70,"Non Validé","Validé avec réserve")),"Non contrôlé"),"")
C4: CODE SANDRE DE L'AGGLOMERATION : | G4: =IF(ISBLANK(Descriptif!F4), "", Descriptif!F4) -> eee | K4: AGREMENT : | X4: {=IFERROR(INDEX($T$37:$T$1003,SMALL(IF($T$37:$T$1003<>"",ROW($T$37:$T$1003)-ROW($T$37)+1),ROW(2:2))),"")} | Y4: {=IFERROR(INDEX($U$37:$U$1003,SMALL(IF($T$37:$T$1003<>"",ROW($T$37:$T$1003)-ROW($T$37)+1),ROW(2:2))),"")} | Z4: {=IFERROR(INDEX($V$37:$V$1003,SMALL(IF($T$37:$T$1003<>"",ROW($T$37:$T$1003)-ROW($T$37)+1),ROW(2:2))),"")} | AA4: {=IFERROR(INDEX($W$37:$W$1003,SMALL(IF($T$37:$T$1003<>"",ROW($T$37:$T$1003)-ROW($T$37)+1),ROW(2:2))),"")} | AB4: =IF(X4<>"",IF($J$28="Oui",100,AA4),"") | AC4: =IF(X4<>"",(AB4/100 * (1-$P$15)*100),"") | AD4: =IF(X4<>"",IF(AC4<>"",IF(AC4>80,"Validé",IF(AC4<70,"Non Validé","Validé avec réserve")),"Non contrôlé"),"")
C5: MAITRE D'OUVRAGE : | G5: =IF(ISBLANK(Descriptif!F5), "", Descriptif!F5) -> Commune de Barjac | K5: ORGANISME DE CONTRÔLE : | O5: =IF(ISBLANK(Descriptif!U3), "", Descriptif!U3) -> CEREG Ingénierie | X5: {=IFERROR(INDEX($T$37:$T$1003,SMALL(IF($T$37:$T$1003<>"",ROW($T$37:$T$1003)-ROW($T$37)+1),ROW(3:3))),"")} | Y5: {=IFERROR(INDEX($U$37:$U$1003,SMALL(IF($T$37:$T$1003<>"",ROW($T$37:$T$1003)-ROW($T$37)+1),ROW(3:3))),"")} | Z5: {=IFERROR(INDEX($V$37:$V$1003,SMALL(IF($T$37:$T$1003<>"",ROW($T$37:$T$1003)-ROW($T$37)+1),ROW(3:3))),"")} | AA5: {=IFERROR(INDEX($W$37:$W$1003,SMALL(IF($T$37:$T$1003<>"",ROW($T$37:$T$1003)-ROW($T$37)+1),ROW(3:3))),"")} | AB5: =IF(X5<>"",IF($J$28="Oui",100,AA5),"") | AC5: =IF(X5<>"",(AB5/100 * (1-$P$15)*100),"") | AD5: =IF(X5<>"",IF(AC5<>"",IF(AC5>80,"Validé",IF(AC5<70,"Non Validé","Validé avec réserve")),"Non contrôlé"),"")
C6: EXPLOITANT : | G6: =IF(ISBLANK(Descriptif!F6), "", Descriptif!F6) -> Regie | K6: NOM·S CONTROLEUR·SE·S : | O6: =IF(ISBLANK(Descriptif!U4), "", Descriptif!U4) -> control | X6: {=IFERROR(INDEX($T$37:$T$1003,SMALL(IF($T$37:$T$1003<>"",ROW($T$37:$T$1003)-ROW($T$37)+1),ROW(4:4))),"")} | Y6: {=IFERROR(INDEX($U$37:$U$1003,SMALL(IF($T$37:$T$1003<>"",ROW($T$37:$T$1003)-ROW($T$37)+1),ROW(4:4))),"")} | Z6: {=IFERROR(INDEX($V$37:$V$1003,SMALL(IF($T$37:$T$1003<>"",ROW($T$37:$T$1003)-ROW($T$37)+1),ROW(4:4))),"")} | AA6: {=IFERROR(INDEX($W$37:$W$1003,SMALL(IF($T$37:$T$1003<>"",ROW($T$37:$T$1003)-ROW($T$37)+1),ROW(4:4))),"")} | AB6: =IF(X6<>"",IF($J$28="Oui",100,AA6),"") | AC6: =IF(X6<>"",(AB6/100 * (1-$P$15)*100),"") | AD6: =IF(X6<>"",IF(AC6<>"",IF(AC6>80,"Validé",IF(AC6<70,"Non Validé","Validé avec réserve")),"Non contrôlé"),"")
X7: {=IFERROR(INDEX($T$37:$T$1003,SMALL(IF($T$37:$T$1003<>"",ROW($T$37:$T$1003)-ROW($T$37)+1),ROW(5:5))),"")} | Y7: {=IFERROR(INDEX($U$37:$U$1003,SMALL(IF($T$37:$T$1003<>"",ROW($T$37:$T$1003)-ROW($T$37)+1),ROW(5:5))),"")} | Z7: {=IFERROR(INDEX($V$37:$V$1003,SMALL(IF($T$37:$T$1003<>"",ROW($T$37:$T$1003)-ROW($T$37)+1),ROW(5:5))),"")} | AA7: {=IFERROR(INDEX($W$37:$W$1003,SMALL(IF($T$37:$T$1003<>"",ROW($T$37:$T$1003)-ROW($T$37)+1),ROW(5:5))),"")} | AB7: =IF(X7<>"",IF($J$28="Oui",100,AA7),"") | AC7: =IF(X7<>"",(AB7/100 * (1-$P$15)*100),"") | AD7: =IF(X7<>"",IF(AC7<>"",IF(AC7>80,"Validé",IF(AC7<70,"Non Validé","Validé avec réserve")),"Non contrôlé"),"")
C8: ECHANTILLONAGE | X8: {=IFERROR(INDEX($T$37:$T$1003,SMALL(IF($T$37:$T$1003<>"",ROW($T$37:$T$1003)-ROW($T$37)+1),ROW(6:6))),"")} | Y8: {=IFERROR(INDEX($U$37:$U$1003,SMALL(IF($T$37:$T$1003<>"",ROW($T$37:$T$1003)-ROW($T$37)+1),ROW(6:6))),"")} | Z8: {=IFERROR(INDEX($V$37:$V$1003,SMALL(IF($T$37:$T$1003<>"",ROW($T$37:$T$1003)-ROW($T$37)+1),ROW(6:6))),"")} | AA8: {=IFERROR(INDEX($W$37:$W$1003,SMALL(IF($T$37:$T$1003<>"",ROW($T$37:$T$1003)-ROW($T$37)+1),ROW(6:6))),"")} | AB8: =IF(X8<>"",IF($J$28="Oui",100,AA8),"") | AC8: =IF(X8<>"",(AB8/100 * (1-$P$15)*100),"") | AD8: =IF(X8<>"",IF(AC8<>"",IF(AC8>80,"Validé",IF(AC8<70,"Non Validé","Validé avec réserve")),"Non contrôlé"),"")
X9: {=IFERROR(INDEX($T$37:$T$1003,SMALL(IF($T$37:$T$1003<>"",ROW($T$37:$T$1003)-ROW($T$37)+1),ROW(7:7))),"")} | Y9: {=IFERROR(INDEX($U$37:$U$1003,SMALL(IF($T$37:$T$1003<>"",ROW($T$37:$T$1003)-ROW($T$37)+1),ROW(7:7))),"")} | Z9: {=IFERROR(INDEX($V$37:$V$1003,SMALL(IF($T$37:$T$1003<>"",ROW($T$37:$T$1003)-ROW($T$37)+1),ROW(7:7))),"")} | AA9: {=IFERROR(INDEX($W$37:$W$1003,SMALL(IF($T$37:$T$1003<>"",ROW($T$37:$T$1003)-ROW($T$37)+1),ROW(7:7))),"")} | AB9: =IF(X9<>"",IF($J$28="Oui",100,AA9),"") | AC9: =IF(X9<>"",(AB9/100 * (1-$P$15)*100),"") | AD9: =IF(X9<>"",IF(AC9<>"",IF(AC9>80,"Validé",IF(AC9<70,"Non Validé","Validé avec réserve")),"Non contrôlé"),"")
D10: Les échantillons sont-ils constitués, conservés et mis en analyse, selon les règles de l'art en vigueur ? | N10: Pénalité | X10: {=IFERROR(INDEX($T$37:$T$1003,SMALL(IF($T$37:$T$1003<>"",ROW($T$37:$T$1003)-ROW($T$37)+1),ROW(8:8))),"")} | Y10: {=IFERROR(INDEX($U$37:$U$1003,SMALL(IF($T$37:$T$1003<>"",ROW($T$37:$T$1003)-ROW($T$37)+1),ROW(8:8))),"")} | Z10: {=IFERROR(INDEX($V$37:$V$1003,SMALL(IF($T$37:$T$1003<>"",ROW($T$37:$T$1003)-ROW($T$37)+1),ROW(8:8))),"")} | AA10: {=IFERROR(INDEX($W$37:$W$1003,SMALL(IF($T$37:$T$1003<>"",ROW($T$37:$T$1003)-ROW($T$37)+1),ROW(8:8))),"")} | AB10: =IF(X10<>"",IF($J$28="Oui",100,AA10),"") | AC10: =IF(X10<>"",(AB10/100 * (1-$P$15)*100),"") | AD10: =IF(X10<>"",IF(AC10<>"",IF(AC10>80,"Validé",IF(AC10<70,"Non Validé","Validé avec réserve")),"Non contrôlé"),"")
D11: Le guide AQUAREF est-il respecté pour le prélèvement des échantillons SDE ? | L11: Non contrôlé | N11: =IF(L11="","",IF(L11="Non",0.1,0)) -> 0 | X11: {=IFERROR(INDEX($T$37:$T$1003,SMALL(IF($T$37:$T$1003<>"",ROW($T$37:$T$1003)-ROW($T$37)+1),ROW(9:9))),"")} | Y11: {=IFERROR(INDEX($U$37:$U$1003,SMALL(IF($T$37:$T$1003<>"",ROW($T$37:$T$1003)-ROW($T$37)+1),ROW(9:9))),"")} | Z11: {=IFERROR(INDEX($V$37:$V$1003,SMALL(IF($T$37:$T$1003<>"",ROW($T$37:$T$1003)-ROW($T$37)+1),ROW(9:9))),"")} | AA11: {=IFERROR(INDEX($W$37:$W$1003,SMALL(IF($T$37:$T$1003<>"",ROW($T$37:$T$1003)-ROW($T$37)+1),ROW(9:9))),"")} | AB11: =IF(X11<>"",IF($J$28="Oui",100,AA11),"") | AC11: =IF(X11<>"",(AB11/100 * (1-$P$15)*100),"") | AD11: =IF(X11<>"",IF(AC11<>"",IF(AC11>80,"Validé",IF(AC11<70,"Non Validé","Validé avec réserve")),"Non contrôlé"),"")
D12: Les échantillons sont-ils fractionnés selon la norme FDT 90-523-2 ? | L12: Oui | N12: =IF(L12="","",IF(L12="Non",0.1,0)) -> 0 | X12: {=IFERROR(INDEX($T$37:$T$1003,SMALL(IF($T$37:$T$1003<>"",ROW($T$37:$T$1003)-ROW($T$37)+1),ROW(10:10))),"")} | Y12: {=IFERROR(INDEX($U$37:$U$1003,SMALL(IF($T$37:$T$1003<>"",ROW($T$37:$T$1003)-ROW($T$37)+1),ROW(10:10))),"")} | Z12: {=IFERROR(INDEX($V$37:$V$1003,SMALL(IF($T$37:$T$1003<>"",ROW($T$37:$T$1003)-ROW($T$37)+1),ROW(10:10))),"")} | AA12: {=IFERROR(INDEX($W$37:$W$1003,SMALL(IF($T$37:$T$1003<>"",ROW($T$37:$T$1003)-ROW($T$37)+1),ROW(10:10))),"")} | AB12: =IF(X12<>"",IF($J$28="Oui",100,AA12),"") | AC12: =IF(X12<>"",(AB12/100 * (1-$P$15)*100),"") | AD12: =IF(X12<>"",IF(AC12<>"",IF(AC12>80,"Validé",IF(AC12<70,"Non Validé","Validé avec réserve")),"Non contrôlé"),"")
D13: La conservation pendant le transport des échantillons est-elle assurée à 5°C ± 3°C ? | L13: Oui | N13: =IF(L13="","",IF(L13="Non",0.1,0)) -> 0 | X13: {=IFERROR(INDEX($T$37:$T$1003,SMALL(IF($T$37:$T$1003<>"",ROW($T$37:$T$1003)-ROW($T$37)+1),ROW(11:11))),"")} | Y13: {=IFERROR(INDEX($U$37:$U$1003,SMALL(IF($T$37:$T$1003<>"",ROW($T$37:$T$1003)-ROW($T$37)+1),ROW(11:11))),"")} | Z13: {=IFERROR(INDEX($V$37:$V$1003,SMALL(IF($T$37:$T$1003<>"",ROW($T$37:$T$1003)-ROW($T$37)+1),ROW(11:11))),"")} | AA13: {=IFERROR(INDEX($W$37:$W$1003,SMALL(IF($T$37:$T$1003<>"",ROW($T$37:$T$1003)-ROW($T$37)+1),ROW(11:11))),"")} | AB13: =IF(X13<>"",IF($J$28="Oui",100,AA13),"") | AC13: =IF(X13<>"",(AB13/100 * (1-$P$15)*100),"") | AD13: =IF(X13<>"",IF(AC13<>"",IF(AC13>80,"Validé",IF(AC13<70,"Non Validé","Validé avec réserve")),"Non contrôlé"),"")
D14: Les conditions de transport permettent-elles l'acheminement et la réception des échantillons dans les 24 h ? | L14: Oui | N14: =IF(L14="","",IF(L14="Non",0.1,0)) -> 0 | X14: {=IFERROR(INDEX($T$37:$T$1003,SMALL(IF($T$37:$T$1003<>"",ROW($T$37:$T$1003)-ROW($T$37)+1),ROW(12:12))),"")} | Y14: {=IFERROR(INDEX($U$37:$U$1003,SMALL(IF($T$37:$T$1003<>"",ROW($T$37:$T$1003)-ROW($T$37)+1),ROW(12:12))),"")} | Z14: {=IFERROR(INDEX($V$37:$V$1003,SMALL(IF($T$37:$T$1003<>"",ROW($T$37:$T$1003)-ROW($T$37)+1),ROW(12:12))),"")} | AA14: {=IFERROR(INDEX($W$37:$W$1003,SMALL(IF($T$37:$T$1003<>"",ROW($T$37:$T$1003)-ROW($T$37)+1),ROW(12:12))),"")} | AB14: =IF(X14<>"",IF($J$28="Oui",100,AA14),"") | AC14: =IF(X14<>"",(AB14/100 * (1-$P$15)*100),"") | AD14: =IF(X14<>"",IF(AC14<>"",IF(AC14>80,"Validé",IF(AC14<70,"Non Validé","Validé avec réserve")),"Non contrôlé"),"")
N15: Total pénalité : | P15: =SUM(N11:P14) -> 0 | X15: {=IFERROR(INDEX($T$37:$T$1003,SMALL(IF($T$37:$T$1003<>"",ROW($T$37:$T$1003)-ROW($T$37)+1),ROW(13:13))),"")} | Y15: {=IFERROR(INDEX($U$37:$U$1003,SMALL(IF($T$37:$T$1003<>"",ROW($T$37:$T$1003)-ROW($T$37)+1),ROW(13:13))),"")} | Z15: {=IFERROR(INDEX($V$37:$V$1003,SMALL(IF($T$37:$T$1003<>"",ROW($T$37:$T$1003)-ROW($T$37)+1),ROW(13:13))),"")} | AA15: {=IFERROR(INDEX($W$37:$W$1003,SMALL(IF($T$37:$T$1003<>"",ROW($T$37:$T$1003)-ROW($T$37)+1),ROW(13:13))),"")} | AB15: =IF(X15<>"",IF($J$28="Oui",100,AA15),"") | AC15: =IF(X15<>"",(AB15/100 * (1-$P$15)*100),"") | AD15: =IF(X15<>"",IF(AC15<>"",IF(AC15>80,"Validé",IF(AC15<70,"Non Validé","Validé avec réserve")),"Non contrôlé"),"")
D16: COMMENTAIRES :
X19: {=IFERROR(INDEX($T$37:$T$1003,SMALL(IF($T$37:$T$1003<>"",ROW($T$37:$T$1003)-ROW($T$37)+1),ROW(14:14))),"")} | Y19: {=IFERROR(INDEX($U$37:$U$1003,SMALL(IF($T$37:$T$1003<>"",ROW($T$37:$T$1003)-ROW($T$37)+1),ROW(14:14))),"")} | Z19: {=IFERROR(INDEX($V$37:$V$1003,SMALL(IF($T$37:$T$1003<>"",ROW($T$37:$T$1003)-ROW($T$37)+1),ROW(14:14))),"")} | AA19: {=IFERROR(INDEX($W$37:$W$1003,SMALL(IF($T$37:$T$1003<>"",ROW($T$37:$T$1003)-ROW($T$37)+1),ROW(14:14))),"")} | AB19: =IF(X19<>"",IF($J$28="Oui",100,AA19),"") | AC19: =IF(X19<>"",(AB19/100 * (1-$P$15)*100),"") | AD19: =IF(X19<>"",IF(AC19<>"",IF(AC19>80,"Validé",IF(AC19<70,"Non Validé","Validé avec réserve")),"Non contrôlé"),"")
X20: {=IFERROR(INDEX($T$37:$T$1003,SMALL(IF($T$37:$T$1003<>"",ROW($T$37:$T$1003)-ROW($T$37)+1),ROW(15:15))),"")} | Y20: {=IFERROR(INDEX($U$37:$U$1003,SMALL(IF($T$37:$T$1003<>"",ROW($T$37:$T$1003)-ROW($T$37)+1),ROW(15:15))),"")} | Z20: {=IFERROR(INDEX($V$37:$V$1003,SMALL(IF($T$37:$T$1003<>"",ROW($T$37:$T$1003)-ROW($T$37)+1),ROW(15:15))),"")} | AA20: {=IFERROR(INDEX($W$37:$W$1003,SMALL(IF($T$37:$T$1003<>"",ROW($T$37:$T$1003)-ROW($T$37)+1),ROW(15:15))),"")} | AB20: =IF(X20<>"",IF($J$28="Oui",100,AA20),"") | AC20: =IF(X20<>"",(AB20/100 * (1-$P$15)*100),"") | AD20: =IF(X20<>"",IF(AC20<>"",IF(AC20>80,"Validé",IF(AC20<70,"Non Validé","Validé avec réserve")),"Non contrôlé"),"")
C21: ANALYSES | X21: {=IFERROR(INDEX($T$37:$T$1003,SMALL(IF($T$37:$T$1003<>"",ROW($T$37:$T$1003)-ROW($T$37)+1),ROW(19:19))),"")} | Y21: {=IFERROR(INDEX($U$37:$U$1003,SMALL(IF($T$37:$T$1003<>"",ROW($T$37:$T$1003)-ROW($T$37)+1),ROW(19:19))),"")} | Z21: {=IFERROR(INDEX($V$37:$V$1003,SMALL(IF($T$37:$T$1003<>"",ROW($T$37:$T$1003)-ROW($T$37)+1),ROW(19:19))),"")} | AA21: {=IFERROR(INDEX($W$37:$W$1003,SMALL(IF($T$37:$T$1003<>"",ROW($T$37:$T$1003)-ROW($T$37)+1),ROW(19:19))),"")} | AB21: =IF(X21<>"",IF($J$28="Oui",100,AA21),"") | AC21: =IF(X21<>"",(AB21/100 * (1-$P$15)*100),"") | AD21: =IF(X21<>"",IF(AC21<>"",IF(AC21>80,"Validé",IF(AC21<70,"Non Validé","Validé avec réserve")),"Non contrôlé"),"")
X22: {=IFERROR(INDEX($T$37:$T$1003,SMALL(IF($T$37:$T$1003<>"",ROW($T$37:$T$1003)-ROW($T$37)+1),ROW(20:20))),"")} | Y22: {=IFERROR(INDEX($U$37:$U$1003,SMALL(IF($T$37:$T$1003<>"",ROW($T$37:$T$1003)-ROW($T$37)+1),ROW(20:20))),"")} | Z22: {=IFERROR(INDEX($V$37:$V$1003,SMALL(IF($T$37:$T$1003<>"",ROW($T$37:$T$1003)-ROW($T$37)+1),ROW(20:20))),"")} | AA22: {=IFERROR(INDEX($W$37:$W$1003,SMALL(IF($T$37:$T$1003<>"",ROW($T$37:$T$1003)-ROW($T$37)+1),ROW(20:20))),"")} | AB22: =IF(X22<>"",IF($J$28="Oui",100,AA22),"") | AC22: =IF(X22<>"",(AB22/100 * (1-$P$15)*100),"") | AD22: =IF(X22<>"",IF(AC22<>"",IF(AC22>80,"Validé",IF(AC22<70,"Non Validé","Validé avec réserve")),"Non contrôlé"),"")
D23: Les analyses sont-elles correctement effectuées ? | X23: {=IFERROR(INDEX($T$37:$T$1003,SMALL(IF($T$37:$T$1003<>"",ROW($T$37:$T$1003)-ROW($T$37)+1),ROW(21:21))),"")} | Y23: {=IFERROR(INDEX($U$37:$U$1003,SMALL(IF($T$37:$T$1003<>"",ROW($T$37:$T$1003)-ROW($T$37)+1),ROW(21:21))),"")} | Z23: {=IFERROR(INDEX($V$37:$V$1003,SMALL(IF($T$37:$T$1003<>"",ROW($T$37:$T$1003)-ROW($T$37)+1),ROW(21:21))),"")} | AA23: {=IFERROR(INDEX($W$37:$W$1003,SMALL(IF($T$37:$T$1003<>"",ROW($T$37:$T$1003)-ROW($T$37)+1),ROW(21:21))),"")} | AB23: =IF(X23<>"",IF($J$28="Oui",100,AA23),"") | AC23: =IF(X23<>"",(AB23/100 * (1-$P$15)*100),"") | AD23: =IF(X23<>"",IF(AC23<>"",IF(AC23>80,"Validé",IF(AC23<70,"Non Validé","Validé avec réserve")),"Non contrôlé"),"")
D24: Nom du(des) laboratoire(s) réalisant les analyses de la matrice eau | X24: {=IFERROR(INDEX($T$37:$T$1003,SMALL(IF($T$37:$T$1003<>"",ROW($T$37:$T$1003)-ROW($T$37)+1),ROW(22:22))),"")} | Y24: {=IFERROR(INDEX($U$37:$U$1003,SMALL(IF($T$37:$T$1003<>"",ROW($T$37:$T$1003)-ROW($T$37)+1),ROW(22:22))),"")} | Z24: {=IFERROR(INDEX($V$37:$V$1003,SMALL(IF($T$37:$T$1003<>"",ROW($T$37:$T$1003)-ROW($T$37)+1),ROW(22:22))),"")} | AA24: {=IFERROR(INDEX($W$37:$W$1003,SMALL(IF($T$37:$T$1003<>"",ROW($T$37:$T$1003)-ROW($T$37)+1),ROW(22:22))),"")} | AB24: =IF(X24<>"",IF($J$28="Oui",100,AA24),"") | AC24: =IF(X24<>"",(AB24/100 * (1-$P$15)*100),"") | AD24: =IF(X24<>"",IF(AC24<>"",IF(AC24>80,"Validé",IF(AC24<70,"Non Validé","Validé avec réserve")),"Non contrôlé"),"")
D25: Nom du(des) laboratoire(s) réalisant l'analyse de la siccité des boues et des matières séches | X25: {=IFERROR(INDEX($T$37:$T$1003,SMALL(IF($T$37:$T$1003<>"",ROW($T$37:$T$1003)-ROW($T$37)+1),ROW(23:23))),"")} | Y25: {=IFERROR(INDEX($U$37:$U$1003,SMALL(IF($T$37:$T$1003<>"",ROW($T$37:$T$1003)-ROW($T$37)+1),ROW(23:23))),"")} | Z25: {=IFERROR(INDEX($V$37:$V$1003,SMALL(IF($T$37:$T$1003<>"",ROW($T$37:$T$1003)-ROW($T$37)+1),ROW(23:23))),"")} | AA25: {=IFERROR(INDEX($W$37:$W$1003,SMALL(IF($T$37:$T$1003<>"",ROW($T$37:$T$1003)-ROW($T$37)+1),ROW(23:23))),"")} | AB25: =IF(X25<>"",IF($J$28="Oui",100,AA25),"") | AC25: =IF(X25<>"",(AB25/100 * (1-$P$15)*100),"") | AD25: =IF(X25<>"",IF(AC25<>"",IF(AC25>80,"Validé",IF(AC25<70,"Non Validé","Validé avec réserve")),"Non contrôlé"),"")
D26: Le(s) laboratoire(s) est/sont-il(s) agréé(s) au titre du code de l’environnement pour l'ensemble des paramètres de la matrice eau résiduaire? | J26: Non | X26: {=IFERROR(INDEX($T$37:$T$1003,SMALL(IF($T$37:$T$1003<>"",ROW($T$37:$T$1003)-ROW($T$37)+1),ROW(24:24))),"")} | Y26: {=IFERROR(INDEX($U$37:$U$1003,SMALL(IF($T$37:$T$1003<>"",ROW($T$37:$T$1003)-ROW($T$37)+1),ROW(24:24))),"")} | Z26: {=IFERROR(INDEX($V$37:$V$1003,SMALL(IF($T$37:$T$1003<>"",ROW($T$37:$T$1003)-ROW($T$37)+1),ROW(24:24))),"")} | AA26: {=IFERROR(INDEX($W$37:$W$1003,SMALL(IF($T$37:$T$1003<>"",ROW($T$37:$T$1003)-ROW($T$37)+1),ROW(24:24))),"")} | AB26: =IF(X26<>"",IF($J$28="Oui",100,AA26),"") | AC26: =IF(X26<>"",(AB26/100 * (1-$P$15)*100),"") | AD26: =IF(X26<>"",IF(AC26<>"",IF(AC26>80,"Validé",IF(AC26<70,"Non Validé","Validé avec réserve")),"Non contrôlé"),"")
D27: A défaut, est ce que le laboratoire réalise un exercice concluant d’intercalibration avec un laboratoire agréé ? | J27: Non | X27: {=IFERROR(INDEX($T$37:$T$1003,SMALL(IF($T$37:$T$1003<>"",ROW($T$37:$T$1003)-ROW($T$37)+1),ROW(25:25))),"")} | Y27: {=IFERROR(INDEX($U$37:$U$1003,SMALL(IF($T$37:$T$1003<>"",ROW($T$37:$T$1003)-ROW($T$37)+1),ROW(25:25))),"")} | Z27: {=IFERROR(INDEX($V$37:$V$1003,SMALL(IF($T$37:$T$1003<>"",ROW($T$37:$T$1003)-ROW($T$37)+1),ROW(25:25))),"")} | AA27: {=IFERROR(INDEX($W$37:$W$1003,SMALL(IF($T$37:$T$1003<>"",ROW($T$37:$T$1003)-ROW($T$37)+1),ROW(25:25))),"")} | AB27: =IF(X27<>"",IF($J$28="Oui",100,AA27),"") | AC27: =IF(X27<>"",(AB27/100 * (1-$P$15)*100),"") | AD27: =IF(X27<>"",IF(AC27<>"",IF(AC27>80,"Validé",IF(AC27<70,"Non Validé","Validé avec réserve")),"Non contrôlé"),"")
